Workbook

Sheet Raw counts
E1: 0 | F1: 0 | G1: 0 | H1: 0 | I1: 0 | J1: 0 | K1: 0 | L1: 0 | M1: 0 | N1: 1 | O1: 1 | P1: 1 | Q1: 1 | R1: 1 | S1: 1 | T1: 1 | U1: 1
A2: id | B2: name | C2: structure_order | D2: parent_id | E2: 124 | F2: 143 | G2: 146 | H2: 152 | I2: 170 | J2: 171 | K2: 175 | L2: 183 | M2: 200 | N2: 113 | O2: 172 | P2: 177 | Q2: 178 | R2: 179 | S2: 180 | T2: 184 | U2: 207 | V2: Filter | W2: Cluster | X2: T-test | Y2: Gem 0 | Z2: Gem 1
A3: 0 | B3: background | C3: 0 | E3: 934616 | F3: 162114 | G3: 70396 | H3: 185434 | I3: 192266 | J3: 124025 | K3: 145132 | L3: 116310 | M3: 195147 | N3: 135274 | O3: 390286 | P3: 204167 | Q3: 229529 | R3: 177156 | S3: 316109 | T3: 124060 | U3: 218070 | V3: =IF(AND(Y3=0,Z3=0),0,1) -> 1 | W3: =SUMIFS(Tabel132[Cluster],Tabel132[ID],A3) -> 0 | X3: =IFERROR(_xlfn.T.TEST(E3:M3,N3:U3,2,2),"") -> 0.90619485 | Y3: =AVERAGE(E3:M3) -> 236160 | Z3: =AVERAGE(N3:U3) -> 224331.38
A4: 1 | B4: Tuberomammillary nucleus, ventral part | C4: 75500 | D4: 557 | E4: 106 | F4: 15 | G4: 20 | H4: 0 | I4: 100 | J4: 22 | K4: 38 | L4: 17 | M4: 63 | N4: 4 | O4: 56 | P4: 87 | Q4: 0 | R4: 6 | S4: 6 | T4: 63 | U4: 25 | V4: =IF(AND(Y4=0,Z4=0),0,1) -> 1 | W4: =SUMIFS(Tabel132[Cluster],Tabel132[ID],A4) -> 84 | X4: =IFERROR(_xlfn.T.TEST(E4:M4,N4:U4,2,2),"") -> 0.52486842 | Y4: =AVERAGE(E4:M4) -> 42.333333 | Z4: =AVERAGE(N4:U4) -> 30.875
A5: 2 | B5: Primary somatosensory area, mouth, layer 6b | C5: 6200 | D5: 345 | E5: 1210 | F5: 309 | G5: 57 | H5: 405 | I5: 107 | J5: 232 | K5: 130 | L5: 330 | M5: 301 | N5: 196 | O5: 180 | P5: 549 | Q5: 37 | R5: 300 | S5: 208 | T5: 161 | U5: 415 | V5: =IF(AND(Y5=0,Z5=0),0,1) -> 1 | W5: =SUMIFS(Tabel132[Cluster],Tabel132[ID],A5) -> 8 | X5: =IFERROR(_xlfn.T.TEST(E5:M5,N5:U5,2,2),"") -> 0.52701758 | Y5: =AVERAGE(E5:M5) -> 342.33333 | Z5: =AVERAGE(N5:U5) -> 255.75
A6: 3 | B6: secondary fissure | C6: 118200 | D6: 1040 | E6: 0 | F6: 0 | G6: 0 | H6: 0 | I6: 0 | J6: 0 | K6: 0 | L6: 0 | M6: 0 | N6: 0 | O6: 0 | P6: 0 | Q6: 0 | R6: 0 | S6: 0 | T6: 0 | U6: 0 | V6: =IF(AND(Y6=0,Z6=0),0,1) -> 0 | W6: =SUMIFS(Tabel132[Cluster],Tabel132[ID],A6) -> 0 | X6: =IFERROR(_xlfn.T.TEST(E6:M6,N6:U6,2,2),"") | Y6: =AVERAGE(E6:M6) -> 0 | Z6: =AVERAGE(N6:U6) -> 0
A7: 4 | B7: Inferior colliculus | C7: 79100 | D7: 339 | E7: 53103 | F7: 1824 | G7: 14643 | H7: 9592 | I7: 15276 | J7: 43731 | K7: 52639 | L7: 14692 | M7: 19213 | N7: 7878 | O7: 42425 | P7: 23709 | Q7: 15300 | R7: 36902 | S7: 15417 | T7: 8161 | U7: 40191 | V7: =IF(AND(Y7=0,Z7=0),0,1) -> 1 | W7: =SUMIFS(Tabel132[Cluster],Tabel132[ID],A7) -> 86 | X7: =IFERROR(_xlfn.T.TEST(E7:M7,N7:U7,2,2),"") -> 0.8860025 | Y7: =AVERAGE(E7:M7) -> 24968.111 | Z7: =AVERAGE(N7:U7) -> 23747.875
A8: 6 | B8: internal capsule | C8: 107000 | D8: 784 | E8: 22324 | F8: 5860 | G8: 5870 | H8: 15768 | I8: 8243 | J8: 18404 | K8: 15279 | L8: 22672 | M8: 19394 | N8: 3482 | O8: 17074 | P8: 23993 | Q8: 2404 | R8: 15315 | S8: 15008 | T8: 5775 | U8: 15789 | V8: =IF(AND(Y8=0,Z8=0),0,1) -> 1 | W8: =SUMIFS(Tabel132[Cluster],Tabel132[ID],A8) -> 0 | X8: =IFERROR(_xlfn.T.TEST(E8:M8,N8:U8,2,2),"") -> 0.47943979 | Y8: =AVERAGE(E8:M8) -> 14868.222 | Z8: =AVERAGE(N8:U8) -> 12355
A9: 7 | B9: Principal sensory nucleus of the trigeminal | C9: 85300 | D9: 1132 | E9: 21202 | F9: 6573 | G9: 3702 | H9: 8977 | I9: 11014 | J9: 5858 | K9: 3751 | L9: 6162 | M9: 10312 | N9: 649 | O9: 6606 | P9: 9280 | Q9: 6123 | R9: 11416 | S9: 5313 | T9: 1380 | U9: 4418 | V9: =IF(AND(Y9=0,Z9=0),0,1) -> 1 | W9: =SUMIFS(Tabel132[Cluster],Tabel132[ID],A9) -> 93 | X9: =IFERROR(_xlfn.T.TEST(E9:M9,N9:U9,2,2),"") -> 0.20921948 | Y9: =AVERAGE(E9:M9) -> 8616.7778 | Z9: =AVERAGE(N9:U9) -> 5648.125
A10: 8 | B10: Basic cell groups and regions | C10: 100 | D10: 997 | E10: 0 | F10: 0 | G10: 0 | H10: 0 | I10: 0 | J10: 0 | K10: 0 | L10: 0 | M10: 0 | N10: 0 | O10: 0 | P10: 0 | Q10: 0 | R10: 0 | S10: 0 | T10: 0 | U10: 0 | V10: =IF(AND(Y10=0,Z10=0),0,1) -> 0 | W10: =SUMIFS(Tabel132[Cluster],Tabel132[ID],A10) -> 0 | X10: =IFERROR(_xlfn.T.TEST(E10:M10,N10:U10,2,2),"") | Y10: =AVERAGE(E10:M10) -> 0 | Z10: =AVERAGE(N10:U10) -> 0
A11: 9 | B11: Primary somatosensory area, trunk, layer 6a | C11: 7500 | D11: 361 | E11: 124 | F11: 0 | G11: 6 | H11: 22 | I11: 95 | J11: 590 | K11: 694 | L11: 136 | M11: 488 | N11: 606 | O11: 1561 | P11: 632 | Q11: 19 | R11: 57 | S11: 101 | T11: 402 | U11: 80 | V11: =IF(AND(Y11=0,Z11=0),0,1) -> 1 | W11: =SUMIFS(Tabel132[Cluster],Tabel132[ID],A11) -> 10 | X11: =IFERROR(_xlfn.T.TEST(E11:M11,N11:U11,2,2),"") -> 0.34516087 | Y11: =AVERAGE(E11:M11) -> 239.44444 | Z11: =AVERAGE(N11:U11) -> 432.25
A12: 10 | B12: Superior colliculus, motor related, intermediate gray layer | C12: 81100 | D12: 294 | E12: 11490 | F12: 752 | G12: 4423 | H12: 1568 | I12: 1582 | J12: 19004 | K12: 11964 | L12: 1708 | M12: 11846 | N12: 4352 | O12: 10377 | P12: 2023 | Q12: 2343 | R12: 11015 | S12: 7367 | T12: 2017 | U12: 13843 | V12: =IF(AND(Y12=0,Z12=0),0,1) -> 1 | W12: =SUMIFS(Tabel132[Cluster],Tabel132[ID],A12) -> 89 | X12: =IFERROR(_xlfn.T.TEST(E12:M12,N12:U12,2,2),"") -> 0.86559049 | Y12: =AVERAGE(E12:M12) -> 7148.5556 | Z12: =AVERAGE(N12:U12) -> 6667.125
A13: 11 | B13: posterolateral fissure | C13: 118300 | D13: 1040 | E13: 0 | F13: 0 | G13: 0 | H13: 0 | I13: 0 | J13: 0 | K13: 0 | L13: 0 | M13: 0 | N13: 0 | O13: 0 | P13: 0 | Q13: 0 | R13: 0 | S13: 0 | T13: 0 | U13: 0 | V13: =IF(AND(Y13=0,Z13=0),0,1) -> 0 | W13: =SUMIFS(Tabel132[Cluster],Tabel132[ID],A13) -> 0 | X13: =IFERROR(_xlfn.T.TEST(E13:M13,N13:U13,2,2),"") | Y13: =AVERAGE(E13:M13) -> 0 | Z13: =AVERAGE(N13:U13) -> 0
A14: 12 | B14: Interfascicular nucleus raphÈ | C14: 84100 | D14: 165 | E14: 0 | F14: 0 | G14: 0 | H14: 0 | I14: 0 | J14: 0 | K14: 0 | L14: 0 | M14: 0 | N14: 0 | O14: 0 | P14: 0 | Q14: 0 | R14: 0 | S14: 0 | T14: 0 | U14: 0 | V14: =IF(AND(Y14=0,Z14=0),0,1) -> 0 | W14: =SUMIFS(Tabel132[Cluster],Tabel132[ID],A14) -> 92 | X14: =IFERROR(_xlfn.T.TEST(E14:M14,N14:U14,2,2),"") | Y14: =AVERAGE(E14:M14) -> 0 | Z14: =AVERAGE(N14:U14) -> 0
A15: 14 | B15: internal medullary lamina of the thalamus | C15: 108200 | D15: 896 | E15: 7 | F15: 1 | G15: 0 | H15: 0 | I15: 0 | J15: 18 | K15: 0 | L15: 0 | M15: 0 | N15: 0 | O15: 4 | P15: 1 | Q15: 0 | R15: 1 | S15: 0 | T15: 0 | U15: 3 | V15: =IF(AND(Y15=0,Z15=0),0,1) -> 1 | W15: =SUMIFS(Tabel132[Cluster],Tabel132[ID],A15) -> 0 | X15: =IFERROR(_xlfn.T.TEST(E15:M15,N15:U15,2,2),"") -> 0.44116827 | Y15: =AVERAGE(E15:M15) -> 2.8888889 | Z15: =AVERAGE(N15:U15) -> 1.125
... A988: 996 | B988: Agranular insular area, dorsal part, layer 1 | C988: 23500 | D988: 104 | E988: 8681 | F988: 5150 | G988: 2790 | H988: 6440 | I988: 2746 | J988: 3526 | K988: 7265 | L988: 3752 | M988: 6484 | N988: 644 | O988: 6250 | P988: 4819 | Q988: 528 | R988: 7713 | S988: 6472 | T988: 1631 | U988: 2959 | V988: =IF(AND(Y988=0,Z988=0),0,1) -> 1 | W988: =SUMIFS(Tabel132[Cluster],Tabel132[ID],A988) -> 30 | X988: =IFERROR(_xlfn.T.TEST(E988:M988,N988:U988,2,2),"") -> 0.28715702 | Y988: =AVERAGE(E988:M988) -> 5203.7778 | Z988: =AVERAGE(N988:U988) -> 3877
A989: 997 | B989: root | C989: 0 | E989: 7 | F989: 1 | G989: 1 | H989: 3 | I989: 8 | J989: 2 | K989: 0 | L989: 1 | M989: 3 | N989: 0 | O989: 3 | P989: 7 | Q989: 0 | R989: 3 | S989: 1 | T989: 4 | U989: 5 | V989: =IF(AND(Y989=0,Z989=0),0,1) -> 1 | W989: =SUMIFS(Tabel132[Cluster],Tabel132[ID],A989) -> 0 | X989: =IFERROR(_xlfn.T.TEST(E989:M989,N989:U989,2,2),"") -> 0.99155335 | Y989: =AVERAGE(E989:M989) -> 2.8888889 | Z989: =AVERAGE(N989:U989) -> 2.875
A990: 998 | B990: Fundus of striatum | C990: 48500 | D990: 493 | E990: 2945 | F990: 1341 | G990: 916 | H990: 704 | I990: 2051 | J990: 3563 | K990: 1888 | L990: 7055 | M990: 3242 | N990: 508 | O990: 2155 | P990: 3047 | Q990: 381 | R990: 3603 | S990: 2370 | T990: 1018 | U990: 2635 | V990: =IF(AND(Y990=0,Z990=0),0,1) -> 1 | W990: =SUMIFS(Tabel132[Cluster],Tabel132[ID],A990) -> 64 | X990: =IFERROR(_xlfn.T.TEST(E990:M990,N990:U990,2,2),"") -> 0.41309014 | Y990: =AVERAGE(E990:M990) -> 2633.8889 | Z990: =AVERAGE(N990:U990) -> 1964.625
A991: 999 | B991: Entorhinal area, lateral part, layer 2/3 | C991: 41600 | D991: 918 | E991: 0 | F991: 0 | G991: 0 | H991: 0 | I991: 0 | J991: 0 | K991: 0 | L991: 0 | M991: 0 | N991: 0 | O991: 0 | P991: 0 | Q991: 0 | R991: 0 | S991: 0 | T991: 0 | U991: 0 | V991: =IF(AND(Y991=0,Z991=0),0,1) -> 0 | W991: =SUMIFS(Tabel132[Cluster],Tabel132[ID],A991) -> 54 | X991: =IFERROR(_xlfn.T.TEST(E991:M991,N991:U991,2,2),"") | Y991: =AVERAGE(E991:M991) -> 0 | Z991: =AVERAGE(N991:U991) -> 0
A992: 1000 | B992: extrapyramidal fiber systems | C992: 108500 | D992: 1009 | E992: 0 | F992: 0 | G992: 0 | H992: 0 | I992: 0 | J992: 0 | K992: 0 | L992: 0 | M992: 0 | N992: 0 | O992: 0 | P992: 0 | Q992: 0 | R992: 0 | S992: 0 | T992: 0 | U992: 0 | V992: =IF(AND(Y992=0,Z992=0),0,1) -> 0 | W992: =SUMIFS(Tabel132[Cluster],Tabel132[ID],A992) -> 0 | X992: =IFERROR(_xlfn.T.TEST(E992:M992,N992:U992,2,2),"") | Y992: =AVERAGE(E992:M992) -> 0 | Z992: =AVERAGE(N992:U992) -> 0
A993: 1001 | B993: Lobule V | C993: 56800 | D993: 928 | E993: 0 | F993: 0 | G993: 0 | H993: 0 | I993: 0 | J993: 0 | K993: 0 | L993: 0 | M993: 0 | N993: 0 | O993: 0 | P993: 0 | Q993: 0 | R993: 0 | S993: 0 | T993: 0 | U993: 0 | V993: =IF(AND(Y993=0,Z993=0),0,1) -> 0 | W993: =SUMIFS(Tabel132[Cluster],Tabel132[ID],A993) -> 0 | X993: =IFERROR(_xlfn.T.TEST(E993:M993,N993:U993,2,2),"") | Y993: =AVERAGE(E993:M993) -> 0 | Z993: =AVERAGE(N993:U993) -> 0
A994: 1002 | B994: Primary auditory area | C994: 11300 | D994: 247 | E994: 0 | F994: 0 | G994: 0 | H994: 0 | I994: 0 | J994: 0 | K994: 0 | L994: 0 | M994: 0 | N994: 0 | O994: 0 | P994: 0 | Q994: 0 | R994: 0 | S994: 0 | T994: 0 | U994: 0 | V994: =IF(AND(Y994=0,Z994=0),0,1) -> 0 | W994: =SUMIFS(Tabel132[Cluster],Tabel132[ID],A994) -> 15 | X994: =IFERROR(_xlfn.T.TEST(E994:M994,N994:U994,2,2),"") | Y994: =AVERAGE(E994:M994) -> 0 | Z994: =AVERAGE(N994:U994) -> 0
A995: 1003 | B995: corticopontine tract | C995: 107400 | D995: 784 | E995: 0 | F995: 0 | G995: 0 | H995: 0 | I995: 0 | J995: 0 | K995: 0 | L995: 0 | M995: 0 | N995: 0 | O995: 0 | P995: 0 | Q995: 0 | R995: 0 | S995: 0 | T995: 0 | U995: 0 | V995: =IF(AND(Y995=0,Z995=0),0,1) -> 0 | W995: =SUMIFS(Tabel132[Cluster],Tabel132[ID],A995) -> 0 | X995: =IFERROR(_xlfn.T.TEST(E995:M995,N995:U995,2,2),"") | Y995: =AVERAGE(E995:M995) -> 0 | Z995: =AVERAGE(N995:U995) -> 0
A996: 1004 | B996: Ventral premammillary nucleus | C996: 76100 | D996: 467 | E996: 164 | F996: 5 | G996: 117 | H996: 5 | I996: 108 | J996: 184 | K996: 81 | L996: 20 | M996: 50 | N996: 4 | O996: 38 | P996: 9 | Q996: 0 | R996: 0 | S996: 0 | T996: 103 | U996: 398 | V996: =IF(AND(Y996=0,Z996=0),0,1) -> 1 | W996: =SUMIFS(Tabel132[Cluster],Tabel132[ID],A996) -> 84 | X996: =IFERROR(_xlfn.T.TEST(E996:M996,N996:U996,2,2),"") -> 0.81053906 | Y996: =AVERAGE(E996:M996) -> 81.555556 | Z996: =AVERAGE(N996:U996) -> 69
A997: 1005 | B997: Primary auditory area, layer 6b | C997: 11900 | D997: 1002 | E997: 1141 | F997: 47 | G997: 266 | H997: 118 | I997: 8 | J997: 223 | K997: 304 | L997: 767 | M997: 182 | N997: 307 | O997: 257 | P997: 147 | Q997: 109 | R997: 331 | S997: 16 | T997: 453 | U997: 175 | V997: =IF(AND(Y997=0,Z997=0),0,1) -> 1 | W997: =SUMIFS(Tabel132[Cluster],Tabel132[ID],A997) -> 15 | X997: =IFERROR(_xlfn.T.TEST(E997:M997,N997:U997,2,2),"") -> 0.42468433 | Y997: =AVERAGE(E997:M997) -> 339.55556 | Z997: =AVERAGE(N997:U997) -> 224.375
A998: 1006 | B998: Primary somatosensory area, trunk, layer 1 | C998: 7100 | D998: 361 | E998: 272 | F998: 52 | G998: 70 | H998: 434 | I998: 334 | J998: 232 | K998: 181 | L998: 5 | M998: 312 | N998: 177 | O998: 392 | P998: 1673 | Q998: 211 | R998: 544 | S998: 771 | T998: 399 | U998: 198 | V998: =IF(AND(Y998=0,Z998=0),0,1) -> 1 | W998: =SUMIFS(Tabel132[Cluster],Tabel132[ID],A998) -> 10 | X998: =IFERROR(_xlfn.T.TEST(E998:M998,N998:U998,2,2),"") -> 0.07171155 | Y998: =AVERAGE(E998:M998) -> 210.22222 | Z998: =AVERAGE(N998:U998) -> 545.625
A999: 1007 | B999: Simple lobule | C999: 59700 | D999: 1073 | E999: 57949 | F999: 2765 | G999: 9564 | H999: 15875 | I999: 16184 | J999: 12662 | K999: 19069 | L999: 8287 | M999: 13593 | N999: 8165 | O999: 19146 | P999: 19112 | Q999: 3437 | R999: 13918 | S999: 14983 | T999: 7919 | U999: 20104 | V999: =IF(AND(Y999=0,Z999=0),0,1) -> 1 | W999: =SUMIFS(Tabel132[Cluster],Tabel132[ID],A999) -> 0 | X999: =IFERROR(_xlfn.T.TEST(E999:M999,N999:U999,2,2),"") -> 0.51985532 | Y999: =AVERAGE(E999:M999) -> 17327.556 | Z999: =AVERAGE(N999:U999) -> 13348
A1000: 1008 | B1000: Geniculate group, dorsal thalamus | C1000: 65000 | D1000: 864 | E1000: 0 | F1000: 0 | G1000: 0 | H1000: 0 | I1000: 0 | J1000: 0 | K1000: 0 | L1000: 0 | M1000: 0 | N1000: 0 | O1000: 0 | P1000: 0 | Q1000: 0 | R1000: 0 | S1000: 0 | T1000: 0 | U1000: 0 | V1000: =IF(AND(Y1000=0,Z1000=0),0,1) -> 0 | W1000: =SUMIFS(Tabel132[Cluster],Tabel132[ID],A1000) -> 77 | X1000: =IFERROR(_xlfn.T.TEST(E1000:M1000,N1000:U1000,2,2),"") | Y1000: =AVERAGE(E1000:M1000) -> 0 | Z1000: =AVERAGE(N1000:U1000) -> 0
A1001: 1009 | B1001: fiber tracts | C1001: 97200 | D1001: 997 | E1001: 24056 | F1001: 4505 | G1001: 3321 | H1001: 4344 | I1001: 3738 | J1001: 8132 | K1001: 7039 | L1001: 13129 | M1001: 9954 | N1001: 5074 | O1001: 8884 | P1001: 11656 | Q1001: 3243 | R1001: 6631 | S1001: 5619 | T1001: 6562 | U1001: 8778 | V1001: =IF(AND(Y1001=0,Z1001=0),0,1) -> 1 | W1001: =SUMIFS(Tabel132[Cluster],Tabel132[ID],A1001) -> 0 | X1001: =IFERROR(_xlfn.T.TEST(E1001:M1001,N1001:U1001,2,2),"") -> 0.52381685 | Y1001: =AVERAGE(E1001:M1001) -> 8690.8889 | Z1001: =AVERAGE(N1001:U1001) -> 7055.875
... A1244: 312782656 | B1244: Unlabeled | C1244: 300 | D1244: 688 | E1244: 6933 | F1244: 1266 | G1244: 2908 | H1244: 2209 | I1244: 880 | J1244: 3093 | K1244: 2491 | L1244: 4055 | M1244: 2243 | N1244: 4092 | O1244: 4760 | P1244: 3309 | Q1244: 1053 | R1244: 1921 | S1244: 2835 | T1244: 1343 | U1244: 3055 | V1244: =IF(AND(Y1244=0,Z1244=0),0,1) -> 1 | W1244: =SUMIFS(Tabel132[Cluster],Tabel132[ID],A1244) -> 0 | X1244: =IFERROR(_xlfn.T.TEST(E1244:M1244,N1244:U1244,2,2),"") -> 0.89624756 | Y1244: =AVERAGE(E1244:M1244) -> 2897.5556 | Z1244: =AVERAGE(N1244:U1244) -> 2796
E1246: =SUM(E3:E1244) -> 5353836 | F1246: =SUM(F3:F1244) -> 1219068 | G1246: =SUM(G3:G1244) -> 992764 | H1246: =SUM(H3:H1244) -> 1432601 | I1246: =SUM(I3:I1244) -> 1624195 | J1246: =SUM(J3:J1244) -> 2028084 | K1246: =SUM(K3:K1244) -> 2242375 | L1246: =SUM(L3:L1244) -> 2267668 | ... U1246: =SUM(U3:U1244) -> 2304430

Sheet Total-corrected counts
E1: 0 | F1: 0 | G1: 0 | H1: 0 | I1: 0 | J1: 0 | K1: 0 | L1: 0 | M1: 0 | N1: 1 | O1: 1 | P1: 1 | Q1: 1 | R1: 1 | S1: 1 | T1: 1 | U1: 1
A2: id | B2: name | C2: structure_order | D2: parent_id | E2: 124 | F2: 143 | G2: 146 | H2: 152 | I2: 170 | J2: 171 | K2: 175 | L2: 183 | M2: 200 | N2: 113 | O2: 172 | P2: 177 | Q2: 178 | R2: 179 | S2: 180 | T2: 184 | U2: 207 | V2: Filter | W2: T-test | X2: Gem 0 | Y2: Gem 1
A3: 0 | B3: background | C3: 0 | E3: ='Raw counts'!E3/'Raw counts'!E$1246*10000 -> 1745.6941 | F3: ='Raw counts'!F3/'Raw counts'!F$1246*10000 -> 1329.8192 | G3: ='Raw counts'!G3/'Raw counts'!G$1246*10000 -> 709.09098 | H3: ='Raw counts'!H3/'Raw counts'!H$1246*10000 -> 1294.3869 | I3: ='Raw counts'!I3/'Raw counts'!I$1246*10000 -> 1183.7618 | J3: ='Raw counts'!J3/'Raw counts'!J$1246*10000 -> 611.53779 | K3: ='Raw counts'!K3/'Raw counts'!K$1246*10000 -> 647.22448 | L3: ='Raw counts'!L3/'Raw counts'!L$1246*10000 -> 512.90577 | ... U3: ='Raw counts'!U3/'Raw counts'!U$1246*10000 -> 946.30776 | V3: =IF(AND(X3=0,Y3=0),0,1) -> 1 | W3: =IFERROR(_xlfn.T.TEST(E3:M3,N3:U3,2,2),"") -> 0.24381384 | X3: =AVERAGE(E3:M3) -> 992.62102 | Y3: =AVERAGE(N3:U3) -> 1262.7244
A4: 1 | B4: Tuberomammillary nucleus, ventral part | C4: 75500 | D4: 557 | E4: ='Raw counts'!E4/'Raw counts'!E$1246*10000 -> 0.19798888 | F4: ='Raw counts'!F4/'Raw counts'!F$1246*10000 -> 0.12304482 | G4: ='Raw counts'!G4/'Raw counts'!G$1246*10000 -> 0.20145775 | H4: ='Raw counts'!H4/'Raw counts'!H$1246*10000 -> 0 | I4: ='Raw counts'!I4/'Raw counts'!I$1246*10000 -> 0.61568962 | J4: ='Raw counts'!J4/'Raw counts'!J$1246*10000 -> 0.10847677 | K4: ='Raw counts'!K4/'Raw counts'!K$1246*10000 -> 0.16946318 | L4: ='Raw counts'!L4/'Raw counts'!L$1246*10000 -> 0.074966882 | ... U4: ='Raw counts'!U4/'Raw counts'!U$1246*10000 -> 0.1084867 | V4: =IF(AND(X4=0,Y4=0),0,1) -> 1 | W4: =IFERROR(_xlfn.T.TEST(E4:M4,N4:U4,2,2),"") -> 0.70436917 | X4: =AVERAGE(E4:M4) -> 0.19792995 | Y4: =AVERAGE(N4:U4) -> 0.16290853
A5: 2 | B5: Primary somatosensory area, mouth, layer 6b | C5: 6200 | D5: 345 | E5: ='Raw counts'!E5/'Raw counts'!E$1246*10000 -> 2.2600618 | F5: ='Raw counts'!F5/'Raw counts'!F$1246*10000 -> 2.5347232 | G5: ='Raw counts'!G5/'Raw counts'!G$1246*10000 -> 0.57415458 | H5: ='Raw counts'!H5/'Raw counts'!H$1246*10000 -> 2.8270258 | I5: ='Raw counts'!I5/'Raw counts'!I$1246*10000 -> 0.65878789 | J5: ='Raw counts'!J5/'Raw counts'!J$1246*10000 -> 1.1439368 | K5: ='Raw counts'!K5/'Raw counts'!K$1246*10000 -> 0.57974246 | L5: ='Raw counts'!L5/'Raw counts'!L$1246*10000 -> 1.4552395 | ... U5: ='Raw counts'!U5/'Raw counts'!U$1246*10000 -> 1.8008792 | V5: =IF(AND(X5=0,Y5=0),0,1) -> 1 | W5: =IFERROR(_xlfn.T.TEST(E5:M5,N5:U5,2,2),"") -> 0.6701315 | X5: =AVERAGE(E5:M5) -> 1.4911748 | Y5: =AVERAGE(N5:U5) -> 1.3280348
A6: 3 | B6: secondary fissure | C6: 118200 | D6: 1040 | E6: ='Raw counts'!E6/'Raw counts'!E$1246*10000 -> 0 | F6: ='Raw counts'!F6/'Raw counts'!F$1246*10000 -> 0 | G6: ='Raw counts'!G6/'Raw counts'!G$1246*10000 -> 0 | H6: ='Raw counts'!H6/'Raw counts'!H$1246*10000 -> 0 | I6: ='Raw counts'!I6/'Raw counts'!I$1246*10000 -> 0 | J6: ='Raw counts'!J6/'Raw counts'!J$1246*10000 -> 0 | K6: ='Raw counts'!K6/'Raw counts'!K$1246*10000 -> 0 | L6: ='Raw counts'!L6/'Raw counts'!L$1246*10000 -> 0 | ... U6: ='Raw counts'!U6/'Raw counts'!U$1246*10000 -> 0 | V6: =IF(AND(X6=0,Y6=0),0,1) -> 0 | W6: =IFERROR(_xlfn.T.TEST(E6:M6,N6:U6,2,2),"") | X6: =AVERAGE(E6:M6) -> 0 | Y6: =AVERAGE(N6:U6) -> 0
A7: 4 | B7: Inferior colliculus | C7: 79100 | D7: 339 | E7: ='Raw counts'!E7/'Raw counts'!E$1246*10000 -> 99.186826 | F7: ='Raw counts'!F7/'Raw counts'!F$1246*10000 -> 14.96225 | G7: ='Raw counts'!G7/'Raw counts'!G$1246*10000 -> 147.49729 | H7: ='Raw counts'!H7/'Raw counts'!H$1246*10000 -> 66.95514 | I7: ='Raw counts'!I7/'Raw counts'!I$1246*10000 -> 94.052746 | J7: ='Raw counts'!J7/'Raw counts'!J$1246*10000 -> 215.62716 | K7: ='Raw counts'!K7/'Raw counts'!K$1246*10000 -> 234.74664 | L7: ='Raw counts'!L7/'Raw counts'!L$1246*10000 -> 64.789026 | ... U7: ='Raw counts'!U7/'Raw counts'!U$1246*10000 -> 174.40755 | V7: =IF(AND(X7=0,Y7=0),0,1) -> 1 | W7: =IFERROR(_xlfn.T.TEST(E7:M7,N7:U7,2,2),"") -> 0.90115181 | X7: =AVERAGE(E7:M7) -> 114.0382 | Y7: =AVERAGE(N7:U7) -> 117.69538
A8: 6 | B8: internal capsule | C8: 107000 | D8: 784 | E8: ='Raw counts'!E8/'Raw counts'!E$1246*10000 -> 41.697206 | F8: ='Raw counts'!F8/'Raw counts'!F$1246*10000 -> 48.069509 | G8: ='Raw counts'!G8/'Raw counts'!G$1246*10000 -> 59.127849 | H8: ='Raw counts'!H8/'Raw counts'!H$1246*10000 -> 110.06554 | I8: ='Raw counts'!I8/'Raw counts'!I$1246*10000 -> 50.751295 | J8: ='Raw counts'!J8/'Raw counts'!J$1246*10000 -> 90.745748 | K8: ='Raw counts'!K8/'Raw counts'!K$1246*10000 -> 68.137577 | L8: ='Raw counts'!L8/'Raw counts'!L$1246*10000 -> 99.979362 | ... U8: ='Raw counts'!U8/'Raw counts'!U$1246*10000 -> 68.515859 | V8: =IF(AND(X8=0,Y8=0),0,1) -> 1 | W8: =IFERROR(_xlfn.T.TEST(E8:M8,N8:U8,2,2),"") -> 0.28674779 | X8: =AVERAGE(E8:M8) -> 73.103862 | Y8: =AVERAGE(N8:U8) -> 59.539757
A9: 7 | B9: Principal sensory nucleus of the trigeminal | C9: 85300 | D9: 1132 | E9: ='Raw counts'!E9/'Raw counts'!E$1246*10000 -> 39.601512 | F9: ='Raw counts'!F9/'Raw counts'!F$1246*10000 -> 53.918239 | G9: ='Raw counts'!G9/'Raw counts'!G$1246*10000 -> 37.289829 | H9: ='Raw counts'!H9/'Raw counts'!H$1246*10000 -> 62.662249 | I9: ='Raw counts'!I9/'Raw counts'!I$1246*10000 -> 67.812055 | J9: ='Raw counts'!J9/'Raw counts'!J$1246*10000 -> 28.884405 | K9: ='Raw counts'!K9/'Raw counts'!K$1246*10000 -> 16.7278 | L9: ='Raw counts'!L9/'Raw counts'!L$1246*10000 -> 27.17329 | ... U9: ='Raw counts'!U9/'Raw counts'!U$1246*10000 -> 19.171769 | V9: =IF(AND(X9=0,Y9=0),0,1) -> 1 | W9: =IFERROR(_xlfn.T.TEST(E9:M9,N9:U9,2,2),"") -> 0.14127468 | X9: =AVERAGE(E9:M9) -> 42.398157 | Y9: =AVERAGE(N9:U9) -> 29.144733
A10: 8 | B10: Basic cell groups and regions | C10: 100 | D10: 997 | E10: ='Raw counts'!E10/'Raw counts'!E$1246*10000 -> 0 | F10: ='Raw counts'!F10/'Raw counts'!F$1246*10000 -> 0 | G10: ='Raw counts'!G10/'Raw counts'!G$1246*10000 -> 0 | H10: ='Raw counts'!H10/'Raw counts'!H$1246*10000 -> 0 | I10: ='Raw counts'!I10/'Raw counts'!I$1246*10000 -> 0 | J10: ='Raw counts'!J10/'Raw counts'!J$1246*10000 -> 0 | K10: ='Raw counts'!K10/'Raw counts'!K$1246*10000 -> 0 | L10: ='Raw counts'!L10/'Raw counts'!L$1246*10000 -> 0 | ... U10: ='Raw counts'!U10/'Raw counts'!U$1246*10000 -> 0 | V10: =IF(AND(X10=0,Y10=0),0,1) -> 0 | W10: =IFERROR(_xlfn.T.TEST(E10:M10,N10:U10,2,2),"") | X10: =AVERAGE(E10:M10) -> 0 | Y10: =AVERAGE(N10:U10) -> 0
A11: 9 | B11: Primary somatosensory area, trunk, layer 6a | C11: 7500 | D11: 361 | E11: ='Raw counts'!E11/'Raw counts'!E$1246*10000 -> 0.23160963 | F11: ='Raw counts'!F11/'Raw counts'!F$1246*10000 -> 0 | G11: ='Raw counts'!G11/'Raw counts'!G$1246*10000 -> 0.060437324 | H11: ='Raw counts'!H11/'Raw counts'!H$1246*10000 -> 0.15356683 | I11: ='Raw counts'!I11/'Raw counts'!I$1246*10000 -> 0.58490514 | J11: ='Raw counts'!J11/'Raw counts'!J$1246*10000 -> 2.9091497 | K11: ='Raw counts'!K11/'Raw counts'!K$1246*10000 -> 3.0949328 | L11: ='Raw counts'!L11/'Raw counts'!L$1246*10000 -> 0.59973506 | ... U11: ='Raw counts'!U11/'Raw counts'!U$1246*10000 -> 0.34715743 | V11: =IF(AND(X11=0,Y11=0),0,1) -> 1 | W11: =IFERROR(_xlfn.T.TEST(E11:M11,N11:U11,2,2),"") -> 0.19902644 | X11: =AVERAGE(E11:M11) -> 1.0980964 | Y11: =AVERAGE(N11:U11) -> 2.2838126
A12: 10 | B12: Superior colliculus, motor related, intermediate gray layer | C12: 81100 | D12: 294 | E12: ='Raw counts'!E12/'Raw counts'!E$1246*10000 -> 21.461248 | F12: ='Raw counts'!F12/'Raw counts'!F$1246*10000 -> 6.1686469 | G12: ='Raw counts'!G12/'Raw counts'!G$1246*10000 -> 44.552381 | H12: ='Raw counts'!H12/'Raw counts'!H$1246*10000 -> 10.945127 | I12: ='Raw counts'!I12/'Raw counts'!I$1246*10000 -> 9.7402098 | J12: ='Raw counts'!J12/'Raw counts'!J$1246*10000 -> 93.704206 | K12: ='Raw counts'!K12/'Raw counts'!K$1246*10000 -> 53.354145 | L12: ='Raw counts'!L12/'Raw counts'!L$1246*10000 -> 7.5319668 | ... U12: ='Raw counts'!U12/'Raw counts'!U$1246*10000 -> 60.071254 | V12: =IF(AND(X12=0,Y12=0),0,1) -> 1 | W12: =IFERROR(_xlfn.T.TEST(E12:M12,N12:U12,2,2),"") -> 0.99463626 | X12: =AVERAGE(E12:M12) -> 33.56001 | Y12: =AVERAGE(N12:U12) -> 33.478105
A13: 11 | B13: posterolateral fissure | C13: 118300 | D13: 1040 | E13: ='Raw counts'!E13/'Raw counts'!E$1246*10000 -> 0 | F13: ='Raw counts'!F13/'Raw counts'!F$1246*10000 -> 0 | G13: ='Raw counts'!G13/'Raw counts'!G$1246*10000 -> 0 | H13: ='Raw counts'!H13/'Raw counts'!H$1246*10000 -> 0 | I13: ='Raw counts'!I13/'Raw counts'!I$1246*10000 -> 0 | J13: ='Raw counts'!J13/'Raw counts'!J$1246*10000 -> 0 | K13: ='Raw counts'!K13/'Raw counts'!K$1246*10000 -> 0 | L13: ='Raw counts'!L13/'Raw counts'!L$1246*10000 -> 0 | ... U13: ='Raw counts'!U13/'Raw counts'!U$1246*10000 -> 0 | V13: =IF(AND(X13=0,Y13=0),0,1) -> 0 | W13: =IFERROR(_xlfn.T.TEST(E13:M13,N13:U13,2,2),"") | X13: =AVERAGE(E13:M13) -> 0 | Y13: =AVERAGE(N13:U13) -> 0
A14: 12 | B14: Interfascicular nucleus raphÈ | C14: 84100 | D14: 165 | E14: ='Raw counts'!E14/'Raw counts'!E$1246*10000 -> 0 | F14: ='Raw counts'!F14/'Raw counts'!F$1246*10000 -> 0 | G14: ='Raw counts'!G14/'Raw counts'!G$1246*10000 -> 0 | H14: ='Raw counts'!H14/'Raw counts'!H$1246*10000 -> 0 | I14: ='Raw counts'!I14/'Raw counts'!I$1246*10000 -> 0 | J14: ='Raw counts'!J14/'Raw counts'!J$1246*10000 -> 0 | K14: ='Raw counts'!K14/'Raw counts'!K$1246*10000 -> 0 | L14: ='Raw counts'!L14/'Raw counts'!L$1246*10000 -> 0 | ... U14: ='Raw counts'!U14/'Raw counts'!U$1246*10000 -> 0 | V14: =IF(AND(X14=0,Y14=0),0,1) -> 0 | W14: =IFERROR(_xlfn.T.TEST(E14:M14,N14:U14,2,2),"") | X14: =AVERAGE(E14:M14) -> 0 | Y14: =AVERAGE(N14:U14) -> 0
A15: 14 | B15: internal medullary lamina of the thalamus | C15: 108200 | D15: 896 | E15: ='Raw counts'!E15/'Raw counts'!E$1246*10000 -> 0.013074737 | F15: ='Raw counts'!F15/'Raw counts'!F$1246*10000 -> 0.0082029879 | G15: ='Raw counts'!G15/'Raw counts'!G$1246*10000 -> 0 | H15: ='Raw counts'!H15/'Raw counts'!H$1246*10000 -> 0 | I15: ='Raw counts'!I15/'Raw counts'!I$1246*10000 -> 0 | J15: ='Raw counts'!J15/'Raw counts'!J$1246*10000 -> 0.08875372 | K15: ='Raw counts'!K15/'Raw counts'!K$1246*10000 -> 0 | L15: ='Raw counts'!L15/'Raw counts'!L$1246*10000 -> 0 | ... U15: ='Raw counts'!U15/'Raw counts'!U$1246*10000 -> 0.013018404 | V15: =IF(AND(X15=0,Y15=0),0,1) -> 1 | W15: =IFERROR(_xlfn.T.TEST(E15:M15,N15:U15,2,2),"") -> 0.46454526 | X15: =AVERAGE(E15:M15) -> 0.012225716 | Y15: =AVERAGE(N15:U15) -> 0.004345064
... A988: 996 | B988: Agranular insular area, dorsal part, layer 1 | C988: 23500 | D988: 104 | E988: ='Raw counts'!E988/'Raw counts'!E$1246*10000 -> 16.214542 | F988: ='Raw counts'!F988/'Raw counts'!F$1246*10000 -> 42.245387 | G988: ='Raw counts'!G988/'Raw counts'!G$1246*10000 -> 28.103356 | H988: ='Raw counts'!H988/'Raw counts'!H$1246*10000 -> 44.953201 | I988: ='Raw counts'!I988/'Raw counts'!I$1246*10000 -> 16.906837 | J988: ='Raw counts'!J988/'Raw counts'!J$1246*10000 -> 17.385868 | K988: ='Raw counts'!K988/'Raw counts'!K$1246*10000 -> 32.398684 | L988: ='Raw counts'!L988/'Raw counts'!L$1246*10000 -> 16.545632 | ... U988: ='Raw counts'!U988/'Raw counts'!U$1246*10000 -> 12.840485 | V988: =IF(AND(X988=0,Y988=0),0,1) -> 1 | W988: =IFERROR(_xlfn.T.TEST(E988:M988,N988:U988,2,2),"") -> 0.11600342 | X988: =AVERAGE(E988:M988) -> 27.181053 | Y988: =AVERAGE(N988:U988) -> 18.196283
A989: 997 | B989: root | C989: 0 | E989: ='Raw counts'!E989/'Raw counts'!E$1246*10000 -> 0.013074737 | F989: ='Raw counts'!F989/'Raw counts'!F$1246*10000 -> 0.0082029879 | G989: ='Raw counts'!G989/'Raw counts'!G$1246*10000 -> 0.010072887 | H989: ='Raw counts'!H989/'Raw counts'!H$1246*10000 -> 0.020940932 | I989: ='Raw counts'!I989/'Raw counts'!I$1246*10000 -> 0.049255169 | J989: ='Raw counts'!J989/'Raw counts'!J$1246*10000 -> 0.0098615245 | K989: ='Raw counts'!K989/'Raw counts'!K$1246*10000 -> 0 | L989: ='Raw counts'!L989/'Raw counts'!L$1246*10000 -> 0.0044098166 | ... U989: ='Raw counts'!U989/'Raw counts'!U$1246*10000 -> 0.021697339 | V989: =IF(AND(X989=0,Y989=0),0,1) -> 1 | W989: =IFERROR(_xlfn.T.TEST(E989:M989,N989:U989,2,2),"") -> 0.97494322 | X989: =AVERAGE(E989:M989) -> 0.014404555 | Y989: =AVERAGE(N989:U989) -> 0.014190409
A990: 998 | B990: Fundus of striatum | C990: 48500 | D990: 493 | E990: ='Raw counts'!E990/'Raw counts'!E$1246*10000 -> 5.5007288 | F990: ='Raw counts'!F990/'Raw counts'!F$1246*10000 -> 11.000207 | G990: ='Raw counts'!G990/'Raw counts'!G$1246*10000 -> 9.2267649 | H990: ='Raw counts'!H990/'Raw counts'!H$1246*10000 -> 4.9141387 | I990: ='Raw counts'!I990/'Raw counts'!I$1246*10000 -> 12.627794 | J990: ='Raw counts'!J990/'Raw counts'!J$1246*10000 -> 17.568306 | K990: ='Raw counts'!K990/'Raw counts'!K$1246*10000 -> 8.4196444 | L990: ='Raw counts'!L990/'Raw counts'!L$1246*10000 -> 31.111256 | ... U990: ='Raw counts'!U990/'Raw counts'!U$1246*10000 -> 11.434498 | V990: =IF(AND(X990=0,Y990=0),0,1) -> 1 | W990: =IFERROR(_xlfn.T.TEST(E990:M990,N990:U990,2,2),"") -> 0.31099302 | X990: =AVERAGE(E990:M990) -> 12.811869 | Y990: =AVERAGE(N990:U990) -> 9.5159759
A991: 999 | B991: Entorhinal area, lateral part, layer 2/3 | C991: 41600 | D991: 918 | E991: ='Raw counts'!E991/'Raw counts'!E$1246*10000 -> 0 | F991: ='Raw counts'!F991/'Raw counts'!F$1246*10000 -> 0 | G991: ='Raw counts'!G991/'Raw counts'!G$1246*10000 -> 0 | H991: ='Raw counts'!H991/'Raw counts'!H$1246*10000 -> 0 | I991: ='Raw counts'!I991/'Raw counts'!I$1246*10000 -> 0 | J991: ='Raw counts'!J991/'Raw counts'!J$1246*10000 -> 0 | K991: ='Raw counts'!K991/'Raw counts'!K$1246*10000 -> 0 | L991: ='Raw counts'!L991/'Raw counts'!L$1246*10000 -> 0 | ... U991: ='Raw counts'!U991/'Raw counts'!U$1246*10000 -> 0 | V991: =IF(AND(X991=0,Y991=0),0,1) -> 0 | W991: =IFERROR(_xlfn.T.TEST(E991:M991,N991:U991,2,2),"") | X991: =AVERAGE(E991:M991) -> 0 | Y991: =AVERAGE(N991:U991) -> 0
A992: 1000 | B992: extrapyramidal fiber systems | C992: 108500 | D992: 1009 | E992: ='Raw counts'!E992/'Raw counts'!E$1246*10000 -> 0 | F992: ='Raw counts'!F992/'Raw counts'!F$1246*10000 -> 0 | G992: ='Raw counts'!G992/'Raw counts'!G$1246*10000 -> 0 | H992: ='Raw counts'!H992/'Raw counts'!H$1246*10000 -> 0 | I992: ='Raw counts'!I992/'Raw counts'!I$1246*10000 -> 0 | J992: ='Raw counts'!J992/'Raw counts'!J$1246*10000 -> 0 | K992: ='Raw counts'!K992/'Raw counts'!K$1246*10000 -> 0 | L992: ='Raw counts'!L992/'Raw counts'!L$1246*10000 -> 0 | ... U992: ='Raw counts'!U992/'Raw counts'!U$1246*10000 -> 0 | V992: =IF(AND(X992=0,Y992=0),0,1) -> 0 | W992: =IFERROR(_xlfn.T.TEST(E992:M992,N992:U992,2,2),"") | X992: =AVERAGE(E992:M992) -> 0 | Y992: =AVERAGE(N992:U992) -> 0
A993: 1001 | B993: Lobule V | C993: 56800 | D993: 928 | E993: ='Raw counts'!E993/'Raw counts'!E$1246*10000 -> 0 | F993: ='Raw counts'!F993/'Raw counts'!F$1246*10000 -> 0 | G993: ='Raw counts'!G993/'Raw counts'!G$1246*10000 -> 0 | H993: ='Raw counts'!H993/'Raw counts'!H$1246*10000 -> 0 | I993: ='Raw counts'!I993/'Raw counts'!I$1246*10000 -> 0 | J993: ='Raw counts'!J993/'Raw counts'!J$1246*10000 -> 0 | K993: ='Raw counts'!K993/'Raw counts'!K$1246*10000 -> 0 | L993: ='Raw counts'!L993/'Raw counts'!L$1246*10000 -> 0 | ... U993: ='Raw counts'!U993/'Raw counts'!U$1246*10000 -> 0 | V993: =IF(AND(X993=0,Y993=0),0,1) -> 0 | W993: =IFERROR(_xlfn.T.TEST(E993:M993,N993:U993,2,2),"") | X993: =AVERAGE(E993:M993) -> 0 | Y993: =AVERAGE(N993:U993) -> 0
A994: 1002 | B994: Primary auditory area | C994: 11300 | D994: 247 | E994: ='Raw counts'!E994/'Raw counts'!E$1246*10000 -> 0 | F994: ='Raw counts'!F994/'Raw counts'!F$1246*10000 -> 0 | G994: ='Raw counts'!G994/'Raw counts'!G$1246*10000 -> 0 | H994: ='Raw counts'!H994/'Raw counts'!H$1246*10000 -> 0 | I994: ='Raw counts'!I994/'Raw counts'!I$1246*10000 -> 0 | J994: ='Raw counts'!J994/'Raw counts'!J$1246*10000 -> 0 | K994: ='Raw counts'!K994/'Raw counts'!K$1246*10000 -> 0 | L994: ='Raw counts'!L994/'Raw counts'!L$1246*10000 -> 0 | ... U994: ='Raw counts'!U994/'Raw counts'!U$1246*10000 -> 0 | V994: =IF(AND(X994=0,Y994=0),0,1) -> 0 | W994: =IFERROR(_xlfn.T.TEST(E994:M994,N994:U994,2,2),"") | X994: =AVERAGE(E994:M994) -> 0 | Y994: =AVERAGE(N994:U994) -> 0
A995: 1003 | B995: corticopontine tract | C995: 107400 | D995: 784 | E995: ='Raw counts'!E995/'Raw counts'!E$1246*10000 -> 0 | F995: ='Raw counts'!F995/'Raw counts'!F$1246*10000 -> 0 | G995: ='Raw counts'!G995/'Raw counts'!G$1246*10000 -> 0 | H995: ='Raw counts'!H995/'Raw counts'!H$1246*10000 -> 0 | I995: ='Raw counts'!I995/'Raw counts'!I$1246*10000 -> 0 | J995: ='Raw counts'!J995/'Raw counts'!J$1246*10000 -> 0 | K995: ='Raw counts'!K995/'Raw counts'!K$1246*10000 -> 0 | L995: ='Raw counts'!L995/'Raw counts'!L$1246*10000 -> 0 | ... U995: ='Raw counts'!U995/'Raw counts'!U$1246*10000 -> 0 | V995: =IF(AND(X995=0,Y995=0),0,1) -> 0 | W995: =IFERROR(_xlfn.T.TEST(E995:M995,N995:U995,2,2),"") | X995: =AVERAGE(E995:M995) -> 0 | Y995: =AVERAGE(N995:U995) -> 0
A996: 1004 | B996: Ventral premammillary nucleus | C996: 76100 | D996: 467 | E996: ='Raw counts'!E996/'Raw counts'!E$1246*10000 -> 0.30632242 | F996: ='Raw counts'!F996/'Raw counts'!F$1246*10000 -> 0.041014939 | G996: ='Raw counts'!G996/'Raw counts'!G$1246*10000 -> 1.1785278 | H996: ='Raw counts'!H996/'Raw counts'!H$1246*10000 -> 0.034901553 | I996: ='Raw counts'!I996/'Raw counts'!I$1246*10000 -> 0.66494479 | J996: ='Raw counts'!J996/'Raw counts'!J$1246*10000 -> 0.90726025 | K996: ='Raw counts'!K996/'Raw counts'!K$1246*10000 -> 0.36122415 | L996: ='Raw counts'!L996/'Raw counts'!L$1246*10000 -> 0.088196332 | ... U996: ='Raw counts'!U996/'Raw counts'!U$1246*10000 -> 1.7271082 | V996: =IF(AND(X996=0,Y996=0),0,1) -> 1 | W996: =IFERROR(_xlfn.T.TEST(E996:M996,N996:U996,2,2),"") -> 0.78197364 | X996: =AVERAGE(E996:M996) -> 0.42364161 | Y996: =AVERAGE(N996:U996) -> 0.35187338
A997: 1005 | B997: Primary auditory area, layer 6b | C997: 11900 | D997: 1002 | E997: ='Raw counts'!E997/'Raw counts'!E$1246*10000 -> 2.1311822 | F997: ='Raw counts'!F997/'Raw counts'!F$1246*10000 -> 0.38554043 | G997: ='Raw counts'!G997/'Raw counts'!G$1246*10000 -> 2.6793881 | H997: ='Raw counts'!H997/'Raw counts'!H$1246*10000 -> 0.82367666 | I997: ='Raw counts'!I997/'Raw counts'!I$1246*10000 -> 0.049255169 | J997: ='Raw counts'!J997/'Raw counts'!J$1246*10000 -> 1.09956 | K997: ='Raw counts'!K997/'Raw counts'!K$1246*10000 -> 1.3557054 | L997: ='Raw counts'!L997/'Raw counts'!L$1246*10000 -> 3.3823293 | ... U997: ='Raw counts'!U997/'Raw counts'!U$1246*10000 -> 0.75940688 | V997: =IF(AND(X997=0,Y997=0),0,1) -> 1 | W997: =IFERROR(_xlfn.T.TEST(E997:M997,N997:U997,2,2),"") -> 0.9821658 | X997: =AVERAGE(E997:M997) -> 1.4161365 | Y997: =AVERAGE(N997:U997) -> 1.429213
A998: 1006 | B998: Primary somatosensory area, trunk, layer 1 | C998: 7100 | D998: 361 | E998: ='Raw counts'!E998/'Raw counts'!E$1246*10000 -> 0.50804694 | F998: ='Raw counts'!F998/'Raw counts'!F$1246*10000 -> 0.42655537 | G998: ='Raw counts'!G998/'Raw counts'!G$1246*10000 -> 0.70510212 | H998: ='Raw counts'!H998/'Raw counts'!H$1246*10000 -> 3.0294548 | I998: ='Raw counts'!I998/'Raw counts'!I$1246*10000 -> 2.0564033 | J998: ='Raw counts'!J998/'Raw counts'!J$1246*10000 -> 1.1439368 | K998: ='Raw counts'!K998/'Raw counts'!K$1246*10000 -> 0.80717989 | L998: ='Raw counts'!L998/'Raw counts'!L$1246*10000 -> 0.022049083 | ... U998: ='Raw counts'!U998/'Raw counts'!U$1246*10000 -> 0.85921464 | V998: =IF(AND(X998=0,Y998=0),0,1) -> 1 | W998: =IFERROR(_xlfn.T.TEST(E998:M998,N998:U998,2,2),"") -> 0.037962184 | X998: =AVERAGE(E998:M998) -> 1.1262571 | Y998: =AVERAGE(N998:U998) -> 2.8501195
A999: 1007 | B999: Simple lobule | C999: 59700 | D999: 1073 | E999: ='Raw counts'!E999/'Raw counts'!E$1246*10000 -> 108.23828 | F999: ='Raw counts'!F999/'Raw counts'!F$1246*10000 -> 22.681261 | G999: ='Raw counts'!G999/'Raw counts'!G$1246*10000 -> 96.337095 | H999: ='Raw counts'!H999/'Raw counts'!H$1246*10000 -> 110.81243 | I999: ='Raw counts'!I999/'Raw counts'!I$1246*10000 -> 99.643208 | J999: ='Raw counts'!J999/'Raw counts'!J$1246*10000 -> 62.433311 | K999: ='Raw counts'!K999/'Raw counts'!K$1246*10000 -> 85.0393 | L999: ='Raw counts'!L999/'Raw counts'!L$1246*10000 -> 36.54415 | ... U999: ='Raw counts'!U999/'Raw counts'!U$1246*10000 -> 87.240663 | V999: =IF(AND(X999=0,Y999=0),0,1) -> 1 | W999: =IFERROR(_xlfn.T.TEST(E999:M999,N999:U999,2,2),"") -> 0.55318774 | X999: =AVERAGE(E999:M999) -> 76.040084 | Y999: =AVERAGE(N999:U999) -> 68.353734
A1000: 1008 | B1000: Geniculate group, dorsal thalamus | C1000: 65000 | D1000: 864 | E1000: ='Raw counts'!E1000/'Raw counts'!E$1246*10000 -> 0 | F1000: ='Raw counts'!F1000/'Raw counts'!F$1246*10000 -> 0 | G1000: ='Raw counts'!G1000/'Raw counts'!G$1246*10000 -> 0 | H1000: ='Raw counts'!H1000/'Raw counts'!H$1246*10000 -> 0 | I1000: ='Raw counts'!I1000/'Raw counts'!I$1246*10000 -> 0 | J1000: ='Raw counts'!J1000/'Raw counts'!J$1246*10000 -> 0 | K1000: ='Raw counts'!K1000/'Raw counts'!K$1246*10000 -> 0 | L1000: ='Raw counts'!L1000/'Raw counts'!L$1246*10000 -> 0 | ... U1000: ='Raw counts'!U1000/'Raw counts'!U$1246*10000 -> 0 | V1000: =IF(AND(X1000=0,Y1000=0),0,1) -> 0 | W1000: =IFERROR(_xlfn.T.TEST(E1000:M1000,N1000:U1000,2,2),"") | X1000: =AVERAGE(E1000:M1000) -> 0 | Y1000: =AVERAGE(N1000:U1000) -> 0
A1001: 1009 | B1001: fiber tracts | C1001: 97200 | D1001: 997 | E1001: ='Raw counts'!E1001/'Raw counts'!E$1246*10000 -> 44.932269 | F1001: ='Raw counts'!F1001/'Raw counts'!F$1246*10000 -> 36.95446 | G1001: ='Raw counts'!G1001/'Raw counts'!G$1246*10000 -> 33.452059 | H1001: ='Raw counts'!H1001/'Raw counts'!H$1246*10000 -> 30.322469 | I1001: ='Raw counts'!I1001/'Raw counts'!I$1246*10000 -> 23.014478 | J1001: ='Raw counts'!J1001/'Raw counts'!J$1246*10000 -> 40.096959 | K1001: ='Raw counts'!K1001/'Raw counts'!K$1246*10000 -> 31.390824 | L1001: ='Raw counts'!L1001/'Raw counts'!L$1246*10000 -> 57.896482 | ... U1001: ='Raw counts'!U1001/'Raw counts'!U$1246*10000 -> 38.091849 | V1001: =IF(AND(X1001=0,Y1001=0),0,1) -> 1 | W1001: =IFERROR(_xlfn.T.TEST(E1001:M1001,N1001:U1001,2,2),"") -> 0.93059699 | X1001: =AVERAGE(E1001:M1001) -> 38.213833 | Y1001: =AVERAGE(N1001:U1001) -> 38.671685
... A1244: 312782656 | B1244: Unlabeled | C1244: 300 | D1244: 688 | E1244: ='Raw counts'!E1244/'Raw counts'!E$1246*10000 -> 12.949594 | F1244: ='Raw counts'!F1244/'Raw counts'!F$1246*10000 -> 10.384983 | G1244: ='Raw counts'!G1244/'Raw counts'!G$1246*10000 -> 29.291957 | H1244: ='Raw counts'!H1244/'Raw counts'!H$1246*10000 -> 15.419506 | I1244: ='Raw counts'!I1244/'Raw counts'!I$1246*10000 -> 5.4180686 | J1244: ='Raw counts'!J1244/'Raw counts'!J$1246*10000 -> 15.250848 | K1244: ='Raw counts'!K1244/'Raw counts'!K$1246*10000 -> 11.108757 | L1244: ='Raw counts'!L1244/'Raw counts'!L$1246*10000 -> 17.881806 | ... U1244: ='Raw counts'!U1244/'Raw counts'!U$1246*10000 -> 13.257074 | V1244: =IF(AND(X1244=0,Y1244=0),0,1) -> 1 | W1244: =IFERROR(_xlfn.T.TEST(E1244:M1244,N1244:U1244,2,2),"") -> 0.70454897 | X1244: =AVERAGE(E1244:M1244) -> 14.226719 | Y1244: =AVERAGE(N1244:U1244) -> 15.726315
E1246: =SUM(E3:E1244) -> 10000 | F1246: =SUM(F3:F1244) -> 10000 | G1246: =SUM(G3:G1244) -> 10000 | H1246: =SUM(H3:H1244) -> 10000 | I1246: =SUM(I3:I1244) -> 10000 | J1246: =SUM(J3:J1244) -> 10000 | K1246: =SUM(K3:K1244) -> 10000 | L1246: =SUM(L3:L1244) -> 10000 | ... U1246: =SUM(U3:U1244) -> 10000

Sheet Activation map
E1: Group | F1: 0 | G1: 0 | H1: 0 | I1: 0 | J1: 0 | K1: 0 | L1: 0 | M1: 0 | N1: 0 | O1: 1 | P1: 1 | Q1: 1 | R1: 1 | S1: 1 | T1: 1 | U1: 1 | V1: 1
A2: region | B2: id | C2: name | D2: structure_order | E2: parent_id | F2: 124 | G2: 143 | H2: 146 | I2: 152 | J2: 170 | K2: 171 | L2: 175 | M2: 183 | N2: 200 | O2: 113 | P2: 172 | Q2: 177 | R2: 178 | S2: 179 | T2: 180 | U2: 184 | V2: 207 | X2: T-test | Y2: Gem 0 | Z2: Gem 1
A3: dCA1 | B3: 382 | C3: Field CA1 | D3: 37700 | E3: 375 | F3: =SUMIFS('Raw counts'!E:E,'Raw counts'!$A:$A,'Activation map'!$B3) -> 1312 | G3: =SUMIFS('Raw counts'!F:F,'Raw counts'!$A:$A,'Activation map'!$B3) -> 25 | H3: =SUMIFS('Raw counts'!G:G,'Raw counts'!$A:$A,'Activation map'!$B3) -> 1549 | I3: =SUMIFS('Raw counts'!H:H,'Raw counts'!$A:$A,'Activation map'!$B3) -> 551 | J3: =SUMIFS('Raw counts'!I:I,'Raw counts'!$A:$A,'Activation map'!$B3) -> 337 | K3: =SUMIFS('Raw counts'!J:J,'Raw counts'!$A:$A,'Activation map'!$B3) -> 3228 | L3: =SUMIFS('Raw counts'!K:K,'Raw counts'!$A:$A,'Activation map'!$B3) -> 1996 | M3: =SUMIFS('Raw counts'!L:L,'Raw counts'!$A:$A,'Activation map'!$B3) -> 1044 | N3: =SUMIFS('Raw counts'!M:M,'Raw counts'!$A:$A,'Activation map'!$B3) -> 1091 | O3: =SUMIFS('Raw counts'!N:N,'Raw counts'!$A:$A,'Activation map'!$B3) -> 3433 | P3: =SUMIFS('Raw counts'!O:O,'Raw counts'!$A:$A,'Activation map'!$B3) -> 6937 | Q3: =SUMIFS('Raw counts'!P:P,'Raw counts'!$A:$A,'Activation map'!$B3) -> 1628 | R3: =SUMIFS('Raw counts'!Q:Q,'Raw counts'!$A:$A,'Activation map'!$B3) -> 422 | S3: =SUMIFS('Raw counts'!R:R,'Raw counts'!$A:$A,'Activation map'!$B3) -> 1717 | T3: =SUMIFS('Raw counts'!S:S,'Raw counts'!$A:$A,'Activation map'!$B3) -> 620 | U3: =SUMIFS('Raw counts'!T:T,'Raw counts'!$A:$A,'Activation map'!$B3) -> 1288 | V3: =SUMIFS('Raw counts'!U:U,'Raw counts'!$A:$A,'Activation map'!$B3) -> 1399 | X3: =_xlfn.T.TEST(F3:N3,O3:V3,2,2) -> 0.24774591 | Y3: =AVERAGE(F3:N3) -> 1237 | Z3: =AVERAGE(O3:V3) -> 2180.5
A4: dCA3 | B4: 463 | C4: Field CA3 | D4: 38700 | E4: 375 | F4: =SUMIFS('Raw counts'!E:E,'Raw counts'!$A:$A,'Activation map'!$B4) -> 2352 | G4: =SUMIFS('Raw counts'!F:F,'Raw counts'!$A:$A,'Activation map'!$B4) -> 21 | H4: =SUMIFS('Raw counts'!G:G,'Raw counts'!$A:$A,'Activation map'!$B4) -> 512 | I4: =SUMIFS('Raw counts'!H:H,'Raw counts'!$A:$A,'Activation map'!$B4) -> 167 | J4: =SUMIFS('Raw counts'!I:I,'Raw counts'!$A:$A,'Activation map'!$B4) -> 245 | K4: =SUMIFS('Raw counts'!J:J,'Raw counts'!$A:$A,'Activation map'!$B4) -> 2686 | L4: =SUMIFS('Raw counts'!K:K,'Raw counts'!$A:$A,'Activation map'!$B4) -> 1682 | M4: =SUMIFS('Raw counts'!L:L,'Raw counts'!$A:$A,'Activation map'!$B4) -> 1363 | N4: =SUMIFS('Raw counts'!M:M,'Raw counts'!$A:$A,'Activation map'!$B4) -> 894 | O4: =SUMIFS('Raw counts'!N:N,'Raw counts'!$A:$A,'Activation map'!$B4) -> 1408 | P4: =SUMIFS('Raw counts'!O:O,'Raw counts'!$A:$A,'Activation map'!$B4) -> 1998 | Q4: =SUMIFS('Raw counts'!P:P,'Raw counts'!$A:$A,'Activation map'!$B4) -> 1035 | R4: =SUMIFS('Raw counts'!Q:Q,'Raw counts'!$A:$A,'Activation map'!$B4) -> 374 | S4: =SUMIFS('Raw counts'!R:R,'Raw counts'!$A:$A,'Activation map'!$B4) -> 1693 | T4: =SUMIFS('Raw counts'!S:S,'Raw counts'!$A:$A,'Activation map'!$B4) -> 281 | U4: =SUMIFS('Raw counts'!T:T,'Raw counts'!$A:$A,'Activation map'!$B4) -> 1113 | V4: =SUMIFS('Raw counts'!U:U,'Raw counts'!$A:$A,'Activation map'!$B4) -> 1121 | X4: =_xlfn.T.TEST(F4:N4,O4:V4,2,2) -> 0.9499731 | Y4: =AVERAGE(F4:N4) -> 1102.4444 | Z4: =AVERAGE(O4:V4) -> 1127.875
A5: dDG | C5: Dentate gyrus | E5: 726 | F5: =SUMPRODUCT(SUMIFS('Raw counts'!E:E,'Raw counts'!$A:$A,$B16:$B18)) -> 2429 | G5: =SUMPRODUCT(SUMIFS('Raw counts'!F:F,'Raw counts'!$A:$A,$B16:$B18)) -> 376 | H5: =SUMPRODUCT(SUMIFS('Raw counts'!G:G,'Raw counts'!$A:$A,$B16:$B18)) -> 3992 | I5: =SUMPRODUCT(SUMIFS('Raw counts'!H:H,'Raw counts'!$A:$A,$B16:$B18)) -> 2644 | J5: =SUMPRODUCT(SUMIFS('Raw counts'!I:I,'Raw counts'!$A:$A,$B16:$B18)) -> 2607 | K5: =SUMPRODUCT(SUMIFS('Raw counts'!J:J,'Raw counts'!$A:$A,$B16:$B18)) -> 3623 | L5: =SUMPRODUCT(SUMIFS('Raw counts'!K:K,'Raw counts'!$A:$A,$B16:$B18)) -> 6249 | M5: =SUMPRODUCT(SUMIFS('Raw counts'!L:L,'Raw counts'!$A:$A,$B16:$B18)) -> 1052 | N5: =SUMPRODUCT(SUMIFS('Raw counts'!M:M,'Raw counts'!$A:$A,$B16:$B18)) -> 1510 | O5: =SUMPRODUCT(SUMIFS('Raw counts'!N:N,'Raw counts'!$A:$A,$B16:$B18)) -> 8190 | P5: =SUMPRODUCT(SUMIFS('Raw counts'!O:O,'Raw counts'!$A:$A,$B16:$B18)) -> 9048 | Q5: =SUMPRODUCT(SUMIFS('Raw counts'!P:P,'Raw counts'!$A:$A,$B16:$B18)) -> 1970 | R5: =SUMPRODUCT(SUMIFS('Raw counts'!Q:Q,'Raw counts'!$A:$A,$B16:$B18)) -> 728 | S5: =SUMPRODUCT(SUMIFS('Raw counts'!R:R,'Raw counts'!$A:$A,$B16:$B18)) -> 7845 | T5: =SUMPRODUCT(SUMIFS('Raw counts'!S:S,'Raw counts'!$A:$A,$B16:$B18)) -> 2823 | U5: =SUMPRODUCT(SUMIFS('Raw counts'!T:T,'Raw counts'!$A:$A,$B16:$B18)) -> 4679 | V5: =SUMPRODUCT(SUMIFS('Raw counts'!U:U,'Raw counts'!$A:$A,$B16:$B18)) -> 4037 | X5: =_xlfn.T.TEST(F5:N5,O5:V5,2,2) -> 0.088994353 | Y5: =AVERAGE(F5:N5) -> 2720.2222 | Z5: =AVERAGE(O5:V5) -> 4915
A6: vCA1 | B6: 2382 | C6: Field CA1 ventral | D6: 37700 | E6: 2375 | F6: =SUMIFS('Raw counts'!E:E,'Raw counts'!$A:$A,'Activation map'!$B6) -> 75342 | G6: =SUMIFS('Raw counts'!F:F,'Raw counts'!$A:$A,'Activation map'!$B6) -> 8188 | H6: =SUMIFS('Raw counts'!G:G,'Raw counts'!$A:$A,'Activation map'!$B6) -> 5097 | I6: =SUMIFS('Raw counts'!H:H,'Raw counts'!$A:$A,'Activation map'!$B6) -> 5994 | J6: =SUMIFS('Raw counts'!I:I,'Raw counts'!$A:$A,'Activation map'!$B6) -> 9304 | K6: =SUMIFS('Raw counts'!J:J,'Raw counts'!$A:$A,'Activation map'!$B6) -> 16314 | L6: =SUMIFS('Raw counts'!K:K,'Raw counts'!$A:$A,'Activation map'!$B6) -> 19276 | M6: =SUMIFS('Raw counts'!L:L,'Raw counts'!$A:$A,'Activation map'!$B6) -> 29203 | N6: =SUMIFS('Raw counts'!M:M,'Raw counts'!$A:$A,'Activation map'!$B6) -> 39310 | O6: =SUMIFS('Raw counts'!N:N,'Raw counts'!$A:$A,'Activation map'!$B6) -> 14246 | P6: =SUMIFS('Raw counts'!O:O,'Raw counts'!$A:$A,'Activation map'!$B6) -> 24872 | Q6: =SUMIFS('Raw counts'!P:P,'Raw counts'!$A:$A,'Activation map'!$B6) -> 13410 | R6: =SUMIFS('Raw counts'!Q:Q,'Raw counts'!$A:$A,'Activation map'!$B6) -> 6531 | S6: =SUMIFS('Raw counts'!R:R,'Raw counts'!$A:$A,'Activation map'!$B6) -> 12069 | T6: =SUMIFS('Raw counts'!S:S,'Raw counts'!$A:$A,'Activation map'!$B6) -> 10802 | U6: =SUMIFS('Raw counts'!T:T,'Raw counts'!$A:$A,'Activation map'!$B6) -> 10019 | V6: =SUMIFS('Raw counts'!U:U,'Raw counts'!$A:$A,'Activation map'!$B6) -> 14118 | X6: =_xlfn.T.TEST(F6:N6,O6:V6,2,2) -> 0.2505201 | Y6: =AVERAGE(F6:N6) -> 23114.222 | Z6: =AVERAGE(O6:V6) -> 13258.375
A7: vCA3 | B7: 2463 | C7: Field CA3 ventral | D7: 38700 | E7: 2375 | F7: =SUMIFS('Raw counts'!E:E,'Raw counts'!$A:$A,'Activation map'!$B7) -> 54246 | G7: =SUMIFS('Raw counts'!F:F,'Raw counts'!$A:$A,'Activation map'!$B7) -> 4730 | H7: =SUMIFS('Raw counts'!G:G,'Raw counts'!$A:$A,'Activation map'!$B7) -> 2743 | I7: =SUMIFS('Raw counts'!H:H,'Raw counts'!$A:$A,'Activation map'!$B7) -> 1844 | J7: =SUMIFS('Raw counts'!I:I,'Raw counts'!$A:$A,'Activation map'!$B7) -> 2145 | K7: =SUMIFS('Raw counts'!J:J,'Raw counts'!$A:$A,'Activation map'!$B7) -> 1337 | L7: =SUMIFS('Raw counts'!K:K,'Raw counts'!$A:$A,'Activation map'!$B7) -> 4347 | M7: =SUMIFS('Raw counts'!L:L,'Raw counts'!$A:$A,'Activation map'!$B7) -> 24159 | N7: =SUMIFS('Raw counts'!M:M,'Raw counts'!$A:$A,'Activation map'!$B7) -> 12774 | O7: =SUMIFS('Raw counts'!N:N,'Raw counts'!$A:$A,'Activation map'!$B7) -> 4422 | P7: =SUMIFS('Raw counts'!O:O,'Raw counts'!$A:$A,'Activation map'!$B7) -> 6991 | Q7: =SUMIFS('Raw counts'!P:P,'Raw counts'!$A:$A,'Activation map'!$B7) -> 7531 | R7: =SUMIFS('Raw counts'!Q:Q,'Raw counts'!$A:$A,'Activation map'!$B7) -> 3820 | S7: =SUMIFS('Raw counts'!R:R,'Raw counts'!$A:$A,'Activation map'!$B7) -> 5094 | T7: =SUMIFS('Raw counts'!S:S,'Raw counts'!$A:$A,'Activation map'!$B7) -> 5437 | U7: =SUMIFS('Raw counts'!T:T,'Raw counts'!$A:$A,'Activation map'!$B7) -> 2981 | V7: =SUMIFS('Raw counts'!U:U,'Raw counts'!$A:$A,'Activation map'!$B7) -> 3679 | X7: =_xlfn.T.TEST(F7:N7,O7:V7,2,2) -> 0.2757829 | Y7: =AVERAGE(F7:N7) -> 12036.111 | Z7: =AVERAGE(O7:V7) -> 4994.375
A8: vDG | C8: Dentate gyrus ventral | E8: 2726 | F8: =SUMPRODUCT(SUMIFS('Raw counts'!E:E,'Raw counts'!$A:$A,$B19:$B21)) -> 57650 | G8: =SUMPRODUCT(SUMIFS('Raw counts'!F:F,'Raw counts'!$A:$A,$B19:$B21)) -> 5976 | H8: =SUMPRODUCT(SUMIFS('Raw counts'!G:G,'Raw counts'!$A:$A,$B19:$B21)) -> 7637 | I8: =SUMPRODUCT(SUMIFS('Raw counts'!H:H,'Raw counts'!$A:$A,$B19:$B21)) -> 7800 | J8: =SUMPRODUCT(SUMIFS('Raw counts'!I:I,'Raw counts'!$A:$A,$B19:$B21)) -> 9331 | K8: =SUMPRODUCT(SUMIFS('Raw counts'!J:J,'Raw counts'!$A:$A,$B19:$B21)) -> 9407 | L8: =SUMPRODUCT(SUMIFS('Raw counts'!K:K,'Raw counts'!$A:$A,$B19:$B21)) -> 16426 | M8: =SUMPRODUCT(SUMIFS('Raw counts'!L:L,'Raw counts'!$A:$A,$B19:$B21)) -> 15215 | N8: =SUMPRODUCT(SUMIFS('Raw counts'!M:M,'Raw counts'!$A:$A,$B19:$B21)) -> 24510 | O8: =SUMPRODUCT(SUMIFS('Raw counts'!N:N,'Raw counts'!$A:$A,$B19:$B21)) -> 11996 | P8: =SUMPRODUCT(SUMIFS('Raw counts'!O:O,'Raw counts'!$A:$A,$B19:$B21)) -> 25240 | Q8: =SUMPRODUCT(SUMIFS('Raw counts'!P:P,'Raw counts'!$A:$A,$B19:$B21)) -> 10918 | R8: =SUMPRODUCT(SUMIFS('Raw counts'!Q:Q,'Raw counts'!$A:$A,$B19:$B21)) -> 11202 | S8: =SUMPRODUCT(SUMIFS('Raw counts'!R:R,'Raw counts'!$A:$A,$B19:$B21)) -> 24350 | T8: =SUMPRODUCT(SUMIFS('Raw counts'!S:S,'Raw counts'!$A:$A,$B19:$B21)) -> 11186 | U8: =SUMPRODUCT(SUMIFS('Raw counts'!T:T,'Raw counts'!$A:$A,$B19:$B21)) -> 8080 | V8: =SUMPRODUCT(SUMIFS('Raw counts'!U:U,'Raw counts'!$A:$A,$B19:$B21)) -> 9334 | X8: =_xlfn.T.TEST(F8:N8,O8:V8,2,2) -> 0.62793564 | Y8: =AVERAGE(F8:N8) -> 17105.778 | Z8: =AVERAGE(O8:V8) -> 14038.25
A9: RSP | C9: Retrosplenial area | F9: =SUMPRODUCT(SUMIFS('Raw counts'!E:E,'Raw counts'!$A:$A,$B22:$B38)) -> 16089 | G9: =SUMPRODUCT(SUMIFS('Raw counts'!F:F,'Raw counts'!$A:$A,$B22:$B38)) -> 334 | H9: =SUMPRODUCT(SUMIFS('Raw counts'!G:G,'Raw counts'!$A:$A,$B22:$B38)) -> 24438 | I9: =SUMPRODUCT(SUMIFS('Raw counts'!H:H,'Raw counts'!$A:$A,$B22:$B38)) -> 17294 | J9: =SUMPRODUCT(SUMIFS('Raw counts'!I:I,'Raw counts'!$A:$A,$B22:$B38)) -> 13621 | K9: =SUMPRODUCT(SUMIFS('Raw counts'!J:J,'Raw counts'!$A:$A,$B22:$B38)) -> 19179 | L9: =SUMPRODUCT(SUMIFS('Raw counts'!K:K,'Raw counts'!$A:$A,$B22:$B38)) -> 40975 | M9: =SUMPRODUCT(SUMIFS('Raw counts'!L:L,'Raw counts'!$A:$A,$B22:$B38)) -> 3810 | N9: =SUMPRODUCT(SUMIFS('Raw counts'!M:M,'Raw counts'!$A:$A,$B22:$B38)) -> 13824 | O9: =SUMPRODUCT(SUMIFS('Raw counts'!N:N,'Raw counts'!$A:$A,$B22:$B38)) -> 23525 | P9: =SUMPRODUCT(SUMIFS('Raw counts'!O:O,'Raw counts'!$A:$A,$B22:$B38)) -> 62879 | Q9: =SUMPRODUCT(SUMIFS('Raw counts'!P:P,'Raw counts'!$A:$A,$B22:$B38)) -> 35639 | R9: =SUMPRODUCT(SUMIFS('Raw counts'!Q:Q,'Raw counts'!$A:$A,$B22:$B38)) -> 13267 | S9: =SUMPRODUCT(SUMIFS('Raw counts'!R:R,'Raw counts'!$A:$A,$B22:$B38)) -> 52026 | T9: =SUMPRODUCT(SUMIFS('Raw counts'!S:S,'Raw counts'!$A:$A,$B22:$B38)) -> 30653 | U9: =SUMPRODUCT(SUMIFS('Raw counts'!T:T,'Raw counts'!$A:$A,$B22:$B38)) -> 33704 | V9: =SUMPRODUCT(SUMIFS('Raw counts'!U:U,'Raw counts'!$A:$A,$B22:$B38)) -> 40940 | X9: =_xlfn.T.TEST(F9:N9,O9:V9,2,2) -> 0.0089986116 | Y9: =AVERAGE(F9:N9) -> 16618.222 | Z9: =AVERAGE(O9:V9) -> 36579.125
A10: ACC | C10: Anterior cingulate area | F10: =SUMPRODUCT(SUMIFS('Raw counts'!E:E,'Raw counts'!$A:$A,$B39:$B48)) -> 21741 | G10: =SUMPRODUCT(SUMIFS('Raw counts'!F:F,'Raw counts'!$A:$A,$B39:$B48)) -> 8809 | H10: =SUMPRODUCT(SUMIFS('Raw counts'!G:G,'Raw counts'!$A:$A,$B39:$B48)) -> 9942 | I10: =SUMPRODUCT(SUMIFS('Raw counts'!H:H,'Raw counts'!$A:$A,$B39:$B48)) -> 3635 | J10: =SUMPRODUCT(SUMIFS('Raw counts'!I:I,'Raw counts'!$A:$A,$B39:$B48)) -> 1154 | K10: =SUMPRODUCT(SUMIFS('Raw counts'!J:J,'Raw counts'!$A:$A,$B39:$B48)) -> 5281 | L10: =SUMPRODUCT(SUMIFS('Raw counts'!K:K,'Raw counts'!$A:$A,$B39:$B48)) -> 9551 | M10: =SUMPRODUCT(SUMIFS('Raw counts'!L:L,'Raw counts'!$A:$A,$B39:$B48)) -> 754 | N10: =SUMPRODUCT(SUMIFS('Raw counts'!M:M,'Raw counts'!$A:$A,$B39:$B48)) -> 1185 | O10: =SUMPRODUCT(SUMIFS('Raw counts'!N:N,'Raw counts'!$A:$A,$B39:$B48)) -> 9032 | P10: =SUMPRODUCT(SUMIFS('Raw counts'!O:O,'Raw counts'!$A:$A,$B39:$B48)) -> 9706 | Q10: =SUMPRODUCT(SUMIFS('Raw counts'!P:P,'Raw counts'!$A:$A,$B39:$B48)) -> 3071 | R10: =SUMPRODUCT(SUMIFS('Raw counts'!Q:Q,'Raw counts'!$A:$A,$B39:$B48)) -> 41 | S10: =SUMPRODUCT(SUMIFS('Raw counts'!R:R,'Raw counts'!$A:$A,$B39:$B48)) -> 2079 | T10: =SUMPRODUCT(SUMIFS('Raw counts'!S:S,'Raw counts'!$A:$A,$B39:$B48)) -> 7857 | U10: =SUMPRODUCT(SUMIFS('Raw counts'!T:T,'Raw counts'!$A:$A,$B39:$B48)) -> 6130 | V10: =SUMPRODUCT(SUMIFS('Raw counts'!U:U,'Raw counts'!$A:$A,$B39:$B48)) -> 16722 | X10: =_xlfn.T.TEST(F10:N10,O10:V10,2,2) -> 0.98272348 | Y10: =AVERAGE(F10:N10) -> 6894.6667 | Z10: =AVERAGE(O10:V10) -> 6829.75
A11: PL | C11: Prelimbic area | E11: 972 | F11: =SUMPRODUCT(SUMIFS('Raw counts'!E:E,'Raw counts'!$A:$A,$B49:$B53)) -> 11894 | G11: =SUMPRODUCT(SUMIFS('Raw counts'!F:F,'Raw counts'!$A:$A,$B49:$B53)) -> 2880 | H11: =SUMPRODUCT(SUMIFS('Raw counts'!G:G,'Raw counts'!$A:$A,$B49:$B53)) -> 4750 | I11: =SUMPRODUCT(SUMIFS('Raw counts'!H:H,'Raw counts'!$A:$A,$B49:$B53)) -> 2494 | J11: =SUMPRODUCT(SUMIFS('Raw counts'!I:I,'Raw counts'!$A:$A,$B49:$B53)) -> 876 | K11: =SUMPRODUCT(SUMIFS('Raw counts'!J:J,'Raw counts'!$A:$A,$B49:$B53)) -> 1470 | L11: =SUMPRODUCT(SUMIFS('Raw counts'!K:K,'Raw counts'!$A:$A,$B49:$B53)) -> 3342 | M11: =SUMPRODUCT(SUMIFS('Raw counts'!L:L,'Raw counts'!$A:$A,$B49:$B53)) -> 179 | N11: =SUMPRODUCT(SUMIFS('Raw counts'!M:M,'Raw counts'!$A:$A,$B49:$B53)) -> 1068 | O11: =SUMPRODUCT(SUMIFS('Raw counts'!N:N,'Raw counts'!$A:$A,$B49:$B53)) -> 1895 | P11: =SUMPRODUCT(SUMIFS('Raw counts'!O:O,'Raw counts'!$A:$A,$B49:$B53)) -> 2205 | Q11: =SUMPRODUCT(SUMIFS('Raw counts'!P:P,'Raw counts'!$A:$A,$B49:$B53)) -> 5991 | R11: =SUMPRODUCT(SUMIFS('Raw counts'!Q:Q,'Raw counts'!$A:$A,$B49:$B53)) -> 68 | S11: =SUMPRODUCT(SUMIFS('Raw counts'!R:R,'Raw counts'!$A:$A,$B49:$B53)) -> 500 | T11: =SUMPRODUCT(SUMIFS('Raw counts'!S:S,'Raw counts'!$A:$A,$B49:$B53)) -> 2046 | U11: =SUMPRODUCT(SUMIFS('Raw counts'!T:T,'Raw counts'!$A:$A,$B49:$B53)) -> 1072 | V11: =SUMPRODUCT(SUMIFS('Raw counts'!U:U,'Raw counts'!$A:$A,$B49:$B53)) -> 3969 | X11: =_xlfn.T.TEST(F11:N11,O11:V11,2,2) -> 0.49076741 | Y11: =AVERAGE(F11:N11) -> 3217 | Z11: =AVERAGE(O11:V11) -> 2218.25
A12: IL | C12: Infralimbic area | E12: 44 | F12: =SUMPRODUCT(SUMIFS('Raw counts'!E:E,'Raw counts'!$A:$A,$B54:$B58)) -> 16132 | G12: =SUMPRODUCT(SUMIFS('Raw counts'!F:F,'Raw counts'!$A:$A,$B54:$B58)) -> 4946 | H12: =SUMPRODUCT(SUMIFS('Raw counts'!G:G,'Raw counts'!$A:$A,$B54:$B58)) -> 4167 | I12: =SUMPRODUCT(SUMIFS('Raw counts'!H:H,'Raw counts'!$A:$A,$B54:$B58)) -> 1176 | J12: =SUMPRODUCT(SUMIFS('Raw counts'!I:I,'Raw counts'!$A:$A,$B54:$B58)) -> 1366 | K12: =SUMPRODUCT(SUMIFS('Raw counts'!J:J,'Raw counts'!$A:$A,$B54:$B58)) -> 1737 | L12: =SUMPRODUCT(SUMIFS('Raw counts'!K:K,'Raw counts'!$A:$A,$B54:$B58)) -> 3291 | M12: =SUMPRODUCT(SUMIFS('Raw counts'!L:L,'Raw counts'!$A:$A,$B54:$B58)) -> 1264 | N12: =SUMPRODUCT(SUMIFS('Raw counts'!M:M,'Raw counts'!$A:$A,$B54:$B58)) -> 1651 | O12: =SUMPRODUCT(SUMIFS('Raw counts'!N:N,'Raw counts'!$A:$A,$B54:$B58)) -> 1542 | P12: =SUMPRODUCT(SUMIFS('Raw counts'!O:O,'Raw counts'!$A:$A,$B54:$B58)) -> 2804 | Q12: =SUMPRODUCT(SUMIFS('Raw counts'!P:P,'Raw counts'!$A:$A,$B54:$B58)) -> 1837 | R12: =SUMPRODUCT(SUMIFS('Raw counts'!Q:Q,'Raw counts'!$A:$A,$B54:$B58)) -> 108 | S12: =SUMPRODUCT(SUMIFS('Raw counts'!R:R,'Raw counts'!$A:$A,$B54:$B58)) -> 1906 | T12: =SUMPRODUCT(SUMIFS('Raw counts'!S:S,'Raw counts'!$A:$A,$B54:$B58)) -> 1290 | U12: =SUMPRODUCT(SUMIFS('Raw counts'!T:T,'Raw counts'!$A:$A,$B54:$B58)) -> 1557 | V12: =SUMPRODUCT(SUMIFS('Raw counts'!U:U,'Raw counts'!$A:$A,$B54:$B58)) -> 4543 | X12: =_xlfn.T.TEST(F12:N12,O12:V12,2,2) -> 0.26453654 | Y12: =AVERAGE(F12:N12) -> 3970 | Z12: =AVERAGE(O12:V12) -> 1948.375
A13: CeA | B13: 536 | C13: Central amygdalar nucleus | D13: 50300 | E13: 278 | F13: =SUMIFS('Raw counts'!E:E,'Raw counts'!$A:$A,'Activation map'!$B13) -> 10111 | G13: =SUMIFS('Raw counts'!F:F,'Raw counts'!$A:$A,'Activation map'!$B13) -> 393 | H13: =SUMIFS('Raw counts'!G:G,'Raw counts'!$A:$A,'Activation map'!$B13) -> 694 | I13: =SUMIFS('Raw counts'!H:H,'Raw counts'!$A:$A,'Activation map'!$B13) -> 2360 | J13: =SUMIFS('Raw counts'!I:I,'Raw counts'!$A:$A,'Activation map'!$B13) -> 4567 | K13: =SUMIFS('Raw counts'!J:J,'Raw counts'!$A:$A,'Activation map'!$B13) -> 4471 | L13: =SUMIFS('Raw counts'!K:K,'Raw counts'!$A:$A,'Activation map'!$B13) -> 5943 | M13: =SUMIFS('Raw counts'!L:L,'Raw counts'!$A:$A,'Activation map'!$B13) -> 22456 | N13: =SUMIFS('Raw counts'!M:M,'Raw counts'!$A:$A,'Activation map'!$B13) -> 9854 | O13: =SUMIFS('Raw counts'!N:N,'Raw counts'!$A:$A,'Activation map'!$B13) -> 1871 | P13: =SUMIFS('Raw counts'!O:O,'Raw counts'!$A:$A,'Activation map'!$B13) -> 6154 | Q13: =SUMIFS('Raw counts'!P:P,'Raw counts'!$A:$A,'Activation map'!$B13) -> 8807 | R13: =SUMIFS('Raw counts'!Q:Q,'Raw counts'!$A:$A,'Activation map'!$B13) -> 779 | S13: =SUMIFS('Raw counts'!R:R,'Raw counts'!$A:$A,'Activation map'!$B13) -> 4737 | T13: =SUMIFS('Raw counts'!S:S,'Raw counts'!$A:$A,'Activation map'!$B13) -> 1928 | U13: =SUMIFS('Raw counts'!T:T,'Raw counts'!$A:$A,'Activation map'!$B13) -> 4350 | V13: =SUMIFS('Raw counts'!U:U,'Raw counts'!$A:$A,'Activation map'!$B13) -> 5644 | X13: =_xlfn.T.TEST(F13:N13,O13:V13,2,2) -> 0.35294776 | Y13: =AVERAGE(F13:N13) -> 6761 | Z13: =AVERAGE(O13:V13) -> 4283.75
A14: BLA | C14: Basolateral amygdalar nucleus | E14: 295 | F14: =SUMPRODUCT(SUMIFS('Raw counts'!E:E,'Raw counts'!$A:$A,$B59:$B61)) -> 30901 | G14: =SUMPRODUCT(SUMIFS('Raw counts'!F:F,'Raw counts'!$A:$A,$B59:$B61)) -> 2730 | H14: =SUMPRODUCT(SUMIFS('Raw counts'!G:G,'Raw counts'!$A:$A,$B59:$B61)) -> 639 | I14: =SUMPRODUCT(SUMIFS('Raw counts'!H:H,'Raw counts'!$A:$A,$B59:$B61)) -> 4965 | J14: =SUMPRODUCT(SUMIFS('Raw counts'!I:I,'Raw counts'!$A:$A,$B59:$B61)) -> 5774 | K14: =SUMPRODUCT(SUMIFS('Raw counts'!J:J,'Raw counts'!$A:$A,$B59:$B61)) -> 1092 | L14: =SUMPRODUCT(SUMIFS('Raw counts'!K:K,'Raw counts'!$A:$A,$B59:$B61)) -> 4115 | M14: =SUMPRODUCT(SUMIFS('Raw counts'!L:L,'Raw counts'!$A:$A,$B59:$B61)) -> 16860 | N14: =SUMPRODUCT(SUMIFS('Raw counts'!M:M,'Raw counts'!$A:$A,$B59:$B61)) -> 5077 | O14: =SUMPRODUCT(SUMIFS('Raw counts'!N:N,'Raw counts'!$A:$A,$B59:$B61)) -> 4228 | P14: =SUMPRODUCT(SUMIFS('Raw counts'!O:O,'Raw counts'!$A:$A,$B59:$B61)) -> 5384 | Q14: =SUMPRODUCT(SUMIFS('Raw counts'!P:P,'Raw counts'!$A:$A,$B59:$B61)) -> 4369 | R14: =SUMPRODUCT(SUMIFS('Raw counts'!Q:Q,'Raw counts'!$A:$A,$B59:$B61)) -> 572 | S14: =SUMPRODUCT(SUMIFS('Raw counts'!R:R,'Raw counts'!$A:$A,$B59:$B61)) -> 4764 | T14: =SUMPRODUCT(SUMIFS('Raw counts'!S:S,'Raw counts'!$A:$A,$B59:$B61)) -> 2140 | U14: =SUMPRODUCT(SUMIFS('Raw counts'!T:T,'Raw counts'!$A:$A,$B59:$B61)) -> 7414 | V14: =SUMPRODUCT(SUMIFS('Raw counts'!U:U,'Raw counts'!$A:$A,$B59:$B61)) -> 4275 | X14: =_xlfn.T.TEST(F14:N14,O14:V14,2,2) -> 0.2921922 | Y14: =AVERAGE(F14:N14) -> 8017 | Z14: =AVERAGE(O14:V14) -> 4143.25
B16: 632 | C16: Dentate gyrus, granule cell layer | D16: 39600 | E16: 726
B17: 10703 | C17: Dentate gyrus, molecular layer | D17: 39400 | E17: 726
B18: 10704 | C18: Dentate gyrus, polymorph layer | D18: 39500 | E18: 726
B19: 2632 | C19: Dentate gyrus, granule cell layer ventral | D19: 39600 | E19: 2726
B20: 12703 | C20: Dentate gyrus, molecular layer | D20: 39400 | E20: 2726
B21: 12704 | C21: Dentate gyrus, subgranular zone ventral | D21: 39700 | E21: 2726
B22: 894 | C22: Retrosplenial area, lateral agranular part | D22: 25300 | E22: 254
B23: 274 | C23: Retrosplenial area, dorsal part, layer 6a | D23: 26400 | E23: 879
B24: 330 | C24: Retrosplenial area, dorsal part, layer 6b | D24: 26500 | E24: 879
B25: 434 | C25: Retrosplenial area, dorsal part, layer 2/3 | D25: 26100 | E25: 879
B26: 442 | C26: Retrosplenial area, dorsal part, layer 1 | D26: 26000 | E26: 879
B27: 545 | C27: Retrosplenial area, dorsal part, layer 4 | D27: 26200 | E27: 879
... B61: 451 | C61: Basolateral amygdalar nucleus, ventral part | D61: 47400 | E61: 295

Sheet Total-corrected counts Z<3
E1: 0 | F1: 0 | G1: 0 | H1: 0 | I1: 0 | J1: 0 | K1: 0 | L1: 0 | M1: 0 | N1: 1 | O1: 1 | P1: 1 | Q1: 1 | R1: 1 | S1: 1 | T1: 1 | U1: 1
A2: id | B2: name | C2: structure_order | D2: parent_id | E2: 124 | F2: 143 | G2: 146 | H2: 152 | I2: 170 | J2: 171 | K2: 175 | L2: 183 | M2: 200 | N2: 113 | O2: 172 | P2: 177 | Q2: 178 | R2: 179 | S2: 180 | T2: 184 | U2: 207 | V2: Filter | W2: Cluster | X2: T-test | Y2: Gem 0 | Z2: Gem 1
