Workbook

Sheet Absolute counts
E1: 0 | F1: 0 | G1: 0 | H1: 0 | I1: 0 | J1: 0 | K1: 0 | L1: 1 | M1: 1 | N1: 1 | O1: 1 | P1: 1
A2: id | B2: name | C2: structure_order | D2: parent_id | E2: 67898 | F2: 190211 | G2: 191735 | H2: 212741 | I2: 277750 | J2: 340773 | K2: 340805 | L2: 190196 | M2: 190198 | N2: 340770 | O2: 340771 | P2: 343011 | Q2: Filter | R2: Cluster | S2: T-test | T2: Gem 0 | U2: Gem 1
A3: 0 | B3: background | C3: 0 | E3: 46349 | F3: 79639 | G3: 110831 | H3: 68308 | I3: 175627 | J3: 33015 | K3: 75427 | L3: 65514 | M3: 39420 | N3: 94696 | O3: 142784 | P3: 100623 | Q3: =IF(AND(T3=0,U3=0),0,1) -> 1 | R3: =SUMIFS(Tabel132[Cluster],Tabel132[ID],A3) -> 0 | S3: =IFERROR(_xlfn.T.TEST(E3:K3,L3:P3,2,2),"") -> 0.86732438 | T3: =AVERAGE(E3:K3) -> 84170.857 | U3: =AVERAGE(L3:P3) -> 88607.4
A4: 1 | B4: Tuberomammillary nucleus, ventral part | C4: 75500 | D4: 557 | E4: 1 | F4: 9 | G4: 0 | H4: 9 | I4: 0 | J4: 0 | K4: 51 | L4: 0 | M4: 4 | N4: 0 | O4: 37 | P4: 0 | Q4: =IF(AND(T4=0,U4=0),0,1) -> 1 | R4: =SUMIFS(Tabel132[Cluster],Tabel132[ID],A4) -> 84 | S4: =IFERROR(_xlfn.T.TEST(E4:K4,L4:P4,2,2),"") -> 0.86515611 | T4: =AVERAGE(E4:K4) -> 10 | U4: =AVERAGE(L4:P4) -> 8.2
A5: 2 | B5: Primary somatosensory area, mouth, layer 6b | C5: 6200 | D5: 345 | E5: 868 | F5: 566 | G5: 350 | H5: 1286 | I5: 749 | J5: 449 | K5: 908 | L5: 375 | M5: 460 | N5: 1112 | O5: 1790 | P5: 1218 | Q5: =IF(AND(T5=0,U5=0),0,1) -> 1 | R5: =SUMIFS(Tabel132[Cluster],Tabel132[ID],A5) -> 8 | S5: =IFERROR(_xlfn.T.TEST(E5:K5,L5:P5,2,2),"") -> 0.3565587 | T5: =AVERAGE(E5:K5) -> 739.42857 | U5: =AVERAGE(L5:P5) -> 991
A6: 3 | B6: secondary fissure | C6: 118200 | D6: 1040 | E6: 0 | F6: 0 | G6: 0 | H6: 0 | I6: 0 | J6: 0 | K6: 0 | L6: 0 | M6: 0 | N6: 0 | O6: 0 | P6: 0 | Q6: =IF(AND(T6=0,U6=0),0,1) -> 0 | R6: =SUMIFS(Tabel132[Cluster],Tabel132[ID],A6) -> 0 | S6: =IFERROR(_xlfn.T.TEST(E6:K6,L6:P6,2,2),"") | T6: =AVERAGE(E6:K6) -> 0 | U6: =AVERAGE(L6:P6) -> 0
A7: 4 | B7: Inferior colliculus | C7: 79100 | D7: 339 | E7: 4693 | F7: 2312 | G7: 2765 | H7: 7998 | I7: 71 | J7: 1448 | K7: 11220 | L7: 1154 | M7: 1074 | N7: 1035 | O7: 3654 | P7: 14627 | Q7: =IF(AND(T7=0,U7=0),0,1) -> 1 | R7: =SUMIFS(Tabel132[Cluster],Tabel132[ID],A7) -> 86 | S7: =IFERROR(_xlfn.T.TEST(E7:K7,L7:P7,2,2),"") -> 0.98638695 | T7: =AVERAGE(E7:K7) -> 4358.1429 | U7: =AVERAGE(L7:P7) -> 4308.8
A8: 6 | B8: internal capsule | C8: 107000 | D8: 784 | E8: 19720 | F8: 25407 | G8: 6901 | H8: 34310 | I8: 18622 | J8: 11954 | K8: 10693 | L8: 13587 | M8: 9854 | N8: 9324 | O8: 25262 | P8: 12287 | Q8: =IF(AND(T8=0,U8=0),0,1) -> 1 | R8: =SUMIFS(Tabel132[Cluster],Tabel132[ID],A8) -> 0 | S8: =IFERROR(_xlfn.T.TEST(E8:K8,L8:P8,2,2),"") -> 0.41683725 | T8: =AVERAGE(E8:K8) -> 18229.571 | U8: =AVERAGE(L8:P8) -> 14062.8
A9: 7 | B9: Principal sensory nucleus of the trigeminal | C9: 85300 | D9: 1132 | E9: 30 | F9: 155 | G9: 102 | H9: 622 | I9: 0 | J9: 238 | K9: 1821 | L9: 105 | M9: 990 | N9: 19 | O9: 19 | P9: 1645 | Q9: =IF(AND(T9=0,U9=0),0,1) -> 1 | R9: =SUMIFS(Tabel132[Cluster],Tabel132[ID],A9) -> 93 | S9: =IFERROR(_xlfn.T.TEST(E9:K9,L9:P9,2,2),"") -> 0.74956599 | T9: =AVERAGE(E9:K9) -> 424 | U9: =AVERAGE(L9:P9) -> 555.6
A10: 8 | B10: Basic cell groups and regions | C10: 100 | D10: 997 | E10: 0 | F10: 0 | G10: 0 | H10: 0 | I10: 0 | J10: 0 | K10: 0 | L10: 0 | M10: 0 | N10: 0 | O10: 0 | P10: 0 | Q10: =IF(AND(T10=0,U10=0),0,1) -> 0 | R10: =SUMIFS(Tabel132[Cluster],Tabel132[ID],A10) -> 0 | S10: =IFERROR(_xlfn.T.TEST(E10:K10,L10:P10,2,2),"") | T10: =AVERAGE(E10:K10) -> 0 | U10: =AVERAGE(L10:P10) -> 0
A11: 9 | B11: Primary somatosensory area, trunk, layer 6a | C11: 7500 | D11: 361 | E11: 922 | F11: 188 | G11: 151 | H11: 438 | I11: 241 | J11: 755 | K11: 520 | L11: 154 | M11: 554 | N11: 1115 | O11: 572 | P11: 711 | Q11: =IF(AND(T11=0,U11=0),0,1) -> 1 | R11: =SUMIFS(Tabel132[Cluster],Tabel132[ID],A11) -> 10 | S11: =IFERROR(_xlfn.T.TEST(E11:K11,L11:P11,2,2),"") -> 0.40218635 | T11: =AVERAGE(E11:K11) -> 459.28571 | U11: =AVERAGE(L11:P11) -> 621.2
A12: 10 | B12: Superior colliculus, motor related, intermediate gray layer | C12: 81100 | D12: 294 | E12: 2774 | F12: 921 | G12: 731 | H12: 4566 | I12: 1976 | J12: 742 | K12: 1408 | L12: 1032 | M12: 207 | N12: 4709 | O12: 1672 | P12: 7465 | Q12: =IF(AND(T12=0,U12=0),0,1) -> 1 | R12: =SUMIFS(Tabel132[Cluster],Tabel132[ID],A12) -> 89 | S12: =IFERROR(_xlfn.T.TEST(E12:K12,L12:P12,2,2),"") -> 0.39421882 | T12: =AVERAGE(E12:K12) -> 1874 | U12: =AVERAGE(L12:P12) -> 3017
A13: 11 | B13: posterolateral fissure | C13: 118300 | D13: 1040 | E13: 0 | F13: 0 | G13: 0 | H13: 0 | I13: 0 | J13: 0 | K13: 0 | L13: 0 | M13: 0 | N13: 0 | O13: 0 | P13: 0 | Q13: =IF(AND(T13=0,U13=0),0,1) -> 0 | R13: =SUMIFS(Tabel132[Cluster],Tabel132[ID],A13) -> 0 | S13: =IFERROR(_xlfn.T.TEST(E13:K13,L13:P13,2,2),"") | T13: =AVERAGE(E13:K13) -> 0 | U13: =AVERAGE(L13:P13) -> 0
A14: 12 | B14: Interfascicular nucleus raphÈ | C14: 84100 | D14: 165 | E14: 0 | F14: 0 | G14: 0 | H14: 0 | I14: 0 | J14: 0 | K14: 0 | L14: 0 | M14: 0 | N14: 0 | O14: 0 | P14: 0 | Q14: =IF(AND(T14=0,U14=0),0,1) -> 0 | R14: =SUMIFS(Tabel132[Cluster],Tabel132[ID],A14) -> 92 | S14: =IFERROR(_xlfn.T.TEST(E14:K14,L14:P14,2,2),"") | T14: =AVERAGE(E14:K14) -> 0 | U14: =AVERAGE(L14:P14) -> 0
A15: 14 | B15: internal medullary lamina of the thalamus | C15: 108200 | D15: 896 | E15: 4 | F15: 0 | G15: 0 | H15: 1 | I15: 5 | J15: 0 | K15: 3 | L15: 0 | M15: 0 | N15: 5 | O15: 0 | P15: 0 | Q15: =IF(AND(T15=0,U15=0),0,1) -> 1 | R15: =SUMIFS(Tabel132[Cluster],Tabel132[ID],A15) -> 0 | S15: =IFERROR(_xlfn.T.TEST(E15:K15,L15:P15,2,2),"") -> 0.51421637 | T15: =AVERAGE(E15:K15) -> 1.8571429 | U15: =AVERAGE(L15:P15) -> 1
... A988: 996 | B988: Agranular insular area, dorsal part, layer 1 | C988: 23500 | D988: 104 | E988: 1117 | F988: 3518 | G988: 1474 | H988: 957 | I988: 271 | J988: 965 | K988: 476 | L988: 1214 | M988: 1809 | N988: 2037 | O988: 2339 | P988: 794 | Q988: =IF(AND(T988=0,U988=0),0,1) -> 1 | R988: =SUMIFS(Tabel132[Cluster],Tabel132[ID],A988) -> 30 | S988: =IFERROR(_xlfn.T.TEST(E988:K988,L988:P988,2,2),"") -> 0.49268675 | T988: =AVERAGE(E988:K988) -> 1254 | U988: =AVERAGE(L988:P988) -> 1638.6
A989: 997 | B989: root | C989: 0 | E989: 1 | F989: 0 | G989: 3 | H989: 2 | I989: 0 | J989: 3 | K989: 0 | L989: 0 | M989: 0 | N989: 0 | O989: 7 | P989: 0 | Q989: =IF(AND(T989=0,U989=0),0,1) -> 1 | R989: =SUMIFS(Tabel132[Cluster],Tabel132[ID],A989) -> 0 | S989: =IFERROR(_xlfn.T.TEST(E989:K989,L989:P989,2,2),"") -> 0.93258765 | T989: =AVERAGE(E989:K989) -> 1.2857143 | U989: =AVERAGE(L989:P989) -> 1.4
A990: 998 | B990: Fundus of striatum | C990: 48500 | D990: 493 | E990: 439 | F990: 353 | G990: 254 | H990: 847 | I990: 369 | J990: 194 | K990: 599 | L990: 89 | M990: 49 | N990: 960 | O990: 304 | P990: 1302 | Q990: =IF(AND(T990=0,U990=0),0,1) -> 1 | R990: =SUMIFS(Tabel132[Cluster],Tabel132[ID],A990) -> 64 | S990: =IFERROR(_xlfn.T.TEST(E990:K990,L990:P990,2,2),"") -> 0.66097852 | T990: =AVERAGE(E990:K990) -> 436.42857 | U990: =AVERAGE(L990:P990) -> 540.8
A991: 999 | B991: Entorhinal area, lateral part, layer 2/3 | C991: 41600 | D991: 918 | E991: 0 | F991: 0 | G991: 0 | H991: 0 | I991: 0 | J991: 0 | K991: 0 | L991: 0 | M991: 0 | N991: 0 | O991: 0 | P991: 0 | Q991: =IF(AND(T991=0,U991=0),0,1) -> 0 | R991: =SUMIFS(Tabel132[Cluster],Tabel132[ID],A991) -> 54 | S991: =IFERROR(_xlfn.T.TEST(E991:K991,L991:P991,2,2),"") | T991: =AVERAGE(E991:K991) -> 0 | U991: =AVERAGE(L991:P991) -> 0
A992: 1000 | B992: extrapyramidal fiber systems | C992: 108500 | D992: 1009 | E992: 0 | F992: 0 | G992: 0 | H992: 0 | I992: 0 | J992: 0 | K992: 0 | L992: 0 | M992: 0 | N992: 0 | O992: 0 | P992: 0 | Q992: =IF(AND(T992=0,U992=0),0,1) -> 0 | R992: =SUMIFS(Tabel132[Cluster],Tabel132[ID],A992) -> 0 | S992: =IFERROR(_xlfn.T.TEST(E992:K992,L992:P992,2,2),"") | T992: =AVERAGE(E992:K992) -> 0 | U992: =AVERAGE(L992:P992) -> 0
A993: 1001 | B993: Lobule V | C993: 56800 | D993: 928 | E993: 0 | F993: 0 | G993: 0 | H993: 0 | I993: 0 | J993: 0 | K993: 0 | L993: 0 | M993: 0 | N993: 0 | O993: 0 | P993: 0 | Q993: =IF(AND(T993=0,U993=0),0,1) -> 0 | R993: =SUMIFS(Tabel132[Cluster],Tabel132[ID],A993) -> 0 | S993: =IFERROR(_xlfn.T.TEST(E993:K993,L993:P993,2,2),"") | T993: =AVERAGE(E993:K993) -> 0 | U993: =AVERAGE(L993:P993) -> 0
A994: 1002 | B994: Primary auditory area | C994: 11300 | D994: 247 | E994: 0 | F994: 0 | G994: 0 | H994: 0 | I994: 0 | J994: 0 | K994: 0 | L994: 0 | M994: 0 | N994: 0 | O994: 0 | P994: 0 | Q994: =IF(AND(T994=0,U994=0),0,1) -> 0 | R994: =SUMIFS(Tabel132[Cluster],Tabel132[ID],A994) -> 15 | S994: =IFERROR(_xlfn.T.TEST(E994:K994,L994:P994,2,2),"") | T994: =AVERAGE(E994:K994) -> 0 | U994: =AVERAGE(L994:P994) -> 0
A995: 1003 | B995: corticopontine tract | C995: 107400 | D995: 784 | E995: 0 | F995: 0 | G995: 0 | H995: 0 | I995: 0 | J995: 0 | K995: 0 | L995: 0 | M995: 0 | N995: 0 | O995: 0 | P995: 0 | Q995: =IF(AND(T995=0,U995=0),0,1) -> 0 | R995: =SUMIFS(Tabel132[Cluster],Tabel132[ID],A995) -> 0 | S995: =IFERROR(_xlfn.T.TEST(E995:K995,L995:P995,2,2),"") | T995: =AVERAGE(E995:K995) -> 0 | U995: =AVERAGE(L995:P995) -> 0
A996: 1004 | B996: Ventral premammillary nucleus | C996: 76100 | D996: 467 | E996: 0 | F996: 0 | G996: 0 | H996: 0 | I996: 0 | J996: 0 | K996: 10 | L996: 0 | M996: 1 | N996: 14 | O996: 31 | P996: 4 | Q996: =IF(AND(T996=0,U996=0),0,1) -> 1 | R996: =SUMIFS(Tabel132[Cluster],Tabel132[ID],A996) -> 84 | S996: =IFERROR(_xlfn.T.TEST(E996:K996,L996:P996,2,2),"") -> 0.12398386 | T996: =AVERAGE(E996:K996) -> 1.4285714 | U996: =AVERAGE(L996:P996) -> 10
A997: 1005 | B997: Primary auditory area, layer 6b | C997: 11900 | D997: 1002 | E997: 142 | F997: 147 | G997: 106 | H997: 375 | I997: 259 | J997: 141 | K997: 220 | L997: 175 | M997: 167 | N997: 370 | O997: 172 | P997: 190 | Q997: =IF(AND(T997=0,U997=0),0,1) -> 1 | R997: =SUMIFS(Tabel132[Cluster],Tabel132[ID],A997) -> 15 | S997: =IFERROR(_xlfn.T.TEST(E997:K997,L997:P997,2,2),"") -> 0.76771778 | T997: =AVERAGE(E997:K997) -> 198.57143 | U997: =AVERAGE(L997:P997) -> 214.8
A998: 1006 | B998: Primary somatosensory area, trunk, layer 1 | C998: 7100 | D998: 361 | E998: 217 | F998: 306 | G998: 280 | H998: 298 | I998: 558 | J998: 358 | K998: 1 | L998: 318 | M998: 175 | N998: 724 | O998: 530 | P998: 27 | Q998: =IF(AND(T998=0,U998=0),0,1) -> 1 | R998: =SUMIFS(Tabel132[Cluster],Tabel132[ID],A998) -> 10 | S998: =IFERROR(_xlfn.T.TEST(E998:K998,L998:P998,2,2),"") -> 0.61313801 | T998: =AVERAGE(E998:K998) -> 288.28571 | U998: =AVERAGE(L998:P998) -> 354.8
A999: 1007 | B999: Simple lobule | C999: 59700 | D999: 1073 | E999: 9 | F999: 98 | G999: 3135 | H999: 668 | I999: 2 | J999: 29 | K999: 155 | L999: 77 | M999: 15 | N999: 517 | O999: 537 | P999: 145 | Q999: =IF(AND(T999=0,U999=0),0,1) -> 1 | R999: =SUMIFS(Tabel132[Cluster],Tabel132[ID],A999) -> 0 | S999: =IFERROR(_xlfn.T.TEST(E999:K999,L999:P999,2,2),"") -> 0.5503585 | T999: =AVERAGE(E999:K999) -> 585.14286 | U999: =AVERAGE(L999:P999) -> 258.2
A1000: 1008 | B1000: Geniculate group, dorsal thalamus | C1000: 65000 | D1000: 864 | E1000: 0 | F1000: 0 | G1000: 0 | H1000: 0 | I1000: 0 | J1000: 0 | K1000: 0 | L1000: 0 | M1000: 0 | N1000: 0 | O1000: 0 | P1000: 0 | Q1000: =IF(AND(T1000=0,U1000=0),0,1) -> 0 | R1000: =SUMIFS(Tabel132[Cluster],Tabel132[ID],A1000) -> 77 | S1000: =IFERROR(_xlfn.T.TEST(E1000:K1000,L1000:P1000,2,2),"") | T1000: =AVERAGE(E1000:K1000) -> 0 | U1000: =AVERAGE(L1000:P1000) -> 0
A1001: 1009 | B1001: fiber tracts | C1001: 97200 | D1001: 997 | E1001: 17820 | F1001: 12658 | G1001: 2912 | H1001: 19111 | I1001: 9646 | J1001: 5937 | K1001: 5881 | L1001: 6995 | M1001: 5180 | N1001: 8993 | O1001: 16680 | P1001: 8199 | Q1001: =IF(AND(T1001=0,U1001=0),0,1) -> 1 | R1001: =SUMIFS(Tabel132[Cluster],Tabel132[ID],A1001) -> 0 | S1001: =IFERROR(_xlfn.T.TEST(E1001:K1001,L1001:P1001,2,2),"") -> 0.68641936 | T1001: =AVERAGE(E1001:K1001) -> 10566.429 | U1001: =AVERAGE(L1001:P1001) -> 9209.4
... A1244: 312782656 | B1244: Unlabeled | C1244: 300 | D1244: 688 | E1244: 586 | F1244: 605 | G1244: 877 | H1244: 236 | I1244: 549 | J1244: 310 | K1244: 481 | L1244: 443 | M1244: 403 | N1244: 395 | O1244: 455 | P1244: 339 | Q1244: =IF(AND(T1244=0,U1244=0),0,1) -> 1 | R1244: =SUMIFS(Tabel132[Cluster],Tabel132[ID],A1244) -> 0 | S1244: =IFERROR(_xlfn.T.TEST(E1244:K1244,L1244:P1244,2,2),"") -> 0.26888984 | T1244: =AVERAGE(E1244:K1244) -> 520.57143 | U1244: =AVERAGE(L1244:P1244) -> 407
E1246: =SUM(E3:E1244) -> 860554 | F1246: =SUM(F3:F1244) -> 716789 | G1246: =SUM(G3:G1244) -> 559995 | H1246: =SUM(H3:H1244) -> 1310637 | I1246: =SUM(I3:I1244) -> 811163 | J1246: =SUM(J3:J1244) -> 460308 | K1246: =SUM(K3:K1244) -> 707921 | L1246: =SUM(L3:L1244) -> 496145 | ... P1246: =SUM(P3:P1244) -> 1097198

Sheet Total-corrected counts
E1: 0 | F1: 0 | G1: 0 | H1: 0 | I1: 0 | J1: 0 | K1: 0 | L1: 1 | M1: 1 | N1: 1 | O1: 1 | P1: 1
A2: id | B2: name | C2: structure_order | D2: parent_id | E2: 67898 | F2: 190211 | G2: 191735 | H2: 212741 | I2: 277750 | J2: 340773 | K2: 340805 | L2: 190196 | M2: 190198 | N2: 340770 | O2: 340771 | P2: 343011 | Q2: Filter | R2: T-test | S2: Gem 0 | T2: Gem 1
A3: 0 | B3: background | C3: 0 | E3: ='Absolute counts'!E3/'Absolute counts'!E$1246*10000 -> 538.59491 | F3: ='Absolute counts'!F3/'Absolute counts'!F$1246*10000 -> 1111.0522 | G3: ='Absolute counts'!G3/'Absolute counts'!G$1246*10000 -> 1979.1427 | H3: ='Absolute counts'!H3/'Absolute counts'!H$1246*10000 -> 521.18168 | I3: ='Absolute counts'!I3/'Absolute counts'!I$1246*10000 -> 2165.1259 | J3: ='Absolute counts'!J3/'Absolute counts'!J$1246*10000 -> 717.23715 | K3: ='Absolute counts'!K3/'Absolute counts'!K$1246*10000 -> 1065.472 | L3: ='Absolute counts'!L3/'Absolute counts'!L$1246*10000 -> 1320.4608 | ... P3: ='Absolute counts'!P3/'Absolute counts'!P$1246*10000 -> 917.09063 | Q3: =IF(AND(S3=0,T3=0),0,1) -> 1 | R3: =IFERROR(_xlfn.T.TEST(E3:K3,L3:P3,2,2),"") -> 0.7181014 | S3: =AVERAGE(E3:K3) -> 1156.8295 | T3: =AVERAGE(L3:P3) -> 1038.2301
A4: 1 | B4: Tuberomammillary nucleus, ventral part | C4: 75500 | D4: 557 | E4: ='Absolute counts'!E4/'Absolute counts'!E$1246*10000 -> 0.011620421 | F4: ='Absolute counts'!F4/'Absolute counts'!F$1246*10000 -> 0.12555996 | G4: ='Absolute counts'!G4/'Absolute counts'!G$1246*10000 -> 0 | H4: ='Absolute counts'!H4/'Absolute counts'!H$1246*10000 -> 0.068668899 | I4: ='Absolute counts'!I4/'Absolute counts'!I$1246*10000 -> 0 | J4: ='Absolute counts'!J4/'Absolute counts'!J$1246*10000 -> 0 | K4: ='Absolute counts'!K4/'Absolute counts'!K$1246*10000 -> 0.72041937 | L4: ='Absolute counts'!L4/'Absolute counts'!L$1246*10000 -> 0 | ... P4: ='Absolute counts'!P4/'Absolute counts'!P$1246*10000 -> 0 | Q4: =IF(AND(S4=0,T4=0),0,1) -> 1 | R4: =IFERROR(_xlfn.T.TEST(E4:K4,L4:P4,2,2),"") -> 0.73140141 | S4: =AVERAGE(E4:K4) -> 0.13232409 | T4: =AVERAGE(L4:P4) -> 0.085762261
A5: 2 | B5: Primary somatosensory area, mouth, layer 6b | C5: 6200 | D5: 345 | E5: ='Absolute counts'!E5/'Absolute counts'!E$1246*10000 -> 10.086526 | F5: ='Absolute counts'!F5/'Absolute counts'!F$1246*10000 -> 7.8963265 | G5: ='Absolute counts'!G5/'Absolute counts'!G$1246*10000 -> 6.2500558 | H5: ='Absolute counts'!H5/'Absolute counts'!H$1246*10000 -> 9.8120227 | I5: ='Absolute counts'!I5/'Absolute counts'!I$1246*10000 -> 9.2336559 | J5: ='Absolute counts'!J5/'Absolute counts'!J$1246*10000 -> 9.7543384 | K5: ='Absolute counts'!K5/'Absolute counts'!K$1246*10000 -> 12.82629 | L5: ='Absolute counts'!L5/'Absolute counts'!L$1246*10000 -> 7.5582743 | ... P5: ='Absolute counts'!P5/'Absolute counts'!P$1246*10000 -> 11.101005 | Q5: =IF(AND(S5=0,T5=0),0,1) -> 1 | R5: =IFERROR(_xlfn.T.TEST(E5:K5,L5:P5,2,2),"") -> 0.38317402 | S5: =AVERAGE(E5:K5) -> 9.4084593 | T5: =AVERAGE(L5:P5) -> 10.869271
A6: 3 | B6: secondary fissure | C6: 118200 | D6: 1040 | E6: ='Absolute counts'!E6/'Absolute counts'!E$1246*10000 -> 0 | F6: ='Absolute counts'!F6/'Absolute counts'!F$1246*10000 -> 0 | G6: ='Absolute counts'!G6/'Absolute counts'!G$1246*10000 -> 0 | H6: ='Absolute counts'!H6/'Absolute counts'!H$1246*10000 -> 0 | I6: ='Absolute counts'!I6/'Absolute counts'!I$1246*10000 -> 0 | J6: ='Absolute counts'!J6/'Absolute counts'!J$1246*10000 -> 0 | K6: ='Absolute counts'!K6/'Absolute counts'!K$1246*10000 -> 0 | L6: ='Absolute counts'!L6/'Absolute counts'!L$1246*10000 -> 0 | ... P6: ='Absolute counts'!P6/'Absolute counts'!P$1246*10000 -> 0 | Q6: =IF(AND(S6=0,T6=0),0,1) -> 0 | R6: =IFERROR(_xlfn.T.TEST(E6:K6,L6:P6,2,2),"") | S6: =AVERAGE(E6:K6) -> 0 | T6: =AVERAGE(L6:P6) -> 0
A7: 4 | B7: Inferior colliculus | C7: 79100 | D7: 339 | E7: ='Absolute counts'!E7/'Absolute counts'!E$1246*10000 -> 54.534637 | F7: ='Absolute counts'!F7/'Absolute counts'!F$1246*10000 -> 32.254959 | G7: ='Absolute counts'!G7/'Absolute counts'!G$1246*10000 -> 49.375441 | H7: ='Absolute counts'!H7/'Absolute counts'!H$1246*10000 -> 61.023762 | I7: ='Absolute counts'!I7/'Absolute counts'!I$1246*10000 -> 0.87528647 | J7: ='Absolute counts'!J7/'Absolute counts'!J$1246*10000 -> 31.457198 | K7: ='Absolute counts'!K7/'Absolute counts'!K$1246*10000 -> 158.49226 | L7: ='Absolute counts'!L7/'Absolute counts'!L$1246*10000 -> 23.259329 | ... P7: ='Absolute counts'!P7/'Absolute counts'!P$1246*10000 -> 133.31231 | Q7: =IF(AND(S7=0,T7=0),0,1) -> 1 | R7: =IFERROR(_xlfn.T.TEST(E7:K7,L7:P7,2,2),"") -> 0.71244647 | S7: =AVERAGE(E7:K7) -> 55.430506 | T7: =AVERAGE(L7:P7) -> 44.327409
A8: 6 | B8: internal capsule | C8: 107000 | D8: 784 | E8: ='Absolute counts'!E8/'Absolute counts'!E$1246*10000 -> 229.15471 | F8: ='Absolute counts'!F8/'Absolute counts'!F$1246*10000 -> 354.45577 | G8: ='Absolute counts'!G8/'Absolute counts'!G$1246*10000 -> 123.23324 | H8: ='Absolute counts'!H8/'Absolute counts'!H$1246*10000 -> 261.7811 | I8: ='Absolute counts'!I8/'Absolute counts'!I$1246*10000 -> 229.57162 | J8: ='Absolute counts'!J8/'Absolute counts'!J$1246*10000 -> 259.69568 | K8: ='Absolute counts'!K8/'Absolute counts'!K$1246*10000 -> 151.04793 | L8: ='Absolute counts'!L8/'Absolute counts'!L$1246*10000 -> 273.85139 | ... P8: ='Absolute counts'!P8/'Absolute counts'!P$1246*10000 -> 111.98526 | Q8: =IF(AND(S8=0,T8=0),0,1) -> 1 | R8: =IFERROR(_xlfn.T.TEST(E8:K8,L8:P8,2,2),"") -> 0.31295418 | S8: =AVERAGE(E8:K8) -> 229.84858 | T8: =AVERAGE(L8:P8) -> 180.76754
A9: 7 | B9: Principal sensory nucleus of the trigeminal | C9: 85300 | D9: 1132 | E9: ='Absolute counts'!E9/'Absolute counts'!E$1246*10000 -> 0.34861264 | F9: ='Absolute counts'!F9/'Absolute counts'!F$1246*10000 -> 2.1624216 | G9: ='Absolute counts'!G9/'Absolute counts'!G$1246*10000 -> 1.8214448 | H9: ='Absolute counts'!H9/'Absolute counts'!H$1246*10000 -> 4.7457839 | I9: ='Absolute counts'!I9/'Absolute counts'!I$1246*10000 -> 0 | J9: ='Absolute counts'!J9/'Absolute counts'!J$1246*10000 -> 5.1704511 | K9: ='Absolute counts'!K9/'Absolute counts'!K$1246*10000 -> 25.723209 | L9: ='Absolute counts'!L9/'Absolute counts'!L$1246*10000 -> 2.1163168 | ... P9: ='Absolute counts'!P9/'Absolute counts'!P$1246*10000 -> 14.992736 | Q9: =IF(AND(S9=0,T9=0),0,1) -> 1 | R9: =IFERROR(_xlfn.T.TEST(E9:K9,L9:P9,2,2),"") -> 0.7413287 | S9: =AVERAGE(E9:K9) -> 5.7102748 | T9: =AVERAGE(L9:P9) -> 7.537824
A10: 8 | B10: Basic cell groups and regions | C10: 100 | D10: 997 | E10: ='Absolute counts'!E10/'Absolute counts'!E$1246*10000 -> 0 | F10: ='Absolute counts'!F10/'Absolute counts'!F$1246*10000 -> 0 | G10: ='Absolute counts'!G10/'Absolute counts'!G$1246*10000 -> 0 | H10: ='Absolute counts'!H10/'Absolute counts'!H$1246*10000 -> 0 | I10: ='Absolute counts'!I10/'Absolute counts'!I$1246*10000 -> 0 | J10: ='Absolute counts'!J10/'Absolute counts'!J$1246*10000 -> 0 | K10: ='Absolute counts'!K10/'Absolute counts'!K$1246*10000 -> 0 | L10: ='Absolute counts'!L10/'Absolute counts'!L$1246*10000 -> 0 | ... P10: ='Absolute counts'!P10/'Absolute counts'!P$1246*10000 -> 0 | Q10: =IF(AND(S10=0,T10=0),0,1) -> 0 | R10: =IFERROR(_xlfn.T.TEST(E10:K10,L10:P10,2,2),"") | S10: =AVERAGE(E10:K10) -> 0 | T10: =AVERAGE(L10:P10) -> 0
A11: 9 | B11: Primary somatosensory area, trunk, layer 6a | C11: 7500 | D11: 361 | E11: ='Absolute counts'!E11/'Absolute counts'!E$1246*10000 -> 10.714028 | F11: ='Absolute counts'!F11/'Absolute counts'!F$1246*10000 -> 2.6228081 | G11: ='Absolute counts'!G11/'Absolute counts'!G$1246*10000 -> 2.6964526 | H11: ='Absolute counts'!H11/'Absolute counts'!H$1246*10000 -> 3.3418864 | I11: ='Absolute counts'!I11/'Absolute counts'!I$1246*10000 -> 2.9710428 | J11: ='Absolute counts'!J11/'Absolute counts'!J$1246*10000 -> 16.402061 | K11: ='Absolute counts'!K11/'Absolute counts'!K$1246*10000 -> 7.3454524 | L11: ='Absolute counts'!L11/'Absolute counts'!L$1246*10000 -> 3.1039313 | ... P11: ='Absolute counts'!P11/'Absolute counts'!P$1246*10000 -> 6.4801431 | Q11: =IF(AND(S11=0,T11=0),0,1) -> 1 | R11: =IFERROR(_xlfn.T.TEST(E11:K11,L11:P11,2,2),"") -> 0.835449 | S11: =AVERAGE(E11:K11) -> 6.5848189 | T11: =AVERAGE(L11:P11) -> 7.158898
A12: 10 | B12: Superior colliculus, motor related, intermediate gray layer | C12: 81100 | D12: 294 | E12: ='Absolute counts'!E12/'Absolute counts'!E$1246*10000 -> 32.235049 | F12: ='Absolute counts'!F12/'Absolute counts'!F$1246*10000 -> 12.84897 | G12: ='Absolute counts'!G12/'Absolute counts'!G$1246*10000 -> 13.053688 | H12: ='Absolute counts'!H12/'Absolute counts'!H$1246*10000 -> 34.838022 | I12: ='Absolute counts'!I12/'Absolute counts'!I$1246*10000 -> 24.360085 | J12: ='Absolute counts'!J12/'Absolute counts'!J$1246*10000 -> 16.119642 | K12: ='Absolute counts'!K12/'Absolute counts'!K$1246*10000 -> 19.889225 | L12: ='Absolute counts'!L12/'Absolute counts'!L$1246*10000 -> 20.800371 | ... P12: ='Absolute counts'!P12/'Absolute counts'!P$1246*10000 -> 68.036945 | Q12: =IF(AND(S12=0,T12=0),0,1) -> 1 | R12: =IFERROR(_xlfn.T.TEST(E12:K12,L12:P12,2,2),"") -> 0.45359851 | S12: =AVERAGE(E12:K12) -> 21.906383 | T12: =AVERAGE(L12:P12) -> 29.791001
A13: 11 | B13: posterolateral fissure | C13: 118300 | D13: 1040 | E13: ='Absolute counts'!E13/'Absolute counts'!E$1246*10000 -> 0 | F13: ='Absolute counts'!F13/'Absolute counts'!F$1246*10000 -> 0 | G13: ='Absolute counts'!G13/'Absolute counts'!G$1246*10000 -> 0 | H13: ='Absolute counts'!H13/'Absolute counts'!H$1246*10000 -> 0 | I13: ='Absolute counts'!I13/'Absolute counts'!I$1246*10000 -> 0 | J13: ='Absolute counts'!J13/'Absolute counts'!J$1246*10000 -> 0 | K13: ='Absolute counts'!K13/'Absolute counts'!K$1246*10000 -> 0 | L13: ='Absolute counts'!L13/'Absolute counts'!L$1246*10000 -> 0 | ... P13: ='Absolute counts'!P13/'Absolute counts'!P$1246*10000 -> 0 | Q13: =IF(AND(S13=0,T13=0),0,1) -> 0 | R13: =IFERROR(_xlfn.T.TEST(E13:K13,L13:P13,2,2),"") | S13: =AVERAGE(E13:K13) -> 0 | T13: =AVERAGE(L13:P13) -> 0
A14: 12 | B14: Interfascicular nucleus raphÈ | C14: 84100 | D14: 165 | E14: ='Absolute counts'!E14/'Absolute counts'!E$1246*10000 -> 0 | F14: ='Absolute counts'!F14/'Absolute counts'!F$1246*10000 -> 0 | G14: ='Absolute counts'!G14/'Absolute counts'!G$1246*10000 -> 0 | H14: ='Absolute counts'!H14/'Absolute counts'!H$1246*10000 -> 0 | I14: ='Absolute counts'!I14/'Absolute counts'!I$1246*10000 -> 0 | J14: ='Absolute counts'!J14/'Absolute counts'!J$1246*10000 -> 0 | K14: ='Absolute counts'!K14/'Absolute counts'!K$1246*10000 -> 0 | L14: ='Absolute counts'!L14/'Absolute counts'!L$1246*10000 -> 0 | ... P14: ='Absolute counts'!P14/'Absolute counts'!P$1246*10000 -> 0 | Q14: =IF(AND(S14=0,T14=0),0,1) -> 0 | R14: =IFERROR(_xlfn.T.TEST(E14:K14,L14:P14,2,2),"") | S14: =AVERAGE(E14:K14) -> 0 | T14: =AVERAGE(L14:P14) -> 0
A15: 14 | B15: internal medullary lamina of the thalamus | C15: 108200 | D15: 896 | E15: ='Absolute counts'!E15/'Absolute counts'!E$1246*10000 -> 0.046481685 | F15: ='Absolute counts'!F15/'Absolute counts'!F$1246*10000 -> 0 | G15: ='Absolute counts'!G15/'Absolute counts'!G$1246*10000 -> 0 | H15: ='Absolute counts'!H15/'Absolute counts'!H$1246*10000 -> 0.0076298777 | I15: ='Absolute counts'!I15/'Absolute counts'!I$1246*10000 -> 0.061639892 | J15: ='Absolute counts'!J15/'Absolute counts'!J$1246*10000 -> 0 | K15: ='Absolute counts'!K15/'Absolute counts'!K$1246*10000 -> 0.04237761 | L15: ='Absolute counts'!L15/'Absolute counts'!L$1246*10000 -> 0 | ... P15: ='Absolute counts'!P15/'Absolute counts'!P$1246*10000 -> 0 | Q15: =IF(AND(S15=0,T15=0),0,1) -> 1 | R15: =IFERROR(_xlfn.T.TEST(E15:K15,L15:P15,2,2),"") -> 0.33849536 | S15: =AVERAGE(E15:K15) -> 0.022589866 | T15: =AVERAGE(L15:P15) -> 0.0085375953
... A988: 996 | B988: Agranular insular area, dorsal part, layer 1 | C988: 23500 | D988: 104 | E988: ='Absolute counts'!E988/'Absolute counts'!E$1246*10000 -> 12.980011 | F988: ='Absolute counts'!F988/'Absolute counts'!F$1246*10000 -> 49.079994 | G988: ='Absolute counts'!G988/'Absolute counts'!G$1246*10000 -> 26.321664 | H988: ='Absolute counts'!H988/'Absolute counts'!H$1246*10000 -> 7.3017929 | I988: ='Absolute counts'!I988/'Absolute counts'!I$1246*10000 -> 3.3408822 | J988: ='Absolute counts'!J988/'Absolute counts'!J$1246*10000 -> 20.964224 | K988: ='Absolute counts'!K988/'Absolute counts'!K$1246*10000 -> 6.7239141 | L988: ='Absolute counts'!L988/'Absolute counts'!L$1246*10000 -> 24.468653 | ... P988: ='Absolute counts'!P988/'Absolute counts'!P$1246*10000 -> 7.2366155 | Q988: =IF(AND(S988=0,T988=0),0,1) -> 1 | R988: =IFERROR(_xlfn.T.TEST(E988:K988,L988:P988,2,2),"") -> 0.68092906 | S988: =AVERAGE(E988:K988) -> 18.101783 | T988: =AVERAGE(L988:P988) -> 21.603588
A989: 997 | B989: root | C989: 0 | E989: ='Absolute counts'!E989/'Absolute counts'!E$1246*10000 -> 0.011620421 | F989: ='Absolute counts'!F989/'Absolute counts'!F$1246*10000 -> 0 | G989: ='Absolute counts'!G989/'Absolute counts'!G$1246*10000 -> 0.053571907 | H989: ='Absolute counts'!H989/'Absolute counts'!H$1246*10000 -> 0.015259755 | I989: ='Absolute counts'!I989/'Absolute counts'!I$1246*10000 -> 0 | J989: ='Absolute counts'!J989/'Absolute counts'!J$1246*10000 -> 0.065173753 | K989: ='Absolute counts'!K989/'Absolute counts'!K$1246*10000 -> 0 | L989: ='Absolute counts'!L989/'Absolute counts'!L$1246*10000 -> 0 | ... P989: ='Absolute counts'!P989/'Absolute counts'!P$1246*10000 -> 0 | Q989: =IF(AND(S989=0,T989=0),0,1) -> 1 | R989: =IFERROR(_xlfn.T.TEST(E989:K989,L989:P989,2,2),"") -> 0.65114993 | S989: =AVERAGE(E989:K989) -> 0.020803691 | T989: =AVERAGE(L989:P989) -> 0.013131053
A990: 998 | B990: Fundus of striatum | C990: 48500 | D990: 493 | E990: ='Absolute counts'!E990/'Absolute counts'!E$1246*10000 -> 5.1013649 | F990: ='Absolute counts'!F990/'Absolute counts'!F$1246*10000 -> 4.9247408 | G990: ='Absolute counts'!G990/'Absolute counts'!G$1246*10000 -> 4.5357548 | H990: ='Absolute counts'!H990/'Absolute counts'!H$1246*10000 -> 6.4625064 | I990: ='Absolute counts'!I990/'Absolute counts'!I$1246*10000 -> 4.5490241 | J990: ='Absolute counts'!J990/'Absolute counts'!J$1246*10000 -> 4.2145694 | K990: ='Absolute counts'!K990/'Absolute counts'!K$1246*10000 -> 8.4613961 | L990: ='Absolute counts'!L990/'Absolute counts'!L$1246*10000 -> 1.7938304 | ... P990: ='Absolute counts'!P990/'Absolute counts'!P$1246*10000 -> 11.866591 | Q990: =IF(AND(S990=0,T990=0),0,1) -> 1 | R990: =IFERROR(_xlfn.T.TEST(E990:K990,L990:P990,2,2),"") -> 0.86648972 | S990: =AVERAGE(E990:K990) -> 5.4641938 | T990: =AVERAGE(L990:P990) -> 5.1419175
A991: 999 | B991: Entorhinal area, lateral part, layer 2/3 | C991: 41600 | D991: 918 | E991: ='Absolute counts'!E991/'Absolute counts'!E$1246*10000 -> 0 | F991: ='Absolute counts'!F991/'Absolute counts'!F$1246*10000 -> 0 | G991: ='Absolute counts'!G991/'Absolute counts'!G$1246*10000 -> 0 | H991: ='Absolute counts'!H991/'Absolute counts'!H$1246*10000 -> 0 | I991: ='Absolute counts'!I991/'Absolute counts'!I$1246*10000 -> 0 | J991: ='Absolute counts'!J991/'Absolute counts'!J$1246*10000 -> 0 | K991: ='Absolute counts'!K991/'Absolute counts'!K$1246*10000 -> 0 | L991: ='Absolute counts'!L991/'Absolute counts'!L$1246*10000 -> 0 | ... P991: ='Absolute counts'!P991/'Absolute counts'!P$1246*10000 -> 0 | Q991: =IF(AND(S991=0,T991=0),0,1) -> 0 | R991: =IFERROR(_xlfn.T.TEST(E991:K991,L991:P991,2,2),"") | S991: =AVERAGE(E991:K991) -> 0 | T991: =AVERAGE(L991:P991) -> 0
A992: 1000 | B992: extrapyramidal fiber systems | C992: 108500 | D992: 1009 | E992: ='Absolute counts'!E992/'Absolute counts'!E$1246*10000 -> 0 | F992: ='Absolute counts'!F992/'Absolute counts'!F$1246*10000 -> 0 | G992: ='Absolute counts'!G992/'Absolute counts'!G$1246*10000 -> 0 | H992: ='Absolute counts'!H992/'Absolute counts'!H$1246*10000 -> 0 | I992: ='Absolute counts'!I992/'Absolute counts'!I$1246*10000 -> 0 | J992: ='Absolute counts'!J992/'Absolute counts'!J$1246*10000 -> 0 | K992: ='Absolute counts'!K992/'Absolute counts'!K$1246*10000 -> 0 | L992: ='Absolute counts'!L992/'Absolute counts'!L$1246*10000 -> 0 | ... P992: ='Absolute counts'!P992/'Absolute counts'!P$1246*10000 -> 0 | Q992: =IF(AND(S992=0,T992=0),0,1) -> 0 | R992: =IFERROR(_xlfn.T.TEST(E992:K992,L992:P992,2,2),"") | S992: =AVERAGE(E992:K992) -> 0 | T992: =AVERAGE(L992:P992) -> 0
A993: 1001 | B993: Lobule V | C993: 56800 | D993: 928 | E993: ='Absolute counts'!E993/'Absolute counts'!E$1246*10000 -> 0 | F993: ='Absolute counts'!F993/'Absolute counts'!F$1246*10000 -> 0 | G993: ='Absolute counts'!G993/'Absolute counts'!G$1246*10000 -> 0 | H993: ='Absolute counts'!H993/'Absolute counts'!H$1246*10000 -> 0 | I993: ='Absolute counts'!I993/'Absolute counts'!I$1246*10000 -> 0 | J993: ='Absolute counts'!J993/'Absolute counts'!J$1246*10000 -> 0 | K993: ='Absolute counts'!K993/'Absolute counts'!K$1246*10000 -> 0 | L993: ='Absolute counts'!L993/'Absolute counts'!L$1246*10000 -> 0 | ... P993: ='Absolute counts'!P993/'Absolute counts'!P$1246*10000 -> 0 | Q993: =IF(AND(S993=0,T993=0),0,1) -> 0 | R993: =IFERROR(_xlfn.T.TEST(E993:K993,L993:P993,2,2),"") | S993: =AVERAGE(E993:K993) -> 0 | T993: =AVERAGE(L993:P993) -> 0
A994: 1002 | B994: Primary auditory area | C994: 11300 | D994: 247 | E994: ='Absolute counts'!E994/'Absolute counts'!E$1246*10000 -> 0 | F994: ='Absolute counts'!F994/'Absolute counts'!F$1246*10000 -> 0 | G994: ='Absolute counts'!G994/'Absolute counts'!G$1246*10000 -> 0 | H994: ='Absolute counts'!H994/'Absolute counts'!H$1246*10000 -> 0 | I994: ='Absolute counts'!I994/'Absolute counts'!I$1246*10000 -> 0 | J994: ='Absolute counts'!J994/'Absolute counts'!J$1246*10000 -> 0 | K994: ='Absolute counts'!K994/'Absolute counts'!K$1246*10000 -> 0 | L994: ='Absolute counts'!L994/'Absolute counts'!L$1246*10000 -> 0 | ... P994: ='Absolute counts'!P994/'Absolute counts'!P$1246*10000 -> 0 | Q994: =IF(AND(S994=0,T994=0),0,1) -> 0 | R994: =IFERROR(_xlfn.T.TEST(E994:K994,L994:P994,2,2),"") | S994: =AVERAGE(E994:K994) -> 0 | T994: =AVERAGE(L994:P994) -> 0
A995: 1003 | B995: corticopontine tract | C995: 107400 | D995: 784 | E995: ='Absolute counts'!E995/'Absolute counts'!E$1246*10000 -> 0 | F995: ='Absolute counts'!F995/'Absolute counts'!F$1246*10000 -> 0 | G995: ='Absolute counts'!G995/'Absolute counts'!G$1246*10000 -> 0 | H995: ='Absolute counts'!H995/'Absolute counts'!H$1246*10000 -> 0 | I995: ='Absolute counts'!I995/'Absolute counts'!I$1246*10000 -> 0 | J995: ='Absolute counts'!J995/'Absolute counts'!J$1246*10000 -> 0 | K995: ='Absolute counts'!K995/'Absolute counts'!K$1246*10000 -> 0 | L995: ='Absolute counts'!L995/'Absolute counts'!L$1246*10000 -> 0 | ... P995: ='Absolute counts'!P995/'Absolute counts'!P$1246*10000 -> 0 | Q995: =IF(AND(S995=0,T995=0),0,1) -> 0 | R995: =IFERROR(_xlfn.T.TEST(E995:K995,L995:P995,2,2),"") | S995: =AVERAGE(E995:K995) -> 0 | T995: =AVERAGE(L995:P995) -> 0
A996: 1004 | B996: Ventral premammillary nucleus | C996: 76100 | D996: 467 | E996: ='Absolute counts'!E996/'Absolute counts'!E$1246*10000 -> 0 | F996: ='Absolute counts'!F996/'Absolute counts'!F$1246*10000 -> 0 | G996: ='Absolute counts'!G996/'Absolute counts'!G$1246*10000 -> 0 | H996: ='Absolute counts'!H996/'Absolute counts'!H$1246*10000 -> 0 | I996: ='Absolute counts'!I996/'Absolute counts'!I$1246*10000 -> 0 | J996: ='Absolute counts'!J996/'Absolute counts'!J$1246*10000 -> 0 | K996: ='Absolute counts'!K996/'Absolute counts'!K$1246*10000 -> 0.1412587 | L996: ='Absolute counts'!L996/'Absolute counts'!L$1246*10000 -> 0 | ... P996: ='Absolute counts'!P996/'Absolute counts'!P$1246*10000 -> 0.036456501 | Q996: =IF(AND(S996=0,T996=0),0,1) -> 1 | R996: =IFERROR(_xlfn.T.TEST(E996:K996,L996:P996,2,2),"") -> 0.17656408 | S996: =AVERAGE(E996:K996) -> 0.020179814 | T996: =AVERAGE(L996:P996) -> 0.093437189
A997: 1005 | B997: Primary auditory area, layer 6b | C997: 11900 | D997: 1002 | E997: ='Absolute counts'!E997/'Absolute counts'!E$1246*10000 -> 1.6500998 | F997: ='Absolute counts'!F997/'Absolute counts'!F$1246*10000 -> 2.0508127 | G997: ='Absolute counts'!G997/'Absolute counts'!G$1246*10000 -> 1.892874 | H997: ='Absolute counts'!H997/'Absolute counts'!H$1246*10000 -> 2.8612041 | I997: ='Absolute counts'!I997/'Absolute counts'!I$1246*10000 -> 3.1929464 | J997: ='Absolute counts'!J997/'Absolute counts'!J$1246*10000 -> 3.0631664 | K997: ='Absolute counts'!K997/'Absolute counts'!K$1246*10000 -> 3.1076914 | L997: ='Absolute counts'!L997/'Absolute counts'!L$1246*10000 -> 3.5271947 | ... P997: ='Absolute counts'!P997/'Absolute counts'!P$1246*10000 -> 1.7316838 | Q997: =IF(AND(S997=0,T997=0),0,1) -> 1 | R997: =IFERROR(_xlfn.T.TEST(E997:K997,L997:P997,2,2),"") -> 0.76010444 | S997: =AVERAGE(E997:K997) -> 2.5455421 | T997: =AVERAGE(L997:P997) -> 2.689039
A998: 1006 | B998: Primary somatosensory area, trunk, layer 1 | C998: 7100 | D998: 361 | E998: ='Absolute counts'!E998/'Absolute counts'!E$1246*10000 -> 2.5216314 | F998: ='Absolute counts'!F998/'Absolute counts'!F$1246*10000 -> 4.2690387 | G998: ='Absolute counts'!G998/'Absolute counts'!G$1246*10000 -> 5.0000446 | H998: ='Absolute counts'!H998/'Absolute counts'!H$1246*10000 -> 2.2737036 | I998: ='Absolute counts'!I998/'Absolute counts'!I$1246*10000 -> 6.879012 | J998: ='Absolute counts'!J998/'Absolute counts'!J$1246*10000 -> 7.7774012 | K998: ='Absolute counts'!K998/'Absolute counts'!K$1246*10000 -> 0.01412587 | L998: ='Absolute counts'!L998/'Absolute counts'!L$1246*10000 -> 6.4094166 | ... P998: ='Absolute counts'!P998/'Absolute counts'!P$1246*10000 -> 0.24608138 | Q998: =IF(AND(S998=0,T998=0),0,1) -> 1 | R998: =IFERROR(_xlfn.T.TEST(E998:K998,L998:P998,2,2),"") -> 0.91374129 | S998: =AVERAGE(E998:K998) -> 4.1049939 | T998: =AVERAGE(L998:P998) -> 4.2770947
A999: 1007 | B999: Simple lobule | C999: 59700 | D999: 1073 | E999: ='Absolute counts'!E999/'Absolute counts'!E$1246*10000 -> 0.10458379 | F999: ='Absolute counts'!F999/'Absolute counts'!F$1246*10000 -> 1.3672085 | G999: ='Absolute counts'!G999/'Absolute counts'!G$1246*10000 -> 55.982643 | H999: ='Absolute counts'!H999/'Absolute counts'!H$1246*10000 -> 5.0967583 | I999: ='Absolute counts'!I999/'Absolute counts'!I$1246*10000 -> 0.024655957 | J999: ='Absolute counts'!J999/'Absolute counts'!J$1246*10000 -> 0.63001295 | K999: ='Absolute counts'!K999/'Absolute counts'!K$1246*10000 -> 2.1895098 | L999: ='Absolute counts'!L999/'Absolute counts'!L$1246*10000 -> 1.5519657 | ... P999: ='Absolute counts'!P999/'Absolute counts'!P$1246*10000 -> 1.3215482 | Q999: =IF(AND(S999=0,T999=0),0,1) -> 1 | R999: =IFERROR(_xlfn.T.TEST(E999:K999,L999:P999,2,2),"") -> 0.48469161 | S999: =AVERAGE(E999:K999) -> 9.342196 | T999: =AVERAGE(L999:P999) -> 2.5261617
A1000: 1008 | B1000: Geniculate group, dorsal thalamus | C1000: 65000 | D1000: 864 | E1000: ='Absolute counts'!E1000/'Absolute counts'!E$1246*10000 -> 0 | F1000: ='Absolute counts'!F1000/'Absolute counts'!F$1246*10000 -> 0 | G1000: ='Absolute counts'!G1000/'Absolute counts'!G$1246*10000 -> 0 | H1000: ='Absolute counts'!H1000/'Absolute counts'!H$1246*10000 -> 0 | I1000: ='Absolute counts'!I1000/'Absolute counts'!I$1246*10000 -> 0 | J1000: ='Absolute counts'!J1000/'Absolute counts'!J$1246*10000 -> 0 | K1000: ='Absolute counts'!K1000/'Absolute counts'!K$1246*10000 -> 0 | L1000: ='Absolute counts'!L1000/'Absolute counts'!L$1246*10000 -> 0 | ... P1000: ='Absolute counts'!P1000/'Absolute counts'!P$1246*10000 -> 0 | Q1000: =IF(AND(S1000=0,T1000=0),0,1) -> 0 | R1000: =IFERROR(_xlfn.T.TEST(E1000:K1000,L1000:P1000,2,2),"") | S1000: =AVERAGE(E1000:K1000) -> 0 | T1000: =AVERAGE(L1000:P1000) -> 0
A1001: 1009 | B1001: fiber tracts | C1001: 97200 | D1001: 997 | E1001: ='Absolute counts'!E1001/'Absolute counts'!E$1246*10000 -> 207.07591 | F1001: ='Absolute counts'!F1001/'Absolute counts'!F$1246*10000 -> 176.59311 | G1001: ='Absolute counts'!G1001/'Absolute counts'!G$1246*10000 -> 52.000464 | H1001: ='Absolute counts'!H1001/'Absolute counts'!H$1246*10000 -> 145.81459 | I1001: ='Absolute counts'!I1001/'Absolute counts'!I$1246*10000 -> 118.91568 | J1001: ='Absolute counts'!J1001/'Absolute counts'!J$1246*10000 -> 128.97886 | K1001: ='Absolute counts'!K1001/'Absolute counts'!K$1246*10000 -> 83.074241 | L1001: ='Absolute counts'!L1001/'Absolute counts'!L$1246*10000 -> 140.98701 | ... P1001: ='Absolute counts'!P1001/'Absolute counts'!P$1246*10000 -> 74.726713 | Q1001: =IF(AND(S1001=0,T1001=0),0,1) -> 1 | R1001: =IFERROR(_xlfn.T.TEST(E1001:K1001,L1001:P1001,2,2),"") -> 0.49882032 | S1001: =AVERAGE(E1001:K1001) -> 130.35041 | T1001: =AVERAGE(L1001:P1001) -> 110.96796
... A1244: 312782656 | B1244: Unlabeled | C1244: 300 | D1244: 688 | E1244: ='Absolute counts'!E1244/'Absolute counts'!E$1246*10000 -> 6.8095669 | F1244: ='Absolute counts'!F1244/'Absolute counts'!F$1246*10000 -> 8.4404197 | G1244: ='Absolute counts'!G1244/'Absolute counts'!G$1246*10000 -> 15.660854 | H1244: ='Absolute counts'!H1244/'Absolute counts'!H$1246*10000 -> 1.8006511 | I1244: ='Absolute counts'!I1244/'Absolute counts'!I$1246*10000 -> 6.7680602 | J1244: ='Absolute counts'!J1244/'Absolute counts'!J$1246*10000 -> 6.7346212 | K1244: ='Absolute counts'!K1244/'Absolute counts'!K$1246*10000 -> 6.7945435 | L1244: ='Absolute counts'!L1244/'Absolute counts'!L$1246*10000 -> 8.9288414 | ... P1244: ='Absolute counts'!P1244/'Absolute counts'!P$1246*10000 -> 3.0896885 | Q1244: =IF(AND(S1244=0,T1244=0),0,1) -> 1 | R1244: =IFERROR(_xlfn.T.TEST(E1244:K1244,L1244:P1244,2,2),"") -> 0.37279135 | S1244: =AVERAGE(E1244:K1244) -> 7.5726738 | T1244: =AVERAGE(L1244:P1244) -> 5.5794878
E1246: =SUM(E3:E1244) -> 10000 | F1246: =SUM(F3:F1244) -> 10000 | G1246: =SUM(G3:G1244) -> 10000 | H1246: =SUM(H3:H1244) -> 10000 | I1246: =SUM(I3:I1244) -> 10000 | J1246: =SUM(J3:J1244) -> 10000 | K1246: =SUM(K3:K1244) -> 10000 | L1246: =SUM(L3:L1244) -> 10000 | ... P1246: =SUM(P3:P1244) -> 10000

Sheet Total-corrected counts Z<3
E1: 0 | F1: 0 | G1: 0 | H1: 0 | I1: 0 | J1: 0 | K1: 0 | L1: 1 | M1: 1 | N1: 1 | O1: 1 | P1: 1
A2: id | B2: name | C2: structure_order | D2: parent_id | E2: 67898 | F2: 190211 | G2: 191735 | H2: 212741 | I2: 277750 | J2: 340773 | K2: 340805 | L2: 190196 | M2: 190198 | N2: 340770 | O2: 340771 | P2: 343011 | Q2: Filter | R2: Cluster | S2: T-test | T2: Gem 0 | U2: Gem 1
A3: 0 | B3: background | C3: 0 | E3: =IFERROR(IF(OR(HLOOKUP($A3,'Z-scores'!$C$2:$RO$15,3,FALSE)>3,HLOOKUP($A3,'Z-scores'!$C$2:$RO$15,3,FALSE)<-3),"",'Total-corrected counts'!E3),"") | F3: =IFERROR(IF(OR(HLOOKUP($A3,'Z-scores'!$C$2:$RO$15,4,FALSE)>3,HLOOKUP($A3,'Z-scores'!$C$2:$RO$15,4,FALSE)<-3),"",'Total-corrected counts'!F3),"") | G3: =IFERROR(IF(OR(HLOOKUP($A3,'Z-scores'!$C$2:$RO$15,5,FALSE)>3,HLOOKUP($A3,'Z-scores'!$C$2:$RO$15,5,FALSE)<-3),"",'Total-corrected counts'!G3),"") | H3: =IFERROR(IF(OR(HLOOKUP($A3,'Z-scores'!$C$2:$RO$15,6,FALSE)>3,HLOOKUP($A3,'Z-scores'!$C$2:$RO$15,6,FALSE)<-3),"",'Total-corrected counts'!H3),"") | I3: =IFERROR(IF(OR(HLOOKUP($A3,'Z-scores'!$C$2:$RO$15,7,FALSE)>3,HLOOKUP($A3,'Z-scores'!$C$2:$RO$15,7,FALSE)<-3),"",'Total-corrected counts'!I3),"") | J3: =IFERROR(IF(OR(HLOOKUP($A3,'Z-scores'!$C$2:$RO$15,8,FALSE)>3,HLOOKUP($A3,'Z-scores'!$C$2:$RO$15,8,FALSE)<-3),"",'Total-corrected counts'!J3),"") | K3: =IFERROR(IF(OR(HLOOKUP($A3,'Z-scores'!$C$2:$RO$15,9,FALSE)>3,HLOOKUP($A3,'Z-scores'!$C$2:$RO$15,9,FALSE)<-3),"",'Total-corrected counts'!K3),"") | L3: =IFERROR(IF(OR(HLOOKUP($A3,'Z-scores'!$C$2:$RO$15,10,FALSE)>3,HLOOKUP($A3,'Z-scores'!$C$2:$RO$15,10,FALSE)<-3),"",'Total-corrected counts'!L3),"") | M3: =IFERROR(IF(OR(HLOOKUP($A3,'Z-scores'!$C$2:$RO$15,11,FALSE)>3,HLOOKUP($A3,'Z-scores'!$C$2:$RO$15,11,FALSE)<-3),"",'Total-corrected counts'!M3),"") | N3: =IFERROR(IF(OR(HLOOKUP($A3,'Z-scores'!$C$2:$RO$15,12,FALSE)>3,HLOOKUP($A3,'Z-scores'!$C$2:$RO$15,12,FALSE)<-3),"",'Total-corrected counts'!N3),"") | O3: =IFERROR(IF(OR(HLOOKUP($A3,'Z-scores'!$C$2:$RO$15,13,FALSE)>3,HLOOKUP($A3,'Z-scores'!$C$2:$RO$15,13,FALSE)<-3),"",'Total-corrected counts'!O3),"") | P3: =IFERROR(IF(OR(HLOOKUP($A3,'Z-scores'!$C$2:$RO$15,14,FALSE)>3,HLOOKUP($A3,'Z-scores'!$C$2:$RO$15,14,FALSE)<-3),"",'Total-corrected counts'!P3),"") | Q3: =IF(AND(T3=0,U3=0),0,1) -> 1 | R3: =SUMIFS(Tabel132[Cluster],Tabel132[ID],'Total-corrected counts Z<3'!A3) -> 0 | S3: =IFERROR(_xlfn.T.TEST(E3:K3,L3:P3,2,2),"") | T3: =IFERROR(AVERAGE(E3:K3),"") | U3: =IFERROR(AVERAGE(L3:P3),"")
A4: 1 | B4: Tuberomammillary nucleus, ventral part | C4: 75500 | D4: 557 | E4: =IFERROR(IF(OR(HLOOKUP($A4,'Z-scores'!$C$2:$RO$15,3,FALSE)>3,HLOOKUP($A4,'Z-scores'!$C$2:$RO$15,3,FALSE)<-3),"",'Total-corrected counts'!E4),"") -> 0.011620421 | F4: =IFERROR(IF(OR(HLOOKUP($A4,'Z-scores'!$C$2:$RO$15,4,FALSE)>3,HLOOKUP($A4,'Z-scores'!$C$2:$RO$15,4,FALSE)<-3),"",'Total-corrected counts'!F4),"") -> 0.12555996 | G4: =IFERROR(IF(OR(HLOOKUP($A4,'Z-scores'!$C$2:$RO$15,5,FALSE)>3,HLOOKUP($A4,'Z-scores'!$C$2:$RO$15,5,FALSE)<-3),"",'Total-corrected counts'!G4),"") -> 0 | H4: =IFERROR(IF(OR(HLOOKUP($A4,'Z-scores'!$C$2:$RO$15,6,FALSE)>3,HLOOKUP($A4,'Z-scores'!$C$2:$RO$15,6,FALSE)<-3),"",'Total-corrected counts'!H4),"") -> 0.068668899 | I4: =IFERROR(IF(OR(HLOOKUP($A4,'Z-scores'!$C$2:$RO$15,7,FALSE)>3,HLOOKUP($A4,'Z-scores'!$C$2:$RO$15,7,FALSE)<-3),"",'Total-corrected counts'!I4),"") -> 0 | J4: =IFERROR(IF(OR(HLOOKUP($A4,'Z-scores'!$C$2:$RO$15,8,FALSE)>3,HLOOKUP($A4,'Z-scores'!$C$2:$RO$15,8,FALSE)<-3),"",'Total-corrected counts'!J4),"") -> 0 | K4: =IFERROR(IF(OR(HLOOKUP($A4,'Z-scores'!$C$2:$RO$15,9,FALSE)>3,HLOOKUP($A4,'Z-scores'!$C$2:$RO$15,9,FALSE)<-3),"",'Total-corrected counts'!K4),"") -> 0.72041937 | L4: =IFERROR(IF(OR(HLOOKUP($A4,'Z-scores'!$C$2:$RO$15,10,FALSE)>3,HLOOKUP($A4,'Z-scores'!$C$2:$RO$15,10,FALSE)<-3),"",'Total-corrected counts'!L4),"") -> 0 | M4: =IFERROR(IF(OR(HLOOKUP($A4,'Z-scores'!$C$2:$RO$15,11,FALSE)>3,HLOOKUP($A4,'Z-scores'!$C$2:$RO$15,11,FALSE)<-3),"",'Total-corrected counts'!M4),"") -> 0.081776346 | N4: =IFERROR(IF(OR(HLOOKUP($A4,'Z-scores'!$C$2:$RO$15,12,FALSE)>3,HLOOKUP($A4,'Z-scores'!$C$2:$RO$15,12,FALSE)<-3),"",'Total-corrected counts'!N4),"") -> 0 | O4: =IFERROR(IF(OR(HLOOKUP($A4,'Z-scores'!$C$2:$RO$15,13,FALSE)>3,HLOOKUP($A4,'Z-scores'!$C$2:$RO$15,13,FALSE)<-3),"",'Total-corrected counts'!O4),"") -> 0.34703496 | P4: =IFERROR(IF(OR(HLOOKUP($A4,'Z-scores'!$C$2:$RO$15,14,FALSE)>3,HLOOKUP($A4,'Z-scores'!$C$2:$RO$15,14,FALSE)<-3),"",'Total-corrected counts'!P4),"") -> 0 | Q4: =IF(AND(T4=0,U4=0),0,1) -> 1 | R4: =SUMIFS(Tabel132[Cluster],Tabel132[ID],'Total-corrected counts Z<3'!A4) -> 84 | S4: =IFERROR(_xlfn.T.TEST(E4:K4,L4:P4,2,2),"") -> 0.73140141 | T4: =IFERROR(AVERAGE(E4:K4),"") -> 0.13232409 | U4: =IFERROR(AVERAGE(L4:P4),"") -> 0.085762261
A5: 2 | B5: Primary somatosensory area, mouth, layer 6b | C5: 6200 | D5: 345 | E5: =IFERROR(IF(OR(HLOOKUP($A5,'Z-scores'!$C$2:$RO$15,3,FALSE)>3,HLOOKUP($A5,'Z-scores'!$C$2:$RO$15,3,FALSE)<-3),"",'Total-corrected counts'!E5),"") -> 10.086526 | F5: =IFERROR(IF(OR(HLOOKUP($A5,'Z-scores'!$C$2:$RO$15,4,FALSE)>3,HLOOKUP($A5,'Z-scores'!$C$2:$RO$15,4,FALSE)<-3),"",'Total-corrected counts'!F5),"") -> 7.8963265 | G5: =IFERROR(IF(OR(HLOOKUP($A5,'Z-scores'!$C$2:$RO$15,5,FALSE)>3,HLOOKUP($A5,'Z-scores'!$C$2:$RO$15,5,FALSE)<-3),"",'Total-corrected counts'!G5),"") -> 6.2500558 | H5: =IFERROR(IF(OR(HLOOKUP($A5,'Z-scores'!$C$2:$RO$15,6,FALSE)>3,HLOOKUP($A5,'Z-scores'!$C$2:$RO$15,6,FALSE)<-3),"",'Total-corrected counts'!H5),"") -> 9.8120227 | I5: =IFERROR(IF(OR(HLOOKUP($A5,'Z-scores'!$C$2:$RO$15,7,FALSE)>3,HLOOKUP($A5,'Z-scores'!$C$2:$RO$15,7,FALSE)<-3),"",'Total-corrected counts'!I5),"") -> 9.2336559 | J5: =IFERROR(IF(OR(HLOOKUP($A5,'Z-scores'!$C$2:$RO$15,8,FALSE)>3,HLOOKUP($A5,'Z-scores'!$C$2:$RO$15,8,FALSE)<-3),"",'Total-corrected counts'!J5),"") -> 9.7543384 | K5: =IFERROR(IF(OR(HLOOKUP($A5,'Z-scores'!$C$2:$RO$15,9,FALSE)>3,HLOOKUP($A5,'Z-scores'!$C$2:$RO$15,9,FALSE)<-3),"",'Total-corrected counts'!K5),"") -> 12.82629 | L5: =IFERROR(IF(OR(HLOOKUP($A5,'Z-scores'!$C$2:$RO$15,10,FALSE)>3,HLOOKUP($A5,'Z-scores'!$C$2:$RO$15,10,FALSE)<-3),"",'Total-corrected counts'!L5),"") -> 7.5582743 | M5: =IFERROR(IF(OR(HLOOKUP($A5,'Z-scores'!$C$2:$RO$15,11,FALSE)>3,HLOOKUP($A5,'Z-scores'!$C$2:$RO$15,11,FALSE)<-3),"",'Total-corrected counts'!M5),"") -> 9.4042798 | N5: =IFERROR(IF(OR(HLOOKUP($A5,'Z-scores'!$C$2:$RO$15,12,FALSE)>3,HLOOKUP($A5,'Z-scores'!$C$2:$RO$15,12,FALSE)<-3),"",'Total-corrected counts'!N5),"") -> 9.493806 | O5: =IFERROR(IF(OR(HLOOKUP($A5,'Z-scores'!$C$2:$RO$15,13,FALSE)>3,HLOOKUP($A5,'Z-scores'!$C$2:$RO$15,13,FALSE)<-3),"",'Total-corrected counts'!O5),"") -> 16.788989 | P5: =IFERROR(IF(OR(HLOOKUP($A5,'Z-scores'!$C$2:$RO$15,14,FALSE)>3,HLOOKUP($A5,'Z-scores'!$C$2:$RO$15,14,FALSE)<-3),"",'Total-corrected counts'!P5),"") -> 11.101005 | Q5: =IF(AND(T5=0,U5=0),0,1) -> 1 | R5: =SUMIFS(Tabel132[Cluster],Tabel132[ID],'Total-corrected counts Z<3'!A5) -> 8 | S5: =IFERROR(_xlfn.T.TEST(E5:K5,L5:P5,2,2),"") -> 0.38317402 | T5: =IFERROR(AVERAGE(E5:K5),"") -> 9.4084593 | U5: =IFERROR(AVERAGE(L5:P5),"") -> 10.869271
A6: 3 | B6: secondary fissure | C6: 118200 | D6: 1040 | E6: =IFERROR(IF(OR(HLOOKUP($A6,'Z-scores'!$C$2:$RO$15,3,FALSE)>3,HLOOKUP($A6,'Z-scores'!$C$2:$RO$15,3,FALSE)<-3),"",'Total-corrected counts'!E6),"") | F6: =IFERROR(IF(OR(HLOOKUP($A6,'Z-scores'!$C$2:$RO$15,4,FALSE)>3,HLOOKUP($A6,'Z-scores'!$C$2:$RO$15,4,FALSE)<-3),"",'Total-corrected counts'!F6),"") | G6: =IFERROR(IF(OR(HLOOKUP($A6,'Z-scores'!$C$2:$RO$15,5,FALSE)>3,HLOOKUP($A6,'Z-scores'!$C$2:$RO$15,5,FALSE)<-3),"",'Total-corrected counts'!G6),"") | H6: =IFERROR(IF(OR(HLOOKUP($A6,'Z-scores'!$C$2:$RO$15,6,FALSE)>3,HLOOKUP($A6,'Z-scores'!$C$2:$RO$15,6,FALSE)<-3),"",'Total-corrected counts'!H6),"") | I6: =IFERROR(IF(OR(HLOOKUP($A6,'Z-scores'!$C$2:$RO$15,7,FALSE)>3,HLOOKUP($A6,'Z-scores'!$C$2:$RO$15,7,FALSE)<-3),"",'Total-corrected counts'!I6),"") | J6: =IFERROR(IF(OR(HLOOKUP($A6,'Z-scores'!$C$2:$RO$15,8,FALSE)>3,HLOOKUP($A6,'Z-scores'!$C$2:$RO$15,8,FALSE)<-3),"",'Total-corrected counts'!J6),"") | K6: =IFERROR(IF(OR(HLOOKUP($A6,'Z-scores'!$C$2:$RO$15,9,FALSE)>3,HLOOKUP($A6,'Z-scores'!$C$2:$RO$15,9,FALSE)<-3),"",'Total-corrected counts'!K6),"") | L6: =IFERROR(IF(OR(HLOOKUP($A6,'Z-scores'!$C$2:$RO$15,10,FALSE)>3,HLOOKUP($A6,'Z-scores'!$C$2:$RO$15,10,FALSE)<-3),"",'Total-corrected counts'!L6),"") | M6: =IFERROR(IF(OR(HLOOKUP($A6,'Z-scores'!$C$2:$RO$15,11,FALSE)>3,HLOOKUP($A6,'Z-scores'!$C$2:$RO$15,11,FALSE)<-3),"",'Total-corrected counts'!M6),"") | N6: =IFERROR(IF(OR(HLOOKUP($A6,'Z-scores'!$C$2:$RO$15,12,FALSE)>3,HLOOKUP($A6,'Z-scores'!$C$2:$RO$15,12,FALSE)<-3),"",'Total-corrected counts'!N6),"") | O6: =IFERROR(IF(OR(HLOOKUP($A6,'Z-scores'!$C$2:$RO$15,13,FALSE)>3,HLOOKUP($A6,'Z-scores'!$C$2:$RO$15,13,FALSE)<-3),"",'Total-corrected counts'!O6),"") | P6: =IFERROR(IF(OR(HLOOKUP($A6,'Z-scores'!$C$2:$RO$15,14,FALSE)>3,HLOOKUP($A6,'Z-scores'!$C$2:$RO$15,14,FALSE)<-3),"",'Total-corrected counts'!P6),"") | Q6: =IF(AND(T6=0,U6=0),0,1) -> 1 | R6: =SUMIFS(Tabel132[Cluster],Tabel132[ID],'Total-corrected counts Z<3'!A6) -> 0 | S6: =IFERROR(_xlfn.T.TEST(E6:K6,L6:P6,2,2),"") | T6: =IFERROR(AVERAGE(E6:K6),"") | U6: =IFERROR(AVERAGE(L6:P6),"")
A7: 4 | B7: Inferior colliculus | C7: 79100 | D7: 339 | E7: =IFERROR(IF(OR(HLOOKUP($A7,'Z-scores'!$C$2:$RO$15,3,FALSE)>3,HLOOKUP($A7,'Z-scores'!$C$2:$RO$15,3,FALSE)<-3),"",'Total-corrected counts'!E7),"") -> 54.534637 | F7: =IFERROR(IF(OR(HLOOKUP($A7,'Z-scores'!$C$2:$RO$15,4,FALSE)>3,HLOOKUP($A7,'Z-scores'!$C$2:$RO$15,4,FALSE)<-3),"",'Total-corrected counts'!F7),"") -> 32.254959 | G7: =IFERROR(IF(OR(HLOOKUP($A7,'Z-scores'!$C$2:$RO$15,5,FALSE)>3,HLOOKUP($A7,'Z-scores'!$C$2:$RO$15,5,FALSE)<-3),"",'Total-corrected counts'!G7),"") -> 49.375441 | H7: =IFERROR(IF(OR(HLOOKUP($A7,'Z-scores'!$C$2:$RO$15,6,FALSE)>3,HLOOKUP($A7,'Z-scores'!$C$2:$RO$15,6,FALSE)<-3),"",'Total-corrected counts'!H7),"") -> 61.023762 | I7: =IFERROR(IF(OR(HLOOKUP($A7,'Z-scores'!$C$2:$RO$15,7,FALSE)>3,HLOOKUP($A7,'Z-scores'!$C$2:$RO$15,7,FALSE)<-3),"",'Total-corrected counts'!I7),"") -> 0.87528647 | J7: =IFERROR(IF(OR(HLOOKUP($A7,'Z-scores'!$C$2:$RO$15,8,FALSE)>3,HLOOKUP($A7,'Z-scores'!$C$2:$RO$15,8,FALSE)<-3),"",'Total-corrected counts'!J7),"") -> 31.457198 | K7: =IFERROR(IF(OR(HLOOKUP($A7,'Z-scores'!$C$2:$RO$15,9,FALSE)>3,HLOOKUP($A7,'Z-scores'!$C$2:$RO$15,9,FALSE)<-3),"",'Total-corrected counts'!K7),"") -> 158.49226 | L7: =IFERROR(IF(OR(HLOOKUP($A7,'Z-scores'!$C$2:$RO$15,10,FALSE)>3,HLOOKUP($A7,'Z-scores'!$C$2:$RO$15,10,FALSE)<-3),"",'Total-corrected counts'!L7),"") -> 23.259329 | M7: =IFERROR(IF(OR(HLOOKUP($A7,'Z-scores'!$C$2:$RO$15,11,FALSE)>3,HLOOKUP($A7,'Z-scores'!$C$2:$RO$15,11,FALSE)<-3),"",'Total-corrected counts'!M7),"") -> 21.956949 | N7: =IFERROR(IF(OR(HLOOKUP($A7,'Z-scores'!$C$2:$RO$15,12,FALSE)>3,HLOOKUP($A7,'Z-scores'!$C$2:$RO$15,12,FALSE)<-3),"",'Total-corrected counts'!N7),"") -> 8.8364111 | O7: =IFERROR(IF(OR(HLOOKUP($A7,'Z-scores'!$C$2:$RO$15,13,FALSE)>3,HLOOKUP($A7,'Z-scores'!$C$2:$RO$15,13,FALSE)<-3),"",'Total-corrected counts'!O7),"") -> 34.272047 | P7: =IFERROR(IF(OR(HLOOKUP($A7,'Z-scores'!$C$2:$RO$15,14,FALSE)>3,HLOOKUP($A7,'Z-scores'!$C$2:$RO$15,14,FALSE)<-3),"",'Total-corrected counts'!P7),"") -> 133.31231 | Q7: =IF(AND(T7=0,U7=0),0,1) -> 1 | R7: =SUMIFS(Tabel132[Cluster],Tabel132[ID],'Total-corrected counts Z<3'!A7) -> 86 | S7: =IFERROR(_xlfn.T.TEST(E7:K7,L7:P7,2,2),"") -> 0.71244647 | T7: =IFERROR(AVERAGE(E7:K7),"") -> 55.430506 | U7: =IFERROR(AVERAGE(L7:P7),"") -> 44.327409
A8: 6 | B8: internal capsule | C8: 107000 | D8: 784 | E8: =IFERROR(IF(OR(HLOOKUP($A8,'Z-scores'!$C$2:$RO$15,3,FALSE)>3,HLOOKUP($A8,'Z-scores'!$C$2:$RO$15,3,FALSE)<-3),"",'Total-corrected counts'!E8),"") -> 229.15471 | F8: =IFERROR(IF(OR(HLOOKUP($A8,'Z-scores'!$C$2:$RO$15,4,FALSE)>3,HLOOKUP($A8,'Z-scores'!$C$2:$RO$15,4,FALSE)<-3),"",'Total-corrected counts'!F8),"") -> 354.45577 | G8: =IFERROR(IF(OR(HLOOKUP($A8,'Z-scores'!$C$2:$RO$15,5,FALSE)>3,HLOOKUP($A8,'Z-scores'!$C$2:$RO$15,5,FALSE)<-3),"",'Total-corrected counts'!G8),"") -> 123.23324 | H8: =IFERROR(IF(OR(HLOOKUP($A8,'Z-scores'!$C$2:$RO$15,6,FALSE)>3,HLOOKUP($A8,'Z-scores'!$C$2:$RO$15,6,FALSE)<-3),"",'Total-corrected counts'!H8),"") -> 261.7811 | I8: =IFERROR(IF(OR(HLOOKUP($A8,'Z-scores'!$C$2:$RO$15,7,FALSE)>3,HLOOKUP($A8,'Z-scores'!$C$2:$RO$15,7,FALSE)<-3),"",'Total-corrected counts'!I8),"") -> 229.57162 | J8: =IFERROR(IF(OR(HLOOKUP($A8,'Z-scores'!$C$2:$RO$15,8,FALSE)>3,HLOOKUP($A8,'Z-scores'!$C$2:$RO$15,8,FALSE)<-3),"",'Total-corrected counts'!J8),"") -> 259.69568 | K8: =IFERROR(IF(OR(HLOOKUP($A8,'Z-scores'!$C$2:$RO$15,9,FALSE)>3,HLOOKUP($A8,'Z-scores'!$C$2:$RO$15,9,FALSE)<-3),"",'Total-corrected counts'!K8),"") -> 151.04793 | L8: =IFERROR(IF(OR(HLOOKUP($A8,'Z-scores'!$C$2:$RO$15,10,FALSE)>3,HLOOKUP($A8,'Z-scores'!$C$2:$RO$15,10,FALSE)<-3),"",'Total-corrected counts'!L8),"") -> 273.85139 | M8: =IFERROR(IF(OR(HLOOKUP($A8,'Z-scores'!$C$2:$RO$15,11,FALSE)>3,HLOOKUP($A8,'Z-scores'!$C$2:$RO$15,11,FALSE)<-3),"",'Total-corrected counts'!M8),"") -> 201.45603 | N8: =IFERROR(IF(OR(HLOOKUP($A8,'Z-scores'!$C$2:$RO$15,12,FALSE)>3,HLOOKUP($A8,'Z-scores'!$C$2:$RO$15,12,FALSE)<-3),"",'Total-corrected counts'!N8),"") -> 79.604539 | O8: =IFERROR(IF(OR(HLOOKUP($A8,'Z-scores'!$C$2:$RO$15,13,FALSE)>3,HLOOKUP($A8,'Z-scores'!$C$2:$RO$15,13,FALSE)<-3),"",'Total-corrected counts'!O8),"") -> 236.94046 | P8: =IFERROR(IF(OR(HLOOKUP($A8,'Z-scores'!$C$2:$RO$15,14,FALSE)>3,HLOOKUP($A8,'Z-scores'!$C$2:$RO$15,14,FALSE)<-3),"",'Total-corrected counts'!P8),"") -> 111.98526 | Q8: =IF(AND(T8=0,U8=0),0,1) -> 1 | R8: =SUMIFS(Tabel132[Cluster],Tabel132[ID],'Total-corrected counts Z<3'!A8) -> 0 | S8: =IFERROR(_xlfn.T.TEST(E8:K8,L8:P8,2,2),"") -> 0.31295418 | T8: =IFERROR(AVERAGE(E8:K8),"") -> 229.84858 | U8: =IFERROR(AVERAGE(L8:P8),"") -> 180.76754
A9: 7 | B9: Principal sensory nucleus of the trigeminal | C9: 85300 | D9: 1132 | E9: =IFERROR(IF(OR(HLOOKUP($A9,'Z-scores'!$C$2:$RO$15,3,FALSE)>3,HLOOKUP($A9,'Z-scores'!$C$2:$RO$15,3,FALSE)<-3),"",'Total-corrected counts'!E9),"") -> 0.34861264 | F9: =IFERROR(IF(OR(HLOOKUP($A9,'Z-scores'!$C$2:$RO$15,4,FALSE)>3,HLOOKUP($A9,'Z-scores'!$C$2:$RO$15,4,FALSE)<-3),"",'Total-corrected counts'!F9),"") -> 2.1624216 | G9: =IFERROR(IF(OR(HLOOKUP($A9,'Z-scores'!$C$2:$RO$15,5,FALSE)>3,HLOOKUP($A9,'Z-scores'!$C$2:$RO$15,5,FALSE)<-3),"",'Total-corrected counts'!G9),"") -> 1.8214448 | H9: =IFERROR(IF(OR(HLOOKUP($A9,'Z-scores'!$C$2:$RO$15,6,FALSE)>3,HLOOKUP($A9,'Z-scores'!$C$2:$RO$15,6,FALSE)<-3),"",'Total-corrected counts'!H9),"") -> 4.7457839 | I9: =IFERROR(IF(OR(HLOOKUP($A9,'Z-scores'!$C$2:$RO$15,7,FALSE)>3,HLOOKUP($A9,'Z-scores'!$C$2:$RO$15,7,FALSE)<-3),"",'Total-corrected counts'!I9),"") -> 0 | J9: =IFERROR(IF(OR(HLOOKUP($A9,'Z-scores'!$C$2:$RO$15,8,FALSE)>3,HLOOKUP($A9,'Z-scores'!$C$2:$RO$15,8,FALSE)<-3),"",'Total-corrected counts'!J9),"") -> 5.1704511 | K9: =IFERROR(IF(OR(HLOOKUP($A9,'Z-scores'!$C$2:$RO$15,9,FALSE)>3,HLOOKUP($A9,'Z-scores'!$C$2:$RO$15,9,FALSE)<-3),"",'Total-corrected counts'!K9),"") -> 25.723209 | L9: =IFERROR(IF(OR(HLOOKUP($A9,'Z-scores'!$C$2:$RO$15,10,FALSE)>3,HLOOKUP($A9,'Z-scores'!$C$2:$RO$15,10,FALSE)<-3),"",'Total-corrected counts'!L9),"") -> 2.1163168 | M9: =IFERROR(IF(OR(HLOOKUP($A9,'Z-scores'!$C$2:$RO$15,11,FALSE)>3,HLOOKUP($A9,'Z-scores'!$C$2:$RO$15,11,FALSE)<-3),"",'Total-corrected counts'!M9),"") -> 20.239646 | N9: =IFERROR(IF(OR(HLOOKUP($A9,'Z-scores'!$C$2:$RO$15,12,FALSE)>3,HLOOKUP($A9,'Z-scores'!$C$2:$RO$15,12,FALSE)<-3),"",'Total-corrected counts'!N9),"") -> 0.16221431 | O9: =IFERROR(IF(OR(HLOOKUP($A9,'Z-scores'!$C$2:$RO$15,13,FALSE)>3,HLOOKUP($A9,'Z-scores'!$C$2:$RO$15,13,FALSE)<-3),"",'Total-corrected counts'!O9),"") -> 0.17820714 | P9: =IFERROR(IF(OR(HLOOKUP($A9,'Z-scores'!$C$2:$RO$15,14,FALSE)>3,HLOOKUP($A9,'Z-scores'!$C$2:$RO$15,14,FALSE)<-3),"",'Total-corrected counts'!P9),"") -> 14.992736 | Q9: =IF(AND(T9=0,U9=0),0,1) -> 1 | R9: =SUMIFS(Tabel132[Cluster],Tabel132[ID],'Total-corrected counts Z<3'!A9) -> 93 | S9: =IFERROR(_xlfn.T.TEST(E9:K9,L9:P9,2,2),"") -> 0.7413287 | T9: =IFERROR(AVERAGE(E9:K9),"") -> 5.7102748 | U9: =IFERROR(AVERAGE(L9:P9),"") -> 7.537824
A10: 8 | B10: Basic cell groups and regions | C10: 100 | D10: 997 | E10: =IFERROR(IF(OR(HLOOKUP($A10,'Z-scores'!$C$2:$RO$15,3,FALSE)>3,HLOOKUP($A10,'Z-scores'!$C$2:$RO$15,3,FALSE)<-3),"",'Total-corrected counts'!E10),"") | F10: =IFERROR(IF(OR(HLOOKUP($A10,'Z-scores'!$C$2:$RO$15,4,FALSE)>3,HLOOKUP($A10,'Z-scores'!$C$2:$RO$15,4,FALSE)<-3),"",'Total-corrected counts'!F10),"") | G10: =IFERROR(IF(OR(HLOOKUP($A10,'Z-scores'!$C$2:$RO$15,5,FALSE)>3,HLOOKUP($A10,'Z-scores'!$C$2:$RO$15,5,FALSE)<-3),"",'Total-corrected counts'!G10),"") | H10: =IFERROR(IF(OR(HLOOKUP($A10,'Z-scores'!$C$2:$RO$15,6,FALSE)>3,HLOOKUP($A10,'Z-scores'!$C$2:$RO$15,6,FALSE)<-3),"",'Total-corrected counts'!H10),"") | I10: =IFERROR(IF(OR(HLOOKUP($A10,'Z-scores'!$C$2:$RO$15,7,FALSE)>3,HLOOKUP($A10,'Z-scores'!$C$2:$RO$15,7,FALSE)<-3),"",'Total-corrected counts'!I10),"") | J10: =IFERROR(IF(OR(HLOOKUP($A10,'Z-scores'!$C$2:$RO$15,8,FALSE)>3,HLOOKUP($A10,'Z-scores'!$C$2:$RO$15,8,FALSE)<-3),"",'Total-corrected counts'!J10),"") | K10: =IFERROR(IF(OR(HLOOKUP($A10,'Z-scores'!$C$2:$RO$15,9,FALSE)>3,HLOOKUP($A10,'Z-scores'!$C$2:$RO$15,9,FALSE)<-3),"",'Total-corrected counts'!K10),"") | L10: =IFERROR(IF(OR(HLOOKUP($A10,'Z-scores'!$C$2:$RO$15,10,FALSE)>3,HLOOKUP($A10,'Z-scores'!$C$2:$RO$15,10,FALSE)<-3),"",'Total-corrected counts'!L10),"") | M10: =IFERROR(IF(OR(HLOOKUP($A10,'Z-scores'!$C$2:$RO$15,11,FALSE)>3,HLOOKUP($A10,'Z-scores'!$C$2:$RO$15,11,FALSE)<-3),"",'Total-corrected counts'!M10),"") | N10: =IFERROR(IF(OR(HLOOKUP($A10,'Z-scores'!$C$2:$RO$15,12,FALSE)>3,HLOOKUP($A10,'Z-scores'!$C$2:$RO$15,12,FALSE)<-3),"",'Total-corrected counts'!N10),"") | O10: =IFERROR(IF(OR(HLOOKUP($A10,'Z-scores'!$C$2:$RO$15,13,FALSE)>3,HLOOKUP($A10,'Z-scores'!$C$2:$RO$15,13,FALSE)<-3),"",'Total-corrected counts'!O10),"") | P10: =IFERROR(IF(OR(HLOOKUP($A10,'Z-scores'!$C$2:$RO$15,14,FALSE)>3,HLOOKUP($A10,'Z-scores'!$C$2:$RO$15,14,FALSE)<-3),"",'Total-corrected counts'!P10),"") | Q10: =IF(AND(T10=0,U10=0),0,1) -> 1 | R10: =SUMIFS(Tabel132[Cluster],Tabel132[ID],'Total-corrected counts Z<3'!A10) -> 0 | S10: =IFERROR(_xlfn.T.TEST(E10:K10,L10:P10,2,2),"") | T10: =IFERROR(AVERAGE(E10:K10),"") | U10: =IFERROR(AVERAGE(L10:P10),"")
A11: 9 | B11: Primary somatosensory area, trunk, layer 6a | C11: 7500 | D11: 361 | E11: =IFERROR(IF(OR(HLOOKUP($A11,'Z-scores'!$C$2:$RO$15,3,FALSE)>3,HLOOKUP($A11,'Z-scores'!$C$2:$RO$15,3,FALSE)<-3),"",'Total-corrected counts'!E11),"") -> 10.714028 | F11: =IFERROR(IF(OR(HLOOKUP($A11,'Z-scores'!$C$2:$RO$15,4,FALSE)>3,HLOOKUP($A11,'Z-scores'!$C$2:$RO$15,4,FALSE)<-3),"",'Total-corrected counts'!F11),"") -> 2.6228081 | G11: =IFERROR(IF(OR(HLOOKUP($A11,'Z-scores'!$C$2:$RO$15,5,FALSE)>3,HLOOKUP($A11,'Z-scores'!$C$2:$RO$15,5,FALSE)<-3),"",'Total-corrected counts'!G11),"") -> 2.6964526 | H11: =IFERROR(IF(OR(HLOOKUP($A11,'Z-scores'!$C$2:$RO$15,6,FALSE)>3,HLOOKUP($A11,'Z-scores'!$C$2:$RO$15,6,FALSE)<-3),"",'Total-corrected counts'!H11),"") -> 3.3418864 | I11: =IFERROR(IF(OR(HLOOKUP($A11,'Z-scores'!$C$2:$RO$15,7,FALSE)>3,HLOOKUP($A11,'Z-scores'!$C$2:$RO$15,7,FALSE)<-3),"",'Total-corrected counts'!I11),"") -> 2.9710428 | J11: =IFERROR(IF(OR(HLOOKUP($A11,'Z-scores'!$C$2:$RO$15,8,FALSE)>3,HLOOKUP($A11,'Z-scores'!$C$2:$RO$15,8,FALSE)<-3),"",'Total-corrected counts'!J11),"") -> 16.402061 | K11: =IFERROR(IF(OR(HLOOKUP($A11,'Z-scores'!$C$2:$RO$15,9,FALSE)>3,HLOOKUP($A11,'Z-scores'!$C$2:$RO$15,9,FALSE)<-3),"",'Total-corrected counts'!K11),"") -> 7.3454524 | L11: =IFERROR(IF(OR(HLOOKUP($A11,'Z-scores'!$C$2:$RO$15,10,FALSE)>3,HLOOKUP($A11,'Z-scores'!$C$2:$RO$15,10,FALSE)<-3),"",'Total-corrected counts'!L11),"") -> 3.1039313 | M11: =IFERROR(IF(OR(HLOOKUP($A11,'Z-scores'!$C$2:$RO$15,11,FALSE)>3,HLOOKUP($A11,'Z-scores'!$C$2:$RO$15,11,FALSE)<-3),"",'Total-corrected counts'!M11),"") -> 11.326024 | N11: =IFERROR(IF(OR(HLOOKUP($A11,'Z-scores'!$C$2:$RO$15,12,FALSE)>3,HLOOKUP($A11,'Z-scores'!$C$2:$RO$15,12,FALSE)<-3),"",'Total-corrected counts'!N11),"") -> 9.5194188 | O11: =IFERROR(IF(OR(HLOOKUP($A11,'Z-scores'!$C$2:$RO$15,13,FALSE)>3,HLOOKUP($A11,'Z-scores'!$C$2:$RO$15,13,FALSE)<-3),"",'Total-corrected counts'!O11),"") -> 5.3649729 | P11: =IFERROR(IF(OR(HLOOKUP($A11,'Z-scores'!$C$2:$RO$15,14,FALSE)>3,HLOOKUP($A11,'Z-scores'!$C$2:$RO$15,14,FALSE)<-3),"",'Total-corrected counts'!P11),"") -> 6.4801431 | Q11: =IF(AND(T11=0,U11=0),0,1) -> 1 | R11: =SUMIFS(Tabel132[Cluster],Tabel132[ID],'Total-corrected counts Z<3'!A11) -> 10 | S11: =IFERROR(_xlfn.T.TEST(E11:K11,L11:P11,2,2),"") -> 0.835449 | T11: =IFERROR(AVERAGE(E11:K11),"") -> 6.5848189 | U11: =IFERROR(AVERAGE(L11:P11),"") -> 7.158898
