Workbook

Sheet Raw counts
E1: 0 | F1: 0 | G1: 0 | H1: 0 | I1: 0 | J1: 0 | K1: 0 | L1: 0 | M1: 0 | N1: 0 | O1: 1 | P1: 1 | Q1: 1 | R1: 1 | S1: 1 | T1: 1
A2: id | B2: name | C2: structure_order | D2: parent_id | E2: 345391 | F2: 348028 | G2: 348030 | H2: 348035 | I2: 348465 | J2: 349038 | K2: 349438 | L2: 354044 | M2: 354519 | N2: 354522 | O2: 348034 | P2: 349022 | Q2: 349440 | R2: 350322 | S2: 350324 | T2: 354043 | U2: Filter | V2: Cluster | W2: T-test | X2: Gem 0 | Y2: Gem 1
A3: 0 | B3: background | C3: 0 | E3: 409976 | F3: 335651 | G3: 251576 | H3: 349440 | I3: 372074 | J3: 363773 | K3: 315889 | L3: 303738 | M3: 234665 | N3: 247709 | O3: 363766 | P3: 525215 | Q3: 350378 | R3: 285271 | S3: 318028 | T3: 355637 | U3: =IF(AND(X3=0,Y3=0),0,1) -> 1 | V3: =SUMIFS(Tabel132[Cluster],Tabel132[ID],A3) -> 0 | W3: =IFERROR(_xlfn.T.TEST(E3:N3,O3:T3,2,2),"") -> 0.19722229 | X3: =AVERAGE(E3:N3) -> 318449.1 | Y3: =AVERAGE(O3:T3) -> 366382.5
A4: 1 | B4: Tuberomammillary nucleus, ventral part | C4: 75500 | D4: 557 | E4: 19 | F4: 1 | G4: 19 | H4: 46 | I4: 51 | J4: 0 | K4: 1 | L4: 14 | M4: 0 | N4: 89 | O4: 360 | P4: 4 | Q4: 7 | R4: 27 | S4: 47 | T4: 0 | U4: =IF(AND(X4=0,Y4=0),0,1) -> 1 | V4: =SUMIFS(Tabel132[Cluster],Tabel132[ID],A4) -> 84 | W4: =IFERROR(_xlfn.T.TEST(E4:N4,O4:T4,2,2),"") -> 0.28604589 | X4: =AVERAGE(E4:N4) -> 24 | Y4: =AVERAGE(O4:T4) -> 74.166667
A5: 2 | B5: Primary somatosensory area, mouth, layer 6b | C5: 6200 | D5: 345 | E5: 643 | F5: 613 | G5: 937 | H5: 618 | I5: 780 | J5: 1663 | K5: 469 | L5: 589 | M5: 557 | N5: 636 | O5: 551 | P5: 680 | Q5: 738 | R5: 612 | S5: 694 | T5: 320 | U5: =IF(AND(X5=0,Y5=0),0,1) -> 1 | V5: =SUMIFS(Tabel132[Cluster],Tabel132[ID],A5) -> 8 | W5: =IFERROR(_xlfn.T.TEST(E5:N5,O5:T5,2,2),"") -> 0.33136571 | X5: =AVERAGE(E5:N5) -> 750.5 | Y5: =AVERAGE(O5:T5) -> 599.16667
A6: 3 | B6: secondary fissure | C6: 118200 | D6: 1040 | E6: 0 | F6: 0 | G6: 0 | H6: 0 | I6: 0 | J6: 0 | K6: 0 | L6: 0 | M6: 0 | N6: 0 | O6: 0 | P6: 0 | Q6: 0 | R6: 0 | S6: 0 | T6: 0 | U6: =IF(AND(X6=0,Y6=0),0,1) -> 0 | V6: =SUMIFS(Tabel132[Cluster],Tabel132[ID],A6) -> 0 | W6: =IFERROR(_xlfn.T.TEST(E6:N6,O6:T6,2,2),"") | X6: =AVERAGE(E6:N6) -> 0 | Y6: =AVERAGE(O6:T6) -> 0
A7: 4 | B7: Inferior colliculus | C7: 79100 | D7: 339 | E7: 10234 | F7: 24062 | G7: 11035 | H7: 6232 | I7: 7301 | J7: 17416 | K7: 9290 | L7: 15429 | M7: 7409 | N7: 11101 | O7: 20742 | P7: 25984 | Q7: 18856 | R7: 26916 | S7: 18871 | T7: 4678 | U7: =IF(AND(X7=0,Y7=0),0,1) -> 1 | V7: =SUMIFS(Tabel132[Cluster],Tabel132[ID],A7) -> 86 | W7: =IFERROR(_xlfn.T.TEST(E7:N7,O7:T7,2,2),"") -> 0.045366564 | X7: =AVERAGE(E7:N7) -> 11950.9 | Y7: =AVERAGE(O7:T7) -> 19341.167
A8: 6 | B8: internal capsule | C8: 107000 | D8: 784 | E8: 24387 | F8: 24092 | G8: 29631 | H8: 21120 | I8: 17399 | J8: 15541 | K8: 16818 | L8: 16337 | M8: 15595 | N8: 21078 | O8: 19550 | P8: 22803 | Q8: 23398 | R8: 19948 | S8: 19063 | T8: 18508 | U8: =IF(AND(X8=0,Y8=0),0,1) -> 1 | V8: =SUMIFS(Tabel132[Cluster],Tabel132[ID],A8) -> 0 | W8: =IFERROR(_xlfn.T.TEST(E8:N8,O8:T8,2,2),"") -> 0.86887801 | X8: =AVERAGE(E8:N8) -> 20199.8 | Y8: =AVERAGE(O8:T8) -> 20545
A9: 7 | B9: Principal sensory nucleus of the trigeminal | C9: 85300 | D9: 1132 | E9: 1588 | F9: 5745 | G9: 2043 | H9: 218 | I9: 718 | J9: 1064 | K9: 156 | L9: 4558 | M9: 2932 | N9: 1075 | O9: 6120 | P9: 710 | Q9: 1964 | R9: 4570 | S9: 5464 | T9: 58 | U9: =IF(AND(X9=0,Y9=0),0,1) -> 1 | V9: =SUMIFS(Tabel132[Cluster],Tabel132[ID],A9) -> 93 | W9: =IFERROR(_xlfn.T.TEST(E9:N9,O9:T9,2,2),"") -> 0.32260944 | X9: =AVERAGE(E9:N9) -> 2009.7 | Y9: =AVERAGE(O9:T9) -> 3147.6667
A10: 8 | B10: Basic cell groups and regions | C10: 100 | D10: 997 | E10: 0 | F10: 0 | G10: 0 | H10: 0 | I10: 0 | J10: 0 | K10: 0 | L10: 0 | M10: 0 | N10: 0 | O10: 0 | P10: 0 | Q10: 0 | R10: 0 | S10: 0 | T10: 0 | U10: =IF(AND(X10=0,Y10=0),0,1) -> 0 | V10: =SUMIFS(Tabel132[Cluster],Tabel132[ID],A10) -> 0 | W10: =IFERROR(_xlfn.T.TEST(E10:N10,O10:T10,2,2),"") | X10: =AVERAGE(E10:N10) -> 0 | Y10: =AVERAGE(O10:T10) -> 0
A11: 9 | B11: Primary somatosensory area, trunk, layer 6a | C11: 7500 | D11: 361 | E11: 732 | F11: 1224 | G11: 2250 | H11: 200 | I11: 1087 | J11: 179 | K11: 711 | L11: 607 | M11: 1045 | N11: 460 | O11: 822 | P11: 1375 | Q11: 867 | R11: 1031 | S11: 1196 | T11: 393 | U11: =IF(AND(X11=0,Y11=0),0,1) -> 1 | V11: =SUMIFS(Tabel132[Cluster],Tabel132[ID],A11) -> 10 | W11: =IFERROR(_xlfn.T.TEST(E11:N11,O11:T11,2,2),"") -> 0.72473121 | X11: =AVERAGE(E11:N11) -> 849.5 | Y11: =AVERAGE(O11:T11) -> 947.33333
A12: 10 | B12: Superior colliculus, motor related, intermediate gray layer | C12: 81100 | D12: 294 | E12: 7362 | F12: 7856 | G12: 8732 | H12: 3835 | I12: 4745 | J12: 3761 | K12: 3199 | L12: 6627 | M12: 4127 | N12: 5817 | O12: 11715 | P12: 7423 | Q12: 12650 | R12: 4499 | S12: 4611 | T12: 4121 | U12: =IF(AND(X12=0,Y12=0),0,1) -> 1 | V12: =SUMIFS(Tabel132[Cluster],Tabel132[ID],A12) -> 89 | W12: =IFERROR(_xlfn.T.TEST(E12:N12,O12:T12,2,2),"") -> 0.20581846 | X12: =AVERAGE(E12:N12) -> 5606.1 | Y12: =AVERAGE(O12:T12) -> 7503.1667
A13: 11 | B13: posterolateral fissure | C13: 118300 | D13: 1040 | E13: 0 | F13: 0 | G13: 0 | H13: 0 | I13: 0 | J13: 0 | K13: 0 | L13: 0 | M13: 0 | N13: 0 | O13: 0 | P13: 0 | Q13: 0 | R13: 0 | S13: 0 | T13: 0 | U13: =IF(AND(X13=0,Y13=0),0,1) -> 0 | V13: =SUMIFS(Tabel132[Cluster],Tabel132[ID],A13) -> 0 | W13: =IFERROR(_xlfn.T.TEST(E13:N13,O13:T13,2,2),"") | X13: =AVERAGE(E13:N13) -> 0 | Y13: =AVERAGE(O13:T13) -> 0
A14: 12 | B14: Interfascicular nucleus raphÈ | C14: 84100 | D14: 165 | E14: 0 | F14: 0 | G14: 0 | H14: 0 | I14: 0 | J14: 0 | K14: 0 | L14: 0 | M14: 0 | N14: 0 | O14: 0 | P14: 0 | Q14: 0 | R14: 0 | S14: 0 | T14: 0 | U14: =IF(AND(X14=0,Y14=0),0,1) -> 0 | V14: =SUMIFS(Tabel132[Cluster],Tabel132[ID],A14) -> 92 | W14: =IFERROR(_xlfn.T.TEST(E14:N14,O14:T14,2,2),"") | X14: =AVERAGE(E14:N14) -> 0 | Y14: =AVERAGE(O14:T14) -> 0
A15: 14 | B15: internal medullary lamina of the thalamus | C15: 108200 | D15: 896 | E15: 11 | F15: 11 | G15: 6 | H15: 6 | I15: 1 | J15: 10 | K15: 12 | L15: 6 | M15: 1 | N15: 8 | O15: 11 | P15: 6 | Q15: 7 | R15: 5 | S15: 9 | T15: 0 | U15: =IF(AND(X15=0,Y15=0),0,1) -> 1 | V15: =SUMIFS(Tabel132[Cluster],Tabel132[ID],A15) -> 0 | W15: =IFERROR(_xlfn.T.TEST(E15:N15,O15:T15,2,2),"") -> 0.67350048 | X15: =AVERAGE(E15:N15) -> 7.2 | Y15: =AVERAGE(O15:T15) -> 6.3333333
... A988: 996 | B988: Agranular insular area, dorsal part, layer 1 | C988: 23500 | D988: 104 | E988: 1563 | F988: 1738 | G988: 878 | H988: 1386 | I988: 2252 | J988: 1244 | K988: 2757 | L988: 1118 | M988: 1038 | N988: 767 | O988: 983 | P988: 1156 | Q988: 1947 | R988: 1053 | S988: 2019 | T988: 5877 | U988: =IF(AND(X988=0,Y988=0),0,1) -> 1 | V988: =SUMIFS(Tabel132[Cluster],Tabel132[ID],A988) -> 30 | W988: =IFERROR(_xlfn.T.TEST(E988:N988,O988:T988,2,2),"") -> 0.28876357 | X988: =AVERAGE(E988:N988) -> 1474.1 | Y988: =AVERAGE(O988:T988) -> 2172.5
A989: 997 | B989: root | C989: 0 | E989: 2 | F989: 3 | G989: 3 | H989: 1 | I989: 0 | J989: 1 | K989: 5 | L989: 0 | M989: 0 | N989: 0 | O989: 2 | P989: 4 | Q989: 3 | R989: 1 | S989: 8 | T989: 7 | U989: =IF(AND(X989=0,Y989=0),0,1) -> 1 | V989: =SUMIFS(Tabel132[Cluster],Tabel132[ID],A989) -> 0 | W989: =IFERROR(_xlfn.T.TEST(E989:N989,O989:T989,2,2),"") -> 0.031438048 | X989: =AVERAGE(E989:N989) -> 1.5 | Y989: =AVERAGE(O989:T989) -> 4.1666667
A990: 998 | B990: Fundus of striatum | C990: 48500 | D990: 493 | E990: 2673 | F990: 2128 | G990: 1711 | H990: 2658 | I990: 2323 | J990: 1350 | K990: 2010 | L990: 1270 | M990: 905 | N990: 859 | O990: 2204 | P990: 2077 | Q990: 2683 | R990: 2008 | S990: 1340 | T990: 1254 | U990: =IF(AND(X990=0,Y990=0),0,1) -> 1 | V990: =SUMIFS(Tabel132[Cluster],Tabel132[ID],A990) -> 64 | W990: =IFERROR(_xlfn.T.TEST(E990:N990,O990:T990,2,2),"") -> 0.67626123 | X990: =AVERAGE(E990:N990) -> 1788.7 | Y990: =AVERAGE(O990:T990) -> 1927.6667
A991: 999 | B991: Entorhinal area, lateral part, layer 2/3 | C991: 41600 | D991: 918 | E991: 0 | F991: 0 | G991: 0 | H991: 0 | I991: 0 | J991: 0 | K991: 0 | L991: 0 | M991: 0 | N991: 0 | O991: 0 | P991: 0 | Q991: 0 | R991: 0 | S991: 0 | T991: 0 | U991: =IF(AND(X991=0,Y991=0),0,1) -> 0 | V991: =SUMIFS(Tabel132[Cluster],Tabel132[ID],A991) -> 54 | W991: =IFERROR(_xlfn.T.TEST(E991:N991,O991:T991,2,2),"") | X991: =AVERAGE(E991:N991) -> 0 | Y991: =AVERAGE(O991:T991) -> 0
A992: 1000 | B992: extrapyramidal fiber systems | C992: 108500 | D992: 1009 | E992: 0 | F992: 0 | G992: 0 | H992: 0 | I992: 0 | J992: 0 | K992: 0 | L992: 0 | M992: 0 | N992: 0 | O992: 0 | P992: 0 | Q992: 0 | R992: 0 | S992: 0 | T992: 0 | U992: =IF(AND(X992=0,Y992=0),0,1) -> 0 | V992: =SUMIFS(Tabel132[Cluster],Tabel132[ID],A992) -> 0 | W992: =IFERROR(_xlfn.T.TEST(E992:N992,O992:T992,2,2),"") | X992: =AVERAGE(E992:N992) -> 0 | Y992: =AVERAGE(O992:T992) -> 0
A993: 1001 | B993: Lobule V | C993: 56800 | D993: 928 | E993: 0 | F993: 0 | G993: 0 | H993: 0 | I993: 0 | J993: 0 | K993: 0 | L993: 0 | M993: 0 | N993: 0 | O993: 0 | P993: 0 | Q993: 0 | R993: 0 | S993: 0 | T993: 0 | U993: =IF(AND(X993=0,Y993=0),0,1) -> 0 | V993: =SUMIFS(Tabel132[Cluster],Tabel132[ID],A993) -> 0 | W993: =IFERROR(_xlfn.T.TEST(E993:N993,O993:T993,2,2),"") | X993: =AVERAGE(E993:N993) -> 0 | Y993: =AVERAGE(O993:T993) -> 0
A994: 1002 | B994: Primary auditory area | C994: 11300 | D994: 247 | E994: 0 | F994: 0 | G994: 0 | H994: 0 | I994: 0 | J994: 0 | K994: 0 | L994: 0 | M994: 0 | N994: 0 | O994: 0 | P994: 0 | Q994: 0 | R994: 0 | S994: 0 | T994: 0 | U994: =IF(AND(X994=0,Y994=0),0,1) -> 0 | V994: =SUMIFS(Tabel132[Cluster],Tabel132[ID],A994) -> 15 | W994: =IFERROR(_xlfn.T.TEST(E994:N994,O994:T994,2,2),"") | X994: =AVERAGE(E994:N994) -> 0 | Y994: =AVERAGE(O994:T994) -> 0
A995: 1003 | B995: corticopontine tract | C995: 107400 | D995: 784 | E995: 0 | F995: 0 | G995: 0 | H995: 0 | I995: 0 | J995: 0 | K995: 0 | L995: 0 | M995: 0 | N995: 0 | O995: 0 | P995: 0 | Q995: 0 | R995: 0 | S995: 0 | T995: 0 | U995: =IF(AND(X995=0,Y995=0),0,1) -> 0 | V995: =SUMIFS(Tabel132[Cluster],Tabel132[ID],A995) -> 0 | W995: =IFERROR(_xlfn.T.TEST(E995:N995,O995:T995,2,2),"") | X995: =AVERAGE(E995:N995) -> 0 | Y995: =AVERAGE(O995:T995) -> 0
A996: 1004 | B996: Ventral premammillary nucleus | C996: 76100 | D996: 467 | E996: 61 | F996: 18 | G996: 56 | H996: 1 | I996: 406 | J996: 5 | K996: 0 | L996: 74 | M996: 1 | N996: 12 | O996: 385 | P996: 0 | Q996: 33 | R996: 80 | S996: 86 | T996: 0 | U996: =IF(AND(X996=0,Y996=0),0,1) -> 1 | V996: =SUMIFS(Tabel132[Cluster],Tabel132[ID],A996) -> 84 | W996: =IFERROR(_xlfn.T.TEST(E996:N996,O996:T996,2,2),"") -> 0.62620175 | X996: =AVERAGE(E996:N996) -> 63.4 | Y996: =AVERAGE(O996:T996) -> 97.333333
A997: 1005 | B997: Primary auditory area, layer 6b | C997: 11900 | D997: 1002 | E997: 489 | F997: 682 | G997: 421 | H997: 242 | I997: 56 | J997: 546 | K997: 351 | L997: 141 | M997: 452 | N997: 140 | O997: 511 | P997: 222 | Q997: 973 | R997: 718 | S997: 531 | T997: 365 | U997: =IF(AND(X997=0,Y997=0),0,1) -> 1 | V997: =SUMIFS(Tabel132[Cluster],Tabel132[ID],A997) -> 15 | W997: =IFERROR(_xlfn.T.TEST(E997:N997,O997:T997,2,2),"") -> 0.10760298 | X997: =AVERAGE(E997:N997) -> 352 | Y997: =AVERAGE(O997:T997) -> 553.33333
A998: 1006 | B998: Primary somatosensory area, trunk, layer 1 | C998: 7100 | D998: 361 | E998: 973 | F998: 478 | G998: 106 | H998: 255 | I998: 803 | J998: 567 | K998: 1060 | L998: 368 | M998: 662 | N998: 89 | O998: 303 | P998: 93 | Q998: 268 | R998: 46 | S998: 1326 | T998: 665 | U998: =IF(AND(X998=0,Y998=0),0,1) -> 1 | V998: =SUMIFS(Tabel132[Cluster],Tabel132[ID],A998) -> 10 | W998: =IFERROR(_xlfn.T.TEST(E998:N998,O998:T998,2,2),"") -> 0.68154964 | X998: =AVERAGE(E998:N998) -> 536.1 | Y998: =AVERAGE(O998:T998) -> 450.16667
A999: 1007 | B999: Simple lobule | C999: 59700 | D999: 1073 | E999: 1446 | F999: 541 | G999: 24 | H999: 526 | I999: 131 | J999: 2738 | K999: 53 | L999: 2861 | M999: 925 | N999: 1305 | O999: 1901 | P999: 563 | Q999: 165 | R999: 658 | S999: 677 | T999: 0 | U999: =IF(AND(X999=0,Y999=0),0,1) -> 1 | V999: =SUMIFS(Tabel132[Cluster],Tabel132[ID],A999) -> 0 | W999: =IFERROR(_xlfn.T.TEST(E999:N999,O999:T999,2,2),"") -> 0.42371922 | X999: =AVERAGE(E999:N999) -> 1055 | Y999: =AVERAGE(O999:T999) -> 660.66667
A1000: 1008 | B1000: Geniculate group, dorsal thalamus | C1000: 65000 | D1000: 864 | E1000: 0 | F1000: 0 | G1000: 0 | H1000: 0 | I1000: 0 | J1000: 0 | K1000: 0 | L1000: 0 | M1000: 0 | N1000: 0 | O1000: 0 | P1000: 0 | Q1000: 0 | R1000: 0 | S1000: 0 | T1000: 0 | U1000: =IF(AND(X1000=0,Y1000=0),0,1) -> 0 | V1000: =SUMIFS(Tabel132[Cluster],Tabel132[ID],A1000) -> 77 | W1000: =IFERROR(_xlfn.T.TEST(E1000:N1000,O1000:T1000,2,2),"") | X1000: =AVERAGE(E1000:N1000) -> 0 | Y1000: =AVERAGE(O1000:T1000) -> 0
A1001: 1009 | B1001: fiber tracts | C1001: 97200 | D1001: 997 | E1001: 11313 | F1001: 11645 | G1001: 12892 | H1001: 6833 | I1001: 11656 | J1001: 12226 | K1001: 7162 | L1001: 6697 | M1001: 5620 | N1001: 7895 | O1001: 8727 | P1001: 9419 | Q1001: 9411 | R1001: 6192 | S1001: 7909 | T1001: 7081 | U1001: =IF(AND(X1001=0,Y1001=0),0,1) -> 1 | V1001: =SUMIFS(Tabel132[Cluster],Tabel132[ID],A1001) -> 0 | W1001: =IFERROR(_xlfn.T.TEST(E1001:N1001,O1001:T1001,2,2),"") -> 0.31480884 | X1001: =AVERAGE(E1001:N1001) -> 9393.9 | Y1001: =AVERAGE(O1001:T1001) -> 8123.1667
... A1244: 312782656 | B1244: Unlabeled | C1244: 300 | D1244: 688 | E1244: 2592 | F1244: 1411 | G1244: 1238 | H1244: 912 | I1244: 1099 | J1244: 1712 | K1244: 1406 | L1244: 925 | M1244: 978 | N1244: 913 | O1244: 1522 | P1244: 1482 | Q1244: 810 | R1244: 1457 | S1244: 1336 | T1244: 1366 | U1244: =IF(AND(X1244=0,Y1244=0),0,1) -> 1 | V1244: =SUMIFS(Tabel132[Cluster],Tabel132[ID],A1244) -> 0 | W1244: =IFERROR(_xlfn.T.TEST(E1244:N1244,O1244:T1244,2,2),"") -> 0.96525574 | X1244: =AVERAGE(E1244:N1244) -> 1318.6 | Y1244: =AVERAGE(O1244:T1244) -> 1328.8333
E1246: =SUM(E3:E1244) -> 2018495 | F1246: =SUM(F3:F1244) -> 2117853 | G1246: =SUM(G3:G1244) -> 2016571 | H1246: =SUM(H3:H1244) -> 1657960 | I1246: =SUM(I3:I1244) -> 1777031 | J1246: =SUM(J3:J1244) -> 1670406 | K1246: =SUM(K3:K1244) -> 1705155 | L1246: =SUM(L3:L1244) -> 1474158 | ... T1246: =SUM(T3:T1244) -> 1464993

Sheet Total-corrected counts
E1: 0 | F1: 0 | G1: 0 | H1: 0 | I1: 0 | J1: 0 | K1: 0 | L1: 0 | M1: 0 | N1: 0 | O1: 1 | P1: 1 | Q1: 1 | R1: 1 | S1: 1 | T1: 1
A2: id | B2: name | C2: structure_order | D2: parent_id | E2: 345391 | F2: 348028 | G2: 348030 | H2: 348035 | I2: 348465 | J2: 349038 | K2: 349438 | L2: 354044 | M2: 354519 | N2: 354522 | O2: 348034 | P2: 349022 | Q2: 349440 | R2: 350322 | S2: 350324 | T2: 354043 | U2: Filter | V2: T-test | W2: Gem 0 | X2: Gem 1
A3: 0 | B3: background | C3: 0 | E3: ='Raw counts'!E3/'Raw counts'!E$1246*10000 -> 2031.0974 | F3: ='Raw counts'!F3/'Raw counts'!F$1246*10000 -> 1584.8645 | G3: ='Raw counts'!G3/'Raw counts'!G$1246*10000 -> 1247.5435 | H3: ='Raw counts'!H3/'Raw counts'!H$1246*10000 -> 2107.6504 | I3: ='Raw counts'!I3/'Raw counts'!I$1246*10000 -> 2093.7958 | J3: ='Raw counts'!J3/'Raw counts'!J$1246*10000 -> 2177.752 | K3: ='Raw counts'!K3/'Raw counts'!K$1246*10000 -> 1852.553 | L3: ='Raw counts'!L3/'Raw counts'!L$1246*10000 -> 2060.4169 | ... T3: ='Raw counts'!T3/'Raw counts'!T$1246*10000 -> 2427.5679 | U3: =IFERROR(IF(W3-X3=0,0,1),0) -> 1 | V3: =IFERROR(_xlfn.T.TEST(E3:N3,O3:T3,2,2),"") -> 0.86264014 | W3: =AVERAGE(E3:N3) -> 1909.8094 | X3: =AVERAGE(O3:T3) -> 1942.6681
A4: 1 | B4: Tuberomammillary nucleus, ventral part | C4: 75500 | D4: 557 | E4: ='Raw counts'!E4/'Raw counts'!E$1246*10000 -> 0.094129537 | F4: ='Raw counts'!F4/'Raw counts'!F$1246*10000 -> 0.004721763 | G4: ='Raw counts'!G4/'Raw counts'!G$1246*10000 -> 0.094219346 | H4: ='Raw counts'!H4/'Raw counts'!H$1246*10000 -> 0.2774494 | I4: ='Raw counts'!I4/'Raw counts'!I$1246*10000 -> 0.28699556 | J4: ='Raw counts'!J4/'Raw counts'!J$1246*10000 -> 0 | K4: ='Raw counts'!K4/'Raw counts'!K$1246*10000 -> 0.0058645695 | L4: ='Raw counts'!L4/'Raw counts'!L$1246*10000 -> 0.094969467 | ... T4: ='Raw counts'!T4/'Raw counts'!T$1246*10000 -> 0 | U4: =IFERROR(IF(W4-X4=0,0,1),0) -> 1 | V4: =IFERROR(_xlfn.T.TEST(E4:N4,O4:T4,2,2),"") -> 0.3940355 | W4: =AVERAGE(E4:N4) -> 0.15560802 | X4: =AVERAGE(O4:T4) -> 0.34183668
A5: 2 | B5: Primary somatosensory area, mouth, layer 6b | C5: 6200 | D5: 345 | E5: ='Raw counts'!E5/'Raw counts'!E$1246*10000 -> 3.1855417 | F5: ='Raw counts'!F5/'Raw counts'!F$1246*10000 -> 2.8944407 | G5: ='Raw counts'!G5/'Raw counts'!G$1246*10000 -> 4.6465014 | H5: ='Raw counts'!H5/'Raw counts'!H$1246*10000 -> 3.7274723 | I5: ='Raw counts'!I5/'Raw counts'!I$1246*10000 -> 4.3893438 | J5: ='Raw counts'!J5/'Raw counts'!J$1246*10000 -> 9.9556635 | K5: ='Raw counts'!K5/'Raw counts'!K$1246*10000 -> 2.7504831 | L5: ='Raw counts'!L5/'Raw counts'!L$1246*10000 -> 3.9955012 | ... T5: ='Raw counts'!T5/'Raw counts'!T$1246*10000 -> 2.1843108 | U5: =IFERROR(IF(W5-X5=0,0,1),0) -> 1 | V5: =IFERROR(_xlfn.T.TEST(E5:N5,O5:T5,2,2),"") -> 0.13299639 | W5: =AVERAGE(E5:N5) -> 4.5279271 | X5: =AVERAGE(O5:T5) -> 3.1238889
A6: 3 | B6: secondary fissure | C6: 118200 | D6: 1040 | E6: ='Raw counts'!E6/'Raw counts'!E$1246*10000 -> 0 | F6: ='Raw counts'!F6/'Raw counts'!F$1246*10000 -> 0 | G6: ='Raw counts'!G6/'Raw counts'!G$1246*10000 -> 0 | H6: ='Raw counts'!H6/'Raw counts'!H$1246*10000 -> 0 | I6: ='Raw counts'!I6/'Raw counts'!I$1246*10000 -> 0 | J6: ='Raw counts'!J6/'Raw counts'!J$1246*10000 -> 0 | K6: ='Raw counts'!K6/'Raw counts'!K$1246*10000 -> 0 | L6: ='Raw counts'!L6/'Raw counts'!L$1246*10000 -> 0 | ... T6: ='Raw counts'!T6/'Raw counts'!T$1246*10000 -> 0 | U6: =IFERROR(IF(W6-X6=0,0,1),0) -> 0 | V6: =IFERROR(_xlfn.T.TEST(E6:N6,O6:T6,2,2),"") | W6: =AVERAGE(E6:N6) -> 0 | X6: =AVERAGE(O6:T6) -> 0
A7: 4 | B7: Inferior colliculus | C7: 79100 | D7: 339 | E7: ='Raw counts'!E7/'Raw counts'!E$1246*10000 -> 50.701141 | F7: ='Raw counts'!F7/'Raw counts'!F$1246*10000 -> 113.61506 | G7: ='Raw counts'!G7/'Raw counts'!G$1246*10000 -> 54.721604 | H7: ='Raw counts'!H7/'Raw counts'!H$1246*10000 -> 37.588362 | I7: ='Raw counts'!I7/'Raw counts'!I$1246*10000 -> 41.085383 | J7: ='Raw counts'!J7/'Raw counts'!J$1246*10000 -> 104.26208 | K7: ='Raw counts'!K7/'Raw counts'!K$1246*10000 -> 54.481851 | L7: ='Raw counts'!L7/'Raw counts'!L$1246*10000 -> 104.66314 | ... T7: ='Raw counts'!T7/'Raw counts'!T$1246*10000 -> 31.931893 | U7: =IFERROR(IF(W7-X7=0,0,1),0) -> 1 | V7: =IFERROR(_xlfn.T.TEST(E7:N7,O7:T7,2,2),"") -> 0.11959718 | W7: =AVERAGE(E7:N7) -> 71.130676 | X7: =AVERAGE(O7:T7) -> 98.616753
A8: 6 | B8: internal capsule | C8: 107000 | D8: 784 | E8: ='Raw counts'!E8/'Raw counts'!E$1246*10000 -> 120.81774 | F8: ='Raw counts'!F8/'Raw counts'!F$1246*10000 -> 113.75671 | G8: ='Raw counts'!G8/'Raw counts'!G$1246*10000 -> 146.93755 | H8: ='Raw counts'!H8/'Raw counts'!H$1246*10000 -> 127.38546 | I8: ='Raw counts'!I8/'Raw counts'!I$1246*10000 -> 97.910504 | J8: ='Raw counts'!J8/'Raw counts'!J$1246*10000 -> 93.037262 | K8: ='Raw counts'!K8/'Raw counts'!K$1246*10000 -> 98.63033 | L8: ='Raw counts'!L8/'Raw counts'!L$1246*10000 -> 110.82258 | ... T8: ='Raw counts'!T8/'Raw counts'!T$1246*10000 -> 126.33507 | U8: =IFERROR(IF(W8-X8=0,0,1),0) -> 1 | V8: =IFERROR(_xlfn.T.TEST(E8:N8,O8:T8,2,2),"") -> 0.27163021 | W8: =AVERAGE(E8:N8) -> 120.74864 | X8: =AVERAGE(O8:T8) -> 108.81222
A9: 7 | B9: Principal sensory nucleus of the trigeminal | C9: 85300 | D9: 1132 | E9: ='Raw counts'!E9/'Raw counts'!E$1246*10000 -> 7.8672476 | F9: ='Raw counts'!F9/'Raw counts'!F$1246*10000 -> 27.126529 | G9: ='Raw counts'!G9/'Raw counts'!G$1246*10000 -> 10.131059 | H9: ='Raw counts'!H9/'Raw counts'!H$1246*10000 -> 1.3148689 | I9: ='Raw counts'!I9/'Raw counts'!I$1246*10000 -> 4.0404472 | J9: ='Raw counts'!J9/'Raw counts'!J$1246*10000 -> 6.3697089 | K9: ='Raw counts'!K9/'Raw counts'!K$1246*10000 -> 0.91487284 | L9: ='Raw counts'!L9/'Raw counts'!L$1246*10000 -> 30.919345 | ... T9: ='Raw counts'!T9/'Raw counts'!T$1246*10000 -> 0.39590633 | U9: =IFERROR(IF(W9-X9=0,0,1),0) -> 1 | V9: =IFERROR(_xlfn.T.TEST(E9:N9,O9:T9,2,2),"") -> 0.55999512 | W9: =AVERAGE(E9:N9) -> 12.210633 | X9: =AVERAGE(O9:T9) -> 15.858311
A10: 8 | B10: Basic cell groups and regions | C10: 100 | D10: 997 | E10: ='Raw counts'!E10/'Raw counts'!E$1246*10000 -> 0 | F10: ='Raw counts'!F10/'Raw counts'!F$1246*10000 -> 0 | G10: ='Raw counts'!G10/'Raw counts'!G$1246*10000 -> 0 | H10: ='Raw counts'!H10/'Raw counts'!H$1246*10000 -> 0 | I10: ='Raw counts'!I10/'Raw counts'!I$1246*10000 -> 0 | J10: ='Raw counts'!J10/'Raw counts'!J$1246*10000 -> 0 | K10: ='Raw counts'!K10/'Raw counts'!K$1246*10000 -> 0 | L10: ='Raw counts'!L10/'Raw counts'!L$1246*10000 -> 0 | ... T10: ='Raw counts'!T10/'Raw counts'!T$1246*10000 -> 0 | U10: =IFERROR(IF(W10-X10=0,0,1),0) -> 0 | V10: =IFERROR(_xlfn.T.TEST(E10:N10,O10:T10,2,2),"") | W10: =AVERAGE(E10:N10) -> 0 | X10: =AVERAGE(O10:T10) -> 0
A11: 9 | B11: Primary somatosensory area, trunk, layer 6a | C11: 7500 | D11: 361 | E11: ='Raw counts'!E11/'Raw counts'!E$1246*10000 -> 3.6264643 | F11: ='Raw counts'!F11/'Raw counts'!F$1246*10000 -> 5.7794379 | G11: ='Raw counts'!G11/'Raw counts'!G$1246*10000 -> 11.157554 | H11: ='Raw counts'!H11/'Raw counts'!H$1246*10000 -> 1.2063017 | I11: ='Raw counts'!I11/'Raw counts'!I$1246*10000 -> 6.1169445 | J11: ='Raw counts'!J11/'Raw counts'!J$1246*10000 -> 1.0715958 | K11: ='Raw counts'!K11/'Raw counts'!K$1246*10000 -> 4.1697089 | L11: ='Raw counts'!L11/'Raw counts'!L$1246*10000 -> 4.1176048 | ... T11: ='Raw counts'!T11/'Raw counts'!T$1246*10000 -> 2.6826067 | U11: =IFERROR(IF(W11-X11=0,0,1),0) -> 1 | V11: =IFERROR(_xlfn.T.TEST(E11:N11,O11:T11,2,2),"") -> 0.97011626 | W11: =AVERAGE(E11:N11) -> 4.9760238 | X11: =AVERAGE(O11:T11) -> 4.9222271
A12: 10 | B12: Superior colliculus, motor related, intermediate gray layer | C12: 81100 | D12: 294 | E12: ='Raw counts'!E12/'Raw counts'!E$1246*10000 -> 36.472719 | F12: ='Raw counts'!F12/'Raw counts'!F$1246*10000 -> 37.09417 | G12: ='Raw counts'!G12/'Raw counts'!G$1246*10000 -> 43.301228 | H12: ='Raw counts'!H12/'Raw counts'!H$1246*10000 -> 23.130835 | I12: ='Raw counts'!I12/'Raw counts'!I$1246*10000 -> 26.701841 | J12: ='Raw counts'!J12/'Raw counts'!J$1246*10000 -> 22.515484 | K12: ='Raw counts'!K12/'Raw counts'!K$1246*10000 -> 18.760758 | L12: ='Raw counts'!L12/'Raw counts'!L$1246*10000 -> 44.954476 | ... T12: ='Raw counts'!T12/'Raw counts'!T$1246*10000 -> 28.129827 | U12: =IFERROR(IF(W12-X12=0,0,1),0) -> 1 | V12: =IFERROR(_xlfn.T.TEST(E12:N12,O12:T12,2,2),"") -> 0.46816688 | W12: =AVERAGE(E12:N12) -> 33.371657 | X12: =AVERAGE(O12:T12) -> 38.154258
A13: 11 | B13: posterolateral fissure | C13: 118300 | D13: 1040 | E13: ='Raw counts'!E13/'Raw counts'!E$1246*10000 -> 0 | F13: ='Raw counts'!F13/'Raw counts'!F$1246*10000 -> 0 | G13: ='Raw counts'!G13/'Raw counts'!G$1246*10000 -> 0 | H13: ='Raw counts'!H13/'Raw counts'!H$1246*10000 -> 0 | I13: ='Raw counts'!I13/'Raw counts'!I$1246*10000 -> 0 | J13: ='Raw counts'!J13/'Raw counts'!J$1246*10000 -> 0 | K13: ='Raw counts'!K13/'Raw counts'!K$1246*10000 -> 0 | L13: ='Raw counts'!L13/'Raw counts'!L$1246*10000 -> 0 | ... T13: ='Raw counts'!T13/'Raw counts'!T$1246*10000 -> 0 | U13: =IFERROR(IF(W13-X13=0,0,1),0) -> 0 | V13: =IFERROR(_xlfn.T.TEST(E13:N13,O13:T13,2,2),"") | W13: =AVERAGE(E13:N13) -> 0 | X13: =AVERAGE(O13:T13) -> 0
A14: 12 | B14: Interfascicular nucleus raphÈ | C14: 84100 | D14: 165 | E14: ='Raw counts'!E14/'Raw counts'!E$1246*10000 -> 0 | F14: ='Raw counts'!F14/'Raw counts'!F$1246*10000 -> 0 | G14: ='Raw counts'!G14/'Raw counts'!G$1246*10000 -> 0 | H14: ='Raw counts'!H14/'Raw counts'!H$1246*10000 -> 0 | I14: ='Raw counts'!I14/'Raw counts'!I$1246*10000 -> 0 | J14: ='Raw counts'!J14/'Raw counts'!J$1246*10000 -> 0 | K14: ='Raw counts'!K14/'Raw counts'!K$1246*10000 -> 0 | L14: ='Raw counts'!L14/'Raw counts'!L$1246*10000 -> 0 | ... T14: ='Raw counts'!T14/'Raw counts'!T$1246*10000 -> 0 | U14: =IFERROR(IF(W14-X14=0,0,1),0) -> 0 | V14: =IFERROR(_xlfn.T.TEST(E14:N14,O14:T14,2,2),"") | W14: =AVERAGE(E14:N14) -> 0 | X14: =AVERAGE(O14:T14) -> 0
A15: 14 | B15: internal medullary lamina of the thalamus | C15: 108200 | D15: 896 | E15: ='Raw counts'!E15/'Raw counts'!E$1246*10000 -> 0.054496048 | F15: ='Raw counts'!F15/'Raw counts'!F$1246*10000 -> 0.051939393 | G15: ='Raw counts'!G15/'Raw counts'!G$1246*10000 -> 0.029753478 | H15: ='Raw counts'!H15/'Raw counts'!H$1246*10000 -> 0.036189052 | I15: ='Raw counts'!I15/'Raw counts'!I$1246*10000 -> 0.0056273638 | J15: ='Raw counts'!J15/'Raw counts'!J$1246*10000 -> 0.059865685 | K15: ='Raw counts'!K15/'Raw counts'!K$1246*10000 -> 0.070374834 | L15: ='Raw counts'!L15/'Raw counts'!L$1246*10000 -> 0.0407012 | ... T15: ='Raw counts'!T15/'Raw counts'!T$1246*10000 -> 0 | U15: =IFERROR(IF(W15-X15=0,0,1),0) -> 1 | V15: =IFERROR(_xlfn.T.TEST(E15:N15,O15:T15,2,2),"") -> 0.35429644 | W15: =AVERAGE(E15:N15) -> 0.042018917 | X15: =AVERAGE(O15:T15) -> 0.031650686
... A988: 996 | B988: Agranular insular area, dorsal part, layer 1 | C988: 23500 | D988: 104 | E988: ='Raw counts'!E988/'Raw counts'!E$1246*10000 -> 7.743393 | F988: ='Raw counts'!F988/'Raw counts'!F$1246*10000 -> 8.2064241 | G988: ='Raw counts'!G988/'Raw counts'!G$1246*10000 -> 4.3539255 | H988: ='Raw counts'!H988/'Raw counts'!H$1246*10000 -> 8.3596709 | I988: ='Raw counts'!I988/'Raw counts'!I$1246*10000 -> 12.672823 | J988: ='Raw counts'!J988/'Raw counts'!J$1246*10000 -> 7.4472913 | K988: ='Raw counts'!K988/'Raw counts'!K$1246*10000 -> 16.168618 | L988: ='Raw counts'!L988/'Raw counts'!L$1246*10000 -> 7.5839903 | ... T988: ='Raw counts'!T988/'Raw counts'!T$1246*10000 -> 40.116233 | U988: =IFERROR(IF(W988-X988=0,0,1),0) -> 1 | V988: =IFERROR(_xlfn.T.TEST(E988:N988,O988:T988,2,2),"") -> 0.3774266 | W988: =AVERAGE(E988:N988) -> 8.7397868 | X988: =AVERAGE(O988:T988) -> 12.787935
A989: 997 | B989: root | C989: 0 | E989: ='Raw counts'!E989/'Raw counts'!E$1246*10000 -> 0.0099083723 | F989: ='Raw counts'!F989/'Raw counts'!F$1246*10000 -> 0.014165289 | G989: ='Raw counts'!G989/'Raw counts'!G$1246*10000 -> 0.014876739 | H989: ='Raw counts'!H989/'Raw counts'!H$1246*10000 -> 0.0060315086 | I989: ='Raw counts'!I989/'Raw counts'!I$1246*10000 -> 0 | J989: ='Raw counts'!J989/'Raw counts'!J$1246*10000 -> 0.0059865685 | K989: ='Raw counts'!K989/'Raw counts'!K$1246*10000 -> 0.029322847 | L989: ='Raw counts'!L989/'Raw counts'!L$1246*10000 -> 0 | ... T989: ='Raw counts'!T989/'Raw counts'!T$1246*10000 -> 0.047781798 | U989: =IFERROR(IF(W989-X989=0,0,1),0) -> 1 | V989: =IFERROR(_xlfn.T.TEST(E989:N989,O989:T989,2,2),"") -> 0.040444738 | W989: =AVERAGE(E989:N989) -> 0.0080291325 | X989: =AVERAGE(O989:T989) -> 0.023644307
A990: 998 | B990: Fundus of striatum | C990: 48500 | D990: 493 | E990: ='Raw counts'!E990/'Raw counts'!E$1246*10000 -> 13.24254 | F990: ='Raw counts'!F990/'Raw counts'!F$1246*10000 -> 10.047912 | G990: ='Raw counts'!G990/'Raw counts'!G$1246*10000 -> 8.4847 | H990: ='Raw counts'!H990/'Raw counts'!H$1246*10000 -> 16.03175 | I990: ='Raw counts'!I990/'Raw counts'!I$1246*10000 -> 13.072366 | J990: ='Raw counts'!J990/'Raw counts'!J$1246*10000 -> 8.0818675 | K990: ='Raw counts'!K990/'Raw counts'!K$1246*10000 -> 11.787785 | L990: ='Raw counts'!L990/'Raw counts'!L$1246*10000 -> 8.6150874 | ... T990: ='Raw counts'!T990/'Raw counts'!T$1246*10000 -> 8.5597679 | U990: =IFERROR(IF(W990-X990=0,0,1),0) -> 1 | V990: =IFERROR(_xlfn.T.TEST(E990:N990,O990:T990,2,2),"") -> 0.77573473 | W990: =AVERAGE(E990:N990) -> 10.381319 | X990: =AVERAGE(O990:T990) -> 9.9782263
A991: 999 | B991: Entorhinal area, lateral part, layer 2/3 | C991: 41600 | D991: 918 | E991: ='Raw counts'!E991/'Raw counts'!E$1246*10000 -> 0 | F991: ='Raw counts'!F991/'Raw counts'!F$1246*10000 -> 0 | G991: ='Raw counts'!G991/'Raw counts'!G$1246*10000 -> 0 | H991: ='Raw counts'!H991/'Raw counts'!H$1246*10000 -> 0 | I991: ='Raw counts'!I991/'Raw counts'!I$1246*10000 -> 0 | J991: ='Raw counts'!J991/'Raw counts'!J$1246*10000 -> 0 | K991: ='Raw counts'!K991/'Raw counts'!K$1246*10000 -> 0 | L991: ='Raw counts'!L991/'Raw counts'!L$1246*10000 -> 0 | ... T991: ='Raw counts'!T991/'Raw counts'!T$1246*10000 -> 0 | U991: =IFERROR(IF(W991-X991=0,0,1),0) -> 0 | V991: =IFERROR(_xlfn.T.TEST(E991:N991,O991:T991,2,2),"") | W991: =AVERAGE(E991:N991) -> 0 | X991: =AVERAGE(O991:T991) -> 0
A992: 1000 | B992: extrapyramidal fiber systems | C992: 108500 | D992: 1009 | E992: ='Raw counts'!E992/'Raw counts'!E$1246*10000 -> 0 | F992: ='Raw counts'!F992/'Raw counts'!F$1246*10000 -> 0 | G992: ='Raw counts'!G992/'Raw counts'!G$1246*10000 -> 0 | H992: ='Raw counts'!H992/'Raw counts'!H$1246*10000 -> 0 | I992: ='Raw counts'!I992/'Raw counts'!I$1246*10000 -> 0 | J992: ='Raw counts'!J992/'Raw counts'!J$1246*10000 -> 0 | K992: ='Raw counts'!K992/'Raw counts'!K$1246*10000 -> 0 | L992: ='Raw counts'!L992/'Raw counts'!L$1246*10000 -> 0 | ... T992: ='Raw counts'!T992/'Raw counts'!T$1246*10000 -> 0 | U992: =IFERROR(IF(W992-X992=0,0,1),0) -> 0 | V992: =IFERROR(_xlfn.T.TEST(E992:N992,O992:T992,2,2),"") | W992: =AVERAGE(E992:N992) -> 0 | X992: =AVERAGE(O992:T992) -> 0
A993: 1001 | B993: Lobule V | C993: 56800 | D993: 928 | E993: ='Raw counts'!E993/'Raw counts'!E$1246*10000 -> 0 | F993: ='Raw counts'!F993/'Raw counts'!F$1246*10000 -> 0 | G993: ='Raw counts'!G993/'Raw counts'!G$1246*10000 -> 0 | H993: ='Raw counts'!H993/'Raw counts'!H$1246*10000 -> 0 | I993: ='Raw counts'!I993/'Raw counts'!I$1246*10000 -> 0 | J993: ='Raw counts'!J993/'Raw counts'!J$1246*10000 -> 0 | K993: ='Raw counts'!K993/'Raw counts'!K$1246*10000 -> 0 | L993: ='Raw counts'!L993/'Raw counts'!L$1246*10000 -> 0 | ... T993: ='Raw counts'!T993/'Raw counts'!T$1246*10000 -> 0 | U993: =IFERROR(IF(W993-X993=0,0,1),0) -> 0 | V993: =IFERROR(_xlfn.T.TEST(E993:N993,O993:T993,2,2),"") | W993: =AVERAGE(E993:N993) -> 0 | X993: =AVERAGE(O993:T993) -> 0
A994: 1002 | B994: Primary auditory area | C994: 11300 | D994: 247 | E994: ='Raw counts'!E994/'Raw counts'!E$1246*10000 -> 0 | F994: ='Raw counts'!F994/'Raw counts'!F$1246*10000 -> 0 | G994: ='Raw counts'!G994/'Raw counts'!G$1246*10000 -> 0 | H994: ='Raw counts'!H994/'Raw counts'!H$1246*10000 -> 0 | I994: ='Raw counts'!I994/'Raw counts'!I$1246*10000 -> 0 | J994: ='Raw counts'!J994/'Raw counts'!J$1246*10000 -> 0 | K994: ='Raw counts'!K994/'Raw counts'!K$1246*10000 -> 0 | L994: ='Raw counts'!L994/'Raw counts'!L$1246*10000 -> 0 | ... T994: ='Raw counts'!T994/'Raw counts'!T$1246*10000 -> 0 | U994: =IFERROR(IF(W994-X994=0,0,1),0) -> 0 | V994: =IFERROR(_xlfn.T.TEST(E994:N994,O994:T994,2,2),"") | W994: =AVERAGE(E994:N994) -> 0 | X994: =AVERAGE(O994:T994) -> 0
A995: 1003 | B995: corticopontine tract | C995: 107400 | D995: 784 | E995: ='Raw counts'!E995/'Raw counts'!E$1246*10000 -> 0 | F995: ='Raw counts'!F995/'Raw counts'!F$1246*10000 -> 0 | G995: ='Raw counts'!G995/'Raw counts'!G$1246*10000 -> 0 | H995: ='Raw counts'!H995/'Raw counts'!H$1246*10000 -> 0 | I995: ='Raw counts'!I995/'Raw counts'!I$1246*10000 -> 0 | J995: ='Raw counts'!J995/'Raw counts'!J$1246*10000 -> 0 | K995: ='Raw counts'!K995/'Raw counts'!K$1246*10000 -> 0 | L995: ='Raw counts'!L995/'Raw counts'!L$1246*10000 -> 0 | ... T995: ='Raw counts'!T995/'Raw counts'!T$1246*10000 -> 0 | U995: =IFERROR(IF(W995-X995=0,0,1),0) -> 0 | V995: =IFERROR(_xlfn.T.TEST(E995:N995,O995:T995,2,2),"") | W995: =AVERAGE(E995:N995) -> 0 | X995: =AVERAGE(O995:T995) -> 0
A996: 1004 | B996: Ventral premammillary nucleus | C996: 76100 | D996: 467 | E996: ='Raw counts'!E996/'Raw counts'!E$1246*10000 -> 0.30220536 | F996: ='Raw counts'!F996/'Raw counts'!F$1246*10000 -> 0.084991735 | G996: ='Raw counts'!G996/'Raw counts'!G$1246*10000 -> 0.27769912 | H996: ='Raw counts'!H996/'Raw counts'!H$1246*10000 -> 0.0060315086 | I996: ='Raw counts'!I996/'Raw counts'!I$1246*10000 -> 2.2847097 | J996: ='Raw counts'!J996/'Raw counts'!J$1246*10000 -> 0.029932843 | K996: ='Raw counts'!K996/'Raw counts'!K$1246*10000 -> 0 | L996: ='Raw counts'!L996/'Raw counts'!L$1246*10000 -> 0.50198147 | ... T996: ='Raw counts'!T996/'Raw counts'!T$1246*10000 -> 0 | U996: =IFERROR(IF(W996-X996=0,0,1),0) -> 1 | V996: =IFERROR(_xlfn.T.TEST(E996:N996,O996:T996,2,2),"") -> 0.77570697 | W996: =AVERAGE(E996:N996) -> 0.35901526 | X996: =AVERAGE(O996:T996) -> 0.46063615
A997: 1005 | B997: Primary auditory area, layer 6b | C997: 11900 | D997: 1002 | E997: ='Raw counts'!E997/'Raw counts'!E$1246*10000 -> 2.422597 | F997: ='Raw counts'!F997/'Raw counts'!F$1246*10000 -> 3.2202424 | G997: ='Raw counts'!G997/'Raw counts'!G$1246*10000 -> 2.0877023 | H997: ='Raw counts'!H997/'Raw counts'!H$1246*10000 -> 1.4596251 | I997: ='Raw counts'!I997/'Raw counts'!I$1246*10000 -> 0.31513238 | J997: ='Raw counts'!J997/'Raw counts'!J$1246*10000 -> 3.2686664 | K997: ='Raw counts'!K997/'Raw counts'!K$1246*10000 -> 2.0584639 | L997: ='Raw counts'!L997/'Raw counts'!L$1246*10000 -> 0.95647821 | ... T997: ='Raw counts'!T997/'Raw counts'!T$1246*10000 -> 2.4914795 | U997: =IFERROR(IF(W997-X997=0,0,1),0) -> 1 | V997: =IFERROR(_xlfn.T.TEST(E997:N997,O997:T997,2,2),"") -> 0.2022064 | W997: =AVERAGE(E997:N997) -> 2.0739655 | X997: =AVERAGE(O997:T997) -> 2.8972516
A998: 1006 | B998: Primary somatosensory area, trunk, layer 1 | C998: 7100 | D998: 361 | E998: ='Raw counts'!E998/'Raw counts'!E$1246*10000 -> 4.8204231 | F998: ='Raw counts'!F998/'Raw counts'!F$1246*10000 -> 2.2570027 | G998: ='Raw counts'!G998/'Raw counts'!G$1246*10000 -> 0.52564477 | H998: ='Raw counts'!H998/'Raw counts'!H$1246*10000 -> 1.5380347 | I998: ='Raw counts'!I998/'Raw counts'!I$1246*10000 -> 4.5187732 | J998: ='Raw counts'!J998/'Raw counts'!J$1246*10000 -> 3.3943844 | K998: ='Raw counts'!K998/'Raw counts'!K$1246*10000 -> 6.2164437 | L998: ='Raw counts'!L998/'Raw counts'!L$1246*10000 -> 2.4963403 | ... T998: ='Raw counts'!T998/'Raw counts'!T$1246*10000 -> 4.5392708 | U998: =IFERROR(IF(W998-X998=0,0,1),0) -> 1 | V998: =IFERROR(_xlfn.T.TEST(E998:N998,O998:T998,2,2),"") -> 0.60754203 | W998: =AVERAGE(E998:N998) -> 3.2108171 | X998: =AVERAGE(O998:T998) -> 2.5695177
A999: 1007 | B999: Simple lobule | C999: 59700 | D999: 1073 | E999: ='Raw counts'!E999/'Raw counts'!E$1246*10000 -> 7.1637532 | F999: ='Raw counts'!F999/'Raw counts'!F$1246*10000 -> 2.5544738 | G999: ='Raw counts'!G999/'Raw counts'!G$1246*10000 -> 0.11901391 | H999: ='Raw counts'!H999/'Raw counts'!H$1246*10000 -> 3.1725735 | I999: ='Raw counts'!I999/'Raw counts'!I$1246*10000 -> 0.73718466 | J999: ='Raw counts'!J999/'Raw counts'!J$1246*10000 -> 16.391225 | K999: ='Raw counts'!K999/'Raw counts'!K$1246*10000 -> 0.31082218 | L999: ='Raw counts'!L999/'Raw counts'!L$1246*10000 -> 19.407689 | ... T999: ='Raw counts'!T999/'Raw counts'!T$1246*10000 -> 0 | U999: =IFERROR(IF(W999-X999=0,0,1),0) -> 1 | V999: =IFERROR(_xlfn.T.TEST(E999:N999,O999:T999,2,2),"") -> 0.24627021 | W999: =AVERAGE(E999:N999) -> 6.797291 | X999: =AVERAGE(O999:T999) -> 3.2063644
A1000: 1008 | B1000: Geniculate group, dorsal thalamus | C1000: 65000 | D1000: 864 | E1000: ='Raw counts'!E1000/'Raw counts'!E$1246*10000 -> 0 | F1000: ='Raw counts'!F1000/'Raw counts'!F$1246*10000 -> 0 | G1000: ='Raw counts'!G1000/'Raw counts'!G$1246*10000 -> 0 | H1000: ='Raw counts'!H1000/'Raw counts'!H$1246*10000 -> 0 | I1000: ='Raw counts'!I1000/'Raw counts'!I$1246*10000 -> 0 | J1000: ='Raw counts'!J1000/'Raw counts'!J$1246*10000 -> 0 | K1000: ='Raw counts'!K1000/'Raw counts'!K$1246*10000 -> 0 | L1000: ='Raw counts'!L1000/'Raw counts'!L$1246*10000 -> 0 | ... T1000: ='Raw counts'!T1000/'Raw counts'!T$1246*10000 -> 0 | U1000: =IFERROR(IF(W1000-X1000=0,0,1),0) -> 0 | V1000: =IFERROR(_xlfn.T.TEST(E1000:N1000,O1000:T1000,2,2),"") | W1000: =AVERAGE(E1000:N1000) -> 0 | X1000: =AVERAGE(O1000:T1000) -> 0
A1001: 1009 | B1001: fiber tracts | C1001: 97200 | D1001: 997 | E1001: ='Raw counts'!E1001/'Raw counts'!E$1246*10000 -> 56.046708 | F1001: ='Raw counts'!F1001/'Raw counts'!F$1246*10000 -> 54.98493 | G1001: ='Raw counts'!G1001/'Raw counts'!G$1246*10000 -> 63.930305 | H1001: ='Raw counts'!H1001/'Raw counts'!H$1246*10000 -> 41.213298 | I1001: ='Raw counts'!I1001/'Raw counts'!I$1246*10000 -> 65.592553 | J1001: ='Raw counts'!J1001/'Raw counts'!J$1246*10000 -> 73.191787 | K1001: ='Raw counts'!K1001/'Raw counts'!K$1246*10000 -> 42.002047 | L1001: ='Raw counts'!L1001/'Raw counts'!L$1246*10000 -> 45.429323 | ... T1001: ='Raw counts'!T1001/'Raw counts'!T$1246*10000 -> 48.334702 | U1001: =IFERROR(IF(W1001-X1001=0,0,1),0) -> 1 | V1001: =IFERROR(_xlfn.T.TEST(E1001:N1001,O1001:T1001,2,2),"") -> 0.025145627 | W1001: =AVERAGE(E1001:N1001) -> 55.219432 | X1001: =AVERAGE(O1001:T1001) -> 42.854644
... A1244: 312782656 | B1244: Unlabeled | C1244: 300 | D1244: 688 | E1244: ='Raw counts'!E1244/'Raw counts'!E$1246*10000 -> 12.841251 | F1244: ='Raw counts'!F1244/'Raw counts'!F$1246*10000 -> 6.6624076 | G1244: ='Raw counts'!G1244/'Raw counts'!G$1246*10000 -> 6.1391342 | H1244: ='Raw counts'!H1244/'Raw counts'!H$1246*10000 -> 5.5007358 | I1244: ='Raw counts'!I1244/'Raw counts'!I$1246*10000 -> 6.1844729 | J1244: ='Raw counts'!J1244/'Raw counts'!J$1246*10000 -> 10.249005 | K1244: ='Raw counts'!K1244/'Raw counts'!K$1246*10000 -> 8.2455847 | L1244: ='Raw counts'!L1244/'Raw counts'!L$1246*10000 -> 6.2747684 | ... T1244: ='Raw counts'!T1244/'Raw counts'!T$1246*10000 -> 9.3242766 | U1244: =IFERROR(IF(W1244-X1244=0,0,1),0) -> 1 | V1244: =IFERROR(_xlfn.T.TEST(E1244:N1244,O1244:T1244,2,2),"") -> 0.54246491 | W1244: =AVERAGE(E1244:N1244) -> 7.7592197 | X1244: =AVERAGE(O1244:T1244) -> 7.083237
E1246: =SUM(E3:E1244) -> 10000 | F1246: =SUM(F3:F1244) -> 10000 | G1246: =SUM(G3:G1244) -> 10000 | H1246: =SUM(H3:H1244) -> 10000 | I1246: =SUM(I3:I1244) -> 10000 | J1246: =SUM(J3:J1244) -> 10000 | K1246: =SUM(K3:K1244) -> 10000 | L1246: =SUM(L3:L1244) -> 10000 | ... T1246: =SUM(T3:T1244) -> 10000

Sheet Activation map
E1: Group | F1: 0 | G1: 0 | H1: 0 | I1: 0 | J1: 0 | K1: 0 | L1: 0 | M1: 0 | N1: 0 | O1: 0 | P1: 1 | Q1: 1 | R1: 1 | S1: 1 | T1: 1 | U1: 1
B2: id | C2: name | D2: structure_order | E2: parent_id | F2: 345391 | G2: 348028 | H2: 348030 | I2: 348035 | J2: 348465 | K2: 349038 | L2: 349438 | M2: 354044 | N2: 354519 | O2: 354522 | P2: 348034 | Q2: 349022 | R2: 349440 | S2: 350322 | T2: 350324 | U2: 354043 | W2: T-test | X2: Gem 0 | Y2: Gem 1
A3: dCA1 | B3: 382 | C3: Field CA1 | D3: 37700 | E3: 375 | F3: =SUMIFS('Raw counts'!E:E,'Raw counts'!$A:$A,'Activation map'!$B3) -> 1900 | G3: =SUMIFS('Raw counts'!F:F,'Raw counts'!$A:$A,'Activation map'!$B3) -> 3509 | H3: =SUMIFS('Raw counts'!G:G,'Raw counts'!$A:$A,'Activation map'!$B3) -> 5872 | I3: =SUMIFS('Raw counts'!H:H,'Raw counts'!$A:$A,'Activation map'!$B3) -> 1758 | J3: =SUMIFS('Raw counts'!I:I,'Raw counts'!$A:$A,'Activation map'!$B3) -> 4336 | K3: =SUMIFS('Raw counts'!J:J,'Raw counts'!$A:$A,'Activation map'!$B3) -> 4723 | L3: =SUMIFS('Raw counts'!K:K,'Raw counts'!$A:$A,'Activation map'!$B3) -> 1646 | M3: =SUMIFS('Raw counts'!L:L,'Raw counts'!$A:$A,'Activation map'!$B3) -> 3505 | N3: =SUMIFS('Raw counts'!M:M,'Raw counts'!$A:$A,'Activation map'!$B3) -> 2737 | O3: =SUMIFS('Raw counts'!N:N,'Raw counts'!$A:$A,'Activation map'!$B3) -> 2570 | P3: =SUMIFS('Raw counts'!O:O,'Raw counts'!$A:$A,'Activation map'!$B3) -> 1737 | Q3: =SUMIFS('Raw counts'!P:P,'Raw counts'!$A:$A,'Activation map'!$B3) -> 3304 | R3: =SUMIFS('Raw counts'!Q:Q,'Raw counts'!$A:$A,'Activation map'!$B3) -> 3136 | S3: =SUMIFS('Raw counts'!R:R,'Raw counts'!$A:$A,'Activation map'!$B3) -> 3062 | T3: =SUMIFS('Raw counts'!S:S,'Raw counts'!$A:$A,'Activation map'!$B3) -> 2475 | U3: =SUMIFS('Raw counts'!T:T,'Raw counts'!$A:$A,'Activation map'!$B3) -> 1547 | W3: =_xlfn.T.TEST(F3:O3,P3:U3,2,2) -> 0.27413536 | X3: =AVERAGE(F3:O3) -> 3255.6 | Y3: =AVERAGE(P3:U3) -> 2543.5
A4: dCA3 | B4: 463 | C4: Field CA3 | D4: 38700 | E4: 375 | F4: =SUMIFS('Raw counts'!E:E,'Raw counts'!$A:$A,'Activation map'!$B4) -> 3640 | G4: =SUMIFS('Raw counts'!F:F,'Raw counts'!$A:$A,'Activation map'!$B4) -> 3311 | H4: =SUMIFS('Raw counts'!G:G,'Raw counts'!$A:$A,'Activation map'!$B4) -> 5319 | I4: =SUMIFS('Raw counts'!H:H,'Raw counts'!$A:$A,'Activation map'!$B4) -> 1759 | J4: =SUMIFS('Raw counts'!I:I,'Raw counts'!$A:$A,'Activation map'!$B4) -> 2953 | K4: =SUMIFS('Raw counts'!J:J,'Raw counts'!$A:$A,'Activation map'!$B4) -> 2057 | L4: =SUMIFS('Raw counts'!K:K,'Raw counts'!$A:$A,'Activation map'!$B4) -> 1146 | M4: =SUMIFS('Raw counts'!L:L,'Raw counts'!$A:$A,'Activation map'!$B4) -> 1052 | N4: =SUMIFS('Raw counts'!M:M,'Raw counts'!$A:$A,'Activation map'!$B4) -> 1776 | O4: =SUMIFS('Raw counts'!N:N,'Raw counts'!$A:$A,'Activation map'!$B4) -> 850 | P4: =SUMIFS('Raw counts'!O:O,'Raw counts'!$A:$A,'Activation map'!$B4) -> 4580 | Q4: =SUMIFS('Raw counts'!P:P,'Raw counts'!$A:$A,'Activation map'!$B4) -> 3095 | R4: =SUMIFS('Raw counts'!Q:Q,'Raw counts'!$A:$A,'Activation map'!$B4) -> 1605 | S4: =SUMIFS('Raw counts'!R:R,'Raw counts'!$A:$A,'Activation map'!$B4) -> 1673 | T4: =SUMIFS('Raw counts'!S:S,'Raw counts'!$A:$A,'Activation map'!$B4) -> 1309 | U4: =SUMIFS('Raw counts'!T:T,'Raw counts'!$A:$A,'Activation map'!$B4) -> 983 | W4: =_xlfn.T.TEST(F4:O4,P4:U4,2,2) -> 0.807682 | X4: =AVERAGE(F4:O4) -> 2386.3 | Y4: =AVERAGE(P4:U4) -> 2207.5
A5: dDG | C5: Dentate gyrus | E5: 726 | F5: =SUMPRODUCT(SUMIFS('Raw counts'!E:E,'Raw counts'!$A:$A,$B16:$B18)) -> 4261 | G5: =SUMPRODUCT(SUMIFS('Raw counts'!F:F,'Raw counts'!$A:$A,$B16:$B18)) -> 6516 | H5: =SUMPRODUCT(SUMIFS('Raw counts'!G:G,'Raw counts'!$A:$A,$B16:$B18)) -> 3341 | I5: =SUMPRODUCT(SUMIFS('Raw counts'!H:H,'Raw counts'!$A:$A,$B16:$B18)) -> 4256 | J5: =SUMPRODUCT(SUMIFS('Raw counts'!I:I,'Raw counts'!$A:$A,$B16:$B18)) -> 5130 | K5: =SUMPRODUCT(SUMIFS('Raw counts'!J:J,'Raw counts'!$A:$A,$B16:$B18)) -> 3187 | L5: =SUMPRODUCT(SUMIFS('Raw counts'!K:K,'Raw counts'!$A:$A,$B16:$B18)) -> 2552 | M5: =SUMPRODUCT(SUMIFS('Raw counts'!L:L,'Raw counts'!$A:$A,$B16:$B18)) -> 7054 | N5: =SUMPRODUCT(SUMIFS('Raw counts'!M:M,'Raw counts'!$A:$A,$B16:$B18)) -> 5486 | O5: =SUMPRODUCT(SUMIFS('Raw counts'!N:N,'Raw counts'!$A:$A,$B16:$B18)) -> 6801 | P5: =SUMPRODUCT(SUMIFS('Raw counts'!O:O,'Raw counts'!$A:$A,$B16:$B18)) -> 3248 | Q5: =SUMPRODUCT(SUMIFS('Raw counts'!P:P,'Raw counts'!$A:$A,$B16:$B18)) -> 3414 | R5: =SUMPRODUCT(SUMIFS('Raw counts'!Q:Q,'Raw counts'!$A:$A,$B16:$B18)) -> 4138 | S5: =SUMPRODUCT(SUMIFS('Raw counts'!R:R,'Raw counts'!$A:$A,$B16:$B18)) -> 3087 | T5: =SUMPRODUCT(SUMIFS('Raw counts'!S:S,'Raw counts'!$A:$A,$B16:$B18)) -> 3838 | U5: =SUMPRODUCT(SUMIFS('Raw counts'!T:T,'Raw counts'!$A:$A,$B16:$B18)) -> 4979 | W5: =_xlfn.T.TEST(F5:O5,P5:U5,2,2) -> 0.14481379 | X5: =AVERAGE(F5:O5) -> 4858.4 | Y5: =AVERAGE(P5:U5) -> 3784
A6: vCA1 | B6: 2382 | C6: Field CA1 ventral | D6: 37700 | E6: 2375 | F6: =SUMIFS('Raw counts'!E:E,'Raw counts'!$A:$A,'Activation map'!$B6) -> 6676 | G6: =SUMIFS('Raw counts'!F:F,'Raw counts'!$A:$A,'Activation map'!$B6) -> 8165 | H6: =SUMIFS('Raw counts'!G:G,'Raw counts'!$A:$A,'Activation map'!$B6) -> 9273 | I6: =SUMIFS('Raw counts'!H:H,'Raw counts'!$A:$A,'Activation map'!$B6) -> 10553 | J6: =SUMIFS('Raw counts'!I:I,'Raw counts'!$A:$A,'Activation map'!$B6) -> 6225 | K6: =SUMIFS('Raw counts'!J:J,'Raw counts'!$A:$A,'Activation map'!$B6) -> 10932 | L6: =SUMIFS('Raw counts'!K:K,'Raw counts'!$A:$A,'Activation map'!$B6) -> 4541 | M6: =SUMIFS('Raw counts'!L:L,'Raw counts'!$A:$A,'Activation map'!$B6) -> 12012 | N6: =SUMIFS('Raw counts'!M:M,'Raw counts'!$A:$A,'Activation map'!$B6) -> 9572 | O6: =SUMIFS('Raw counts'!N:N,'Raw counts'!$A:$A,'Activation map'!$B6) -> 10539 | P6: =SUMIFS('Raw counts'!O:O,'Raw counts'!$A:$A,'Activation map'!$B6) -> 10096 | Q6: =SUMIFS('Raw counts'!P:P,'Raw counts'!$A:$A,'Activation map'!$B6) -> 9186 | R6: =SUMIFS('Raw counts'!Q:Q,'Raw counts'!$A:$A,'Activation map'!$B6) -> 12271 | S6: =SUMIFS('Raw counts'!R:R,'Raw counts'!$A:$A,'Activation map'!$B6) -> 5597 | T6: =SUMIFS('Raw counts'!S:S,'Raw counts'!$A:$A,'Activation map'!$B6) -> 8441 | U6: =SUMIFS('Raw counts'!T:T,'Raw counts'!$A:$A,'Activation map'!$B6) -> 8473 | W6: =_xlfn.T.TEST(F6:O6,P6:U6,2,2) -> 0.89458166 | X6: =AVERAGE(F6:O6) -> 8848.8 | Y6: =AVERAGE(P6:U6) -> 9010.6667
A7: vCA3 | B7: 2463 | C7: Field CA3 ventral | D7: 38700 | E7: 2375 | F7: =SUMIFS('Raw counts'!E:E,'Raw counts'!$A:$A,'Activation map'!$B7) -> 6267 | G7: =SUMIFS('Raw counts'!F:F,'Raw counts'!$A:$A,'Activation map'!$B7) -> 8359 | H7: =SUMIFS('Raw counts'!G:G,'Raw counts'!$A:$A,'Activation map'!$B7) -> 5770 | I7: =SUMIFS('Raw counts'!H:H,'Raw counts'!$A:$A,'Activation map'!$B7) -> 3801 | J7: =SUMIFS('Raw counts'!I:I,'Raw counts'!$A:$A,'Activation map'!$B7) -> 2522 | K7: =SUMIFS('Raw counts'!J:J,'Raw counts'!$A:$A,'Activation map'!$B7) -> 9729 | L7: =SUMIFS('Raw counts'!K:K,'Raw counts'!$A:$A,'Activation map'!$B7) -> 3505 | M7: =SUMIFS('Raw counts'!L:L,'Raw counts'!$A:$A,'Activation map'!$B7) -> 4277 | N7: =SUMIFS('Raw counts'!M:M,'Raw counts'!$A:$A,'Activation map'!$B7) -> 3163 | O7: =SUMIFS('Raw counts'!N:N,'Raw counts'!$A:$A,'Activation map'!$B7) -> 3220 | P7: =SUMIFS('Raw counts'!O:O,'Raw counts'!$A:$A,'Activation map'!$B7) -> 7996 | Q7: =SUMIFS('Raw counts'!P:P,'Raw counts'!$A:$A,'Activation map'!$B7) -> 5774 | R7: =SUMIFS('Raw counts'!Q:Q,'Raw counts'!$A:$A,'Activation map'!$B7) -> 3384 | S7: =SUMIFS('Raw counts'!R:R,'Raw counts'!$A:$A,'Activation map'!$B7) -> 3293 | T7: =SUMIFS('Raw counts'!S:S,'Raw counts'!$A:$A,'Activation map'!$B7) -> 2714 | U7: =SUMIFS('Raw counts'!T:T,'Raw counts'!$A:$A,'Activation map'!$B7) -> 5398 | W7: =_xlfn.T.TEST(F7:O7,P7:U7,2,2) -> 0.80170036 | X7: =AVERAGE(F7:O7) -> 5061.3 | Y7: =AVERAGE(P7:U7) -> 4759.8333
A8: vDG | C8: Dentate gyrus ventral | E8: 2726 | F8: =SUMPRODUCT(SUMIFS('Raw counts'!E:E,'Raw counts'!$A:$A,$B19:$B21)) -> 6992 | G8: =SUMPRODUCT(SUMIFS('Raw counts'!F:F,'Raw counts'!$A:$A,$B19:$B21)) -> 7573 | H8: =SUMPRODUCT(SUMIFS('Raw counts'!G:G,'Raw counts'!$A:$A,$B19:$B21)) -> 4924 | I8: =SUMPRODUCT(SUMIFS('Raw counts'!H:H,'Raw counts'!$A:$A,$B19:$B21)) -> 9062 | J8: =SUMPRODUCT(SUMIFS('Raw counts'!I:I,'Raw counts'!$A:$A,$B19:$B21)) -> 3714 | K8: =SUMPRODUCT(SUMIFS('Raw counts'!J:J,'Raw counts'!$A:$A,$B19:$B21)) -> 6601 | L8: =SUMPRODUCT(SUMIFS('Raw counts'!K:K,'Raw counts'!$A:$A,$B19:$B21)) -> 4025 | M8: =SUMPRODUCT(SUMIFS('Raw counts'!L:L,'Raw counts'!$A:$A,$B19:$B21)) -> 5565 | N8: =SUMPRODUCT(SUMIFS('Raw counts'!M:M,'Raw counts'!$A:$A,$B19:$B21)) -> 7088 | O8: =SUMPRODUCT(SUMIFS('Raw counts'!N:N,'Raw counts'!$A:$A,$B19:$B21)) -> 11342 | P8: =SUMPRODUCT(SUMIFS('Raw counts'!O:O,'Raw counts'!$A:$A,$B19:$B21)) -> 5715 | Q8: =SUMPRODUCT(SUMIFS('Raw counts'!P:P,'Raw counts'!$A:$A,$B19:$B21)) -> 5144 | R8: =SUMPRODUCT(SUMIFS('Raw counts'!Q:Q,'Raw counts'!$A:$A,$B19:$B21)) -> 7107 | S8: =SUMPRODUCT(SUMIFS('Raw counts'!R:R,'Raw counts'!$A:$A,$B19:$B21)) -> 3383 | T8: =SUMPRODUCT(SUMIFS('Raw counts'!S:S,'Raw counts'!$A:$A,$B19:$B21)) -> 3989 | U8: =SUMPRODUCT(SUMIFS('Raw counts'!T:T,'Raw counts'!$A:$A,$B19:$B21)) -> 11030 | W8: =_xlfn.T.TEST(F8:O8,P8:U8,2,2) -> 0.63333191 | X8: =AVERAGE(F8:O8) -> 6688.6 | Y8: =AVERAGE(P8:U8) -> 6061.3333
A9: RSP | C9: Retrosplenial area | F9: =SUMPRODUCT(SUMIFS('Raw counts'!E:E,'Raw counts'!$A:$A,$B22:$B38)) -> 26854 | G9: =SUMPRODUCT(SUMIFS('Raw counts'!F:F,'Raw counts'!$A:$A,$B22:$B38)) -> 36709 | H9: =SUMPRODUCT(SUMIFS('Raw counts'!G:G,'Raw counts'!$A:$A,$B22:$B38)) -> 45888 | I9: =SUMPRODUCT(SUMIFS('Raw counts'!H:H,'Raw counts'!$A:$A,$B22:$B38)) -> 37556 | J9: =SUMPRODUCT(SUMIFS('Raw counts'!I:I,'Raw counts'!$A:$A,$B22:$B38)) -> 24907 | K9: =SUMPRODUCT(SUMIFS('Raw counts'!J:J,'Raw counts'!$A:$A,$B22:$B38)) -> 57924 | L9: =SUMPRODUCT(SUMIFS('Raw counts'!K:K,'Raw counts'!$A:$A,$B22:$B38)) -> 36222 | M9: =SUMPRODUCT(SUMIFS('Raw counts'!L:L,'Raw counts'!$A:$A,$B22:$B38)) -> 24608 | N9: =SUMPRODUCT(SUMIFS('Raw counts'!M:M,'Raw counts'!$A:$A,$B22:$B38)) -> 30613 | O9: =SUMPRODUCT(SUMIFS('Raw counts'!N:N,'Raw counts'!$A:$A,$B22:$B38)) -> 28467 | P9: =SUMPRODUCT(SUMIFS('Raw counts'!O:O,'Raw counts'!$A:$A,$B22:$B38)) -> 35896 | Q9: =SUMPRODUCT(SUMIFS('Raw counts'!P:P,'Raw counts'!$A:$A,$B22:$B38)) -> 25105 | R9: =SUMPRODUCT(SUMIFS('Raw counts'!Q:Q,'Raw counts'!$A:$A,$B22:$B38)) -> 33601 | S9: =SUMPRODUCT(SUMIFS('Raw counts'!R:R,'Raw counts'!$A:$A,$B22:$B38)) -> 25103 | T9: =SUMPRODUCT(SUMIFS('Raw counts'!S:S,'Raw counts'!$A:$A,$B22:$B38)) -> 33057 | U9: =SUMPRODUCT(SUMIFS('Raw counts'!T:T,'Raw counts'!$A:$A,$B22:$B38)) -> 22549 | W9: =_xlfn.T.TEST(F9:O9,P9:U9,2,2) -> 0.23900088 | X9: =AVERAGE(F9:O9) -> 34974.8 | Y9: =AVERAGE(P9:U9) -> 29218.5
A10: ACC | C10: Anterior cingulate area | F10: =SUMPRODUCT(SUMIFS('Raw counts'!E:E,'Raw counts'!$A:$A,$B39:$B48)) -> 13388 | G10: =SUMPRODUCT(SUMIFS('Raw counts'!F:F,'Raw counts'!$A:$A,$B39:$B48)) -> 10712 | H10: =SUMPRODUCT(SUMIFS('Raw counts'!G:G,'Raw counts'!$A:$A,$B39:$B48)) -> 14888 | I10: =SUMPRODUCT(SUMIFS('Raw counts'!H:H,'Raw counts'!$A:$A,$B39:$B48)) -> 9851 | J10: =SUMPRODUCT(SUMIFS('Raw counts'!I:I,'Raw counts'!$A:$A,$B39:$B48)) -> 5492 | K10: =SUMPRODUCT(SUMIFS('Raw counts'!J:J,'Raw counts'!$A:$A,$B39:$B48)) -> 17127 | L10: =SUMPRODUCT(SUMIFS('Raw counts'!K:K,'Raw counts'!$A:$A,$B39:$B48)) -> 34083 | M10: =SUMPRODUCT(SUMIFS('Raw counts'!L:L,'Raw counts'!$A:$A,$B39:$B48)) -> 8370 | N10: =SUMPRODUCT(SUMIFS('Raw counts'!M:M,'Raw counts'!$A:$A,$B39:$B48)) -> 10101 | O10: =SUMPRODUCT(SUMIFS('Raw counts'!N:N,'Raw counts'!$A:$A,$B39:$B48)) -> 6644 | P10: =SUMPRODUCT(SUMIFS('Raw counts'!O:O,'Raw counts'!$A:$A,$B39:$B48)) -> 7343 | Q10: =SUMPRODUCT(SUMIFS('Raw counts'!P:P,'Raw counts'!$A:$A,$B39:$B48)) -> 9143 | R10: =SUMPRODUCT(SUMIFS('Raw counts'!Q:Q,'Raw counts'!$A:$A,$B39:$B48)) -> 15813 | S10: =SUMPRODUCT(SUMIFS('Raw counts'!R:R,'Raw counts'!$A:$A,$B39:$B48)) -> 10284 | T10: =SUMPRODUCT(SUMIFS('Raw counts'!S:S,'Raw counts'!$A:$A,$B39:$B48)) -> 6178 | U10: =SUMPRODUCT(SUMIFS('Raw counts'!T:T,'Raw counts'!$A:$A,$B39:$B48)) -> 6281 | W10: =_xlfn.T.TEST(F10:O10,P10:U10,2,2) -> 0.29537749 | X10: =AVERAGE(F10:O10) -> 13065.6 | Y10: =AVERAGE(P10:U10) -> 9173.6667
A11: PL | C11: Prelimbic area | E11: 972 | F11: =SUMPRODUCT(SUMIFS('Raw counts'!E:E,'Raw counts'!$A:$A,$B49:$B53)) -> 5898 | G11: =SUMPRODUCT(SUMIFS('Raw counts'!F:F,'Raw counts'!$A:$A,$B49:$B53)) -> 3868 | H11: =SUMPRODUCT(SUMIFS('Raw counts'!G:G,'Raw counts'!$A:$A,$B49:$B53)) -> 2352 | I11: =SUMPRODUCT(SUMIFS('Raw counts'!H:H,'Raw counts'!$A:$A,$B49:$B53)) -> 2321 | J11: =SUMPRODUCT(SUMIFS('Raw counts'!I:I,'Raw counts'!$A:$A,$B49:$B53)) -> 3026 | K11: =SUMPRODUCT(SUMIFS('Raw counts'!J:J,'Raw counts'!$A:$A,$B49:$B53)) -> 7984 | L11: =SUMPRODUCT(SUMIFS('Raw counts'!K:K,'Raw counts'!$A:$A,$B49:$B53)) -> 13225 | M11: =SUMPRODUCT(SUMIFS('Raw counts'!L:L,'Raw counts'!$A:$A,$B49:$B53)) -> 3339 | N11: =SUMPRODUCT(SUMIFS('Raw counts'!M:M,'Raw counts'!$A:$A,$B49:$B53)) -> 5049 | O11: =SUMPRODUCT(SUMIFS('Raw counts'!N:N,'Raw counts'!$A:$A,$B49:$B53)) -> 1172 | P11: =SUMPRODUCT(SUMIFS('Raw counts'!O:O,'Raw counts'!$A:$A,$B49:$B53)) -> 2171 | Q11: =SUMPRODUCT(SUMIFS('Raw counts'!P:P,'Raw counts'!$A:$A,$B49:$B53)) -> 3102 | R11: =SUMPRODUCT(SUMIFS('Raw counts'!Q:Q,'Raw counts'!$A:$A,$B49:$B53)) -> 7774 | S11: =SUMPRODUCT(SUMIFS('Raw counts'!R:R,'Raw counts'!$A:$A,$B49:$B53)) -> 3079 | T11: =SUMPRODUCT(SUMIFS('Raw counts'!S:S,'Raw counts'!$A:$A,$B49:$B53)) -> 1590 | U11: =SUMPRODUCT(SUMIFS('Raw counts'!T:T,'Raw counts'!$A:$A,$B49:$B53)) -> 2013 | W11: =_xlfn.T.TEST(F11:O11,P11:U11,2,2) -> 0.36273876 | X11: =AVERAGE(F11:O11) -> 4823.4 | Y11: =AVERAGE(P11:U11) -> 3288.1667
A12: IL | C12: Infralimbic area | E12: 44 | F12: =SUMPRODUCT(SUMIFS('Raw counts'!E:E,'Raw counts'!$A:$A,$B54:$B58)) -> 7080 | G12: =SUMPRODUCT(SUMIFS('Raw counts'!F:F,'Raw counts'!$A:$A,$B54:$B58)) -> 5251 | H12: =SUMPRODUCT(SUMIFS('Raw counts'!G:G,'Raw counts'!$A:$A,$B54:$B58)) -> 2895 | I12: =SUMPRODUCT(SUMIFS('Raw counts'!H:H,'Raw counts'!$A:$A,$B54:$B58)) -> 2729 | J12: =SUMPRODUCT(SUMIFS('Raw counts'!I:I,'Raw counts'!$A:$A,$B54:$B58)) -> 4086 | K12: =SUMPRODUCT(SUMIFS('Raw counts'!J:J,'Raw counts'!$A:$A,$B54:$B58)) -> 2974 | L12: =SUMPRODUCT(SUMIFS('Raw counts'!K:K,'Raw counts'!$A:$A,$B54:$B58)) -> 13899 | M12: =SUMPRODUCT(SUMIFS('Raw counts'!L:L,'Raw counts'!$A:$A,$B54:$B58)) -> 2014 | N12: =SUMPRODUCT(SUMIFS('Raw counts'!M:M,'Raw counts'!$A:$A,$B54:$B58)) -> 5967 | O12: =SUMPRODUCT(SUMIFS('Raw counts'!N:N,'Raw counts'!$A:$A,$B54:$B58)) -> 1047 | P12: =SUMPRODUCT(SUMIFS('Raw counts'!O:O,'Raw counts'!$A:$A,$B54:$B58)) -> 2869 | Q12: =SUMPRODUCT(SUMIFS('Raw counts'!P:P,'Raw counts'!$A:$A,$B54:$B58)) -> 5545 | R12: =SUMPRODUCT(SUMIFS('Raw counts'!Q:Q,'Raw counts'!$A:$A,$B54:$B58)) -> 3787 | S12: =SUMPRODUCT(SUMIFS('Raw counts'!R:R,'Raw counts'!$A:$A,$B54:$B58)) -> 6201 | T12: =SUMPRODUCT(SUMIFS('Raw counts'!S:S,'Raw counts'!$A:$A,$B54:$B58)) -> 2798 | U12: =SUMPRODUCT(SUMIFS('Raw counts'!T:T,'Raw counts'!$A:$A,$B54:$B58)) -> 2045 | W12: =_xlfn.T.TEST(F12:O12,P12:U12,2,2) -> 0.57786715 | X12: =AVERAGE(F12:O12) -> 4794.2 | Y12: =AVERAGE(P12:U12) -> 3874.1667
A13: CeA | B13: 536 | C13: Central amygdalar nucleus | D13: 50300 | E13: 278 | F13: =SUMIFS('Raw counts'!E:E,'Raw counts'!$A:$A,'Activation map'!$B13) -> 5608 | G13: =SUMIFS('Raw counts'!F:F,'Raw counts'!$A:$A,'Activation map'!$B13) -> 5209 | H13: =SUMIFS('Raw counts'!G:G,'Raw counts'!$A:$A,'Activation map'!$B13) -> 5142 | I13: =SUMIFS('Raw counts'!H:H,'Raw counts'!$A:$A,'Activation map'!$B13) -> 3038 | J13: =SUMIFS('Raw counts'!I:I,'Raw counts'!$A:$A,'Activation map'!$B13) -> 3624 | K13: =SUMIFS('Raw counts'!J:J,'Raw counts'!$A:$A,'Activation map'!$B13) -> 4137 | L13: =SUMIFS('Raw counts'!K:K,'Raw counts'!$A:$A,'Activation map'!$B13) -> 4657 | M13: =SUMIFS('Raw counts'!L:L,'Raw counts'!$A:$A,'Activation map'!$B13) -> 1751 | N13: =SUMIFS('Raw counts'!M:M,'Raw counts'!$A:$A,'Activation map'!$B13) -> 1722 | O13: =SUMIFS('Raw counts'!N:N,'Raw counts'!$A:$A,'Activation map'!$B13) -> 777 | P13: =SUMIFS('Raw counts'!O:O,'Raw counts'!$A:$A,'Activation map'!$B13) -> 3627 | Q13: =SUMIFS('Raw counts'!P:P,'Raw counts'!$A:$A,'Activation map'!$B13) -> 2993 | R13: =SUMIFS('Raw counts'!Q:Q,'Raw counts'!$A:$A,'Activation map'!$B13) -> 4030 | S13: =SUMIFS('Raw counts'!R:R,'Raw counts'!$A:$A,'Activation map'!$B13) -> 4983 | T13: =SUMIFS('Raw counts'!S:S,'Raw counts'!$A:$A,'Activation map'!$B13) -> 3170 | U13: =SUMIFS('Raw counts'!T:T,'Raw counts'!$A:$A,'Activation map'!$B13) -> 2915 | W13: =_xlfn.T.TEST(F13:O13,P13:U13,2,2) -> 0.94373435 | X13: =AVERAGE(F13:O13) -> 3566.5 | Y13: =AVERAGE(P13:U13) -> 3619.6667
A14: BLA | C14: Basolateral amygdalar nucleus | E14: 295 | F14: =SUMPRODUCT(SUMIFS('Raw counts'!E:E,'Raw counts'!$A:$A,$B59:$B61)) -> 4020 | G14: =SUMPRODUCT(SUMIFS('Raw counts'!F:F,'Raw counts'!$A:$A,$B59:$B61)) -> 5103 | H14: =SUMPRODUCT(SUMIFS('Raw counts'!G:G,'Raw counts'!$A:$A,$B59:$B61)) -> 5984 | I14: =SUMPRODUCT(SUMIFS('Raw counts'!H:H,'Raw counts'!$A:$A,$B59:$B61)) -> 3288 | J14: =SUMPRODUCT(SUMIFS('Raw counts'!I:I,'Raw counts'!$A:$A,$B59:$B61)) -> 3274 | K14: =SUMPRODUCT(SUMIFS('Raw counts'!J:J,'Raw counts'!$A:$A,$B59:$B61)) -> 3984 | L14: =SUMPRODUCT(SUMIFS('Raw counts'!K:K,'Raw counts'!$A:$A,$B59:$B61)) -> 5387 | M14: =SUMPRODUCT(SUMIFS('Raw counts'!L:L,'Raw counts'!$A:$A,$B59:$B61)) -> 1970 | N14: =SUMPRODUCT(SUMIFS('Raw counts'!M:M,'Raw counts'!$A:$A,$B59:$B61)) -> 2393 | O14: =SUMPRODUCT(SUMIFS('Raw counts'!N:N,'Raw counts'!$A:$A,$B59:$B61)) -> 1841 | P14: =SUMPRODUCT(SUMIFS('Raw counts'!O:O,'Raw counts'!$A:$A,$B59:$B61)) -> 5532 | Q14: =SUMPRODUCT(SUMIFS('Raw counts'!P:P,'Raw counts'!$A:$A,$B59:$B61)) -> 3906 | R14: =SUMPRODUCT(SUMIFS('Raw counts'!Q:Q,'Raw counts'!$A:$A,$B59:$B61)) -> 5707 | S14: =SUMPRODUCT(SUMIFS('Raw counts'!R:R,'Raw counts'!$A:$A,$B59:$B61)) -> 6726 | T14: =SUMPRODUCT(SUMIFS('Raw counts'!S:S,'Raw counts'!$A:$A,$B59:$B61)) -> 3639 | U14: =SUMPRODUCT(SUMIFS('Raw counts'!T:T,'Raw counts'!$A:$A,$B59:$B61)) -> 2722 | W14: =_xlfn.T.TEST(F14:O14,P14:U14,2,2) -> 0.21679415 | X14: =AVERAGE(F14:O14) -> 3724.4 | Y14: =AVERAGE(P14:U14) -> 4705.3333
B16: 632 | C16: Dentate gyrus, granule cell layer | D16: 39600 | E16: 726
B17: 10703 | C17: Dentate gyrus, molecular layer | D17: 39400 | E17: 726
B18: 10704 | C18: Dentate gyrus, polymorph layer | D18: 39500 | E18: 726
B19: 2632 | C19: Dentate gyrus, granule cell layer ventral | D19: 39600 | E19: 2726
B20: 12703 | C20: Dentate gyrus, molecular layer | D20: 39400 | E20: 2726
B21: 12704 | C21: Dentate gyrus, subgranular zone ventral | D21: 39700 | E21: 2726
B22: 894 | C22: Retrosplenial area, lateral agranular part | D22: 25300 | E22: 254
B23: 274 | C23: Retrosplenial area, dorsal part, layer 6a | D23: 26400 | E23: 879
B24: 330 | C24: Retrosplenial area, dorsal part, layer 6b | D24: 26500 | E24: 879
B25: 434 | C25: Retrosplenial area, dorsal part, layer 2/3 | D25: 26100 | E25: 879
B26: 442 | C26: Retrosplenial area, dorsal part, layer 1 | D26: 26000 | E26: 879
B27: 545 | C27: Retrosplenial area, dorsal part, layer 4 | D27: 26200 | E27: 879
... B61: 451 | C61: Basolateral amygdalar nucleus, ventral part | D61: 47400 | E61: 295

Sheet Total-corrected counts Z<3
E1: 0 | F1: 0 | G1: 0 | H1: 0 | I1: 0 | J1: 0 | K1: 0 | L1: 0 | M1: 0 | N1: 0 | O1: 1 | P1: 1 | Q1: 1 | R1: 1 | S1: 1 | T1: 1
A2: id | B2: name | C2: structure_order | D2: parent_id | E2: 345391 | F2: 348028 | G2: 348030 | H2: 348035 | I2: 348465 | J2: 349038 | K2: 349438 | L2: 354044 | M2: 354519 | N2: 354522 | O2: 348034 | P2: 349022 | Q2: 349440 | R2: 350322 | S2: 350324 | T2: 354043 | U2: Filter | V2: Cluster | W2: T-test | X2: Gem 0 | Y2: Gem 1
A3: 0 | B3: background | C3: 0 | E3: =IFERROR(IF(OR(HLOOKUP($A3,'Z-scores'!$C$2:$SK$20,5,FALSE)>3,HLOOKUP($A3,'Z-scores'!$C$2:$SK$20,5,FALSE)<-3),"",'Total-corrected counts'!E3),"") | F3: =IFERROR(IF(OR(HLOOKUP($A3,'Z-scores'!$C$2:$SK$20,5,FALSE)>3,HLOOKUP($A3,'Z-scores'!$C$2:$SK$20,5,FALSE)<-3),"",'Total-corrected counts'!F3),"") | G3: =IFERROR(IF(OR(HLOOKUP($A3,'Z-scores'!$C$2:$SK$20,5,FALSE)>3,HLOOKUP($A3,'Z-scores'!$C$2:$SK$20,5,FALSE)<-3),"",'Total-corrected counts'!G3),"") | H3: =IFERROR(IF(OR(HLOOKUP($A3,'Z-scores'!$C$2:$SK$20,5,FALSE)>3,HLOOKUP($A3,'Z-scores'!$C$2:$SK$20,5,FALSE)<-3),"",'Total-corrected counts'!H3),"") | I3: =IFERROR(IF(OR(HLOOKUP($A3,'Z-scores'!$C$2:$SK$20,5,FALSE)>3,HLOOKUP($A3,'Z-scores'!$C$2:$SK$20,5,FALSE)<-3),"",'Total-corrected counts'!I3),"") | J3: =IFERROR(IF(OR(HLOOKUP($A3,'Z-scores'!$C$2:$SK$20,5,FALSE)>3,HLOOKUP($A3,'Z-scores'!$C$2:$SK$20,5,FALSE)<-3),"",'Total-corrected counts'!J3),"") | K3: =IFERROR(IF(OR(HLOOKUP($A3,'Z-scores'!$C$2:$SK$20,5,FALSE)>3,HLOOKUP($A3,'Z-scores'!$C$2:$SK$20,5,FALSE)<-3),"",'Total-corrected counts'!K3),"") | L3: =IFERROR(IF(OR(HLOOKUP($A3,'Z-scores'!$C$2:$SK$20,5,FALSE)>3,HLOOKUP($A3,'Z-scores'!$C$2:$SK$20,5,FALSE)<-3),"",'Total-corrected counts'!L3),"") | ... T3: =IFERROR(IF(OR(HLOOKUP($A3,'Z-scores'!$C$2:$SK$20,5,FALSE)>3,HLOOKUP($A3,'Z-scores'!$C$2:$SK$20,5,FALSE)<-3),"",'Total-corrected counts'!T3),"") | U3: =IFERROR(IF(X3-Y3=0,0,1),0) -> 0 | V3: =SUMIFS(Tabel132[Cluster],Tabel132[ID],'Total-corrected counts Z<3'!A3) -> 0 | W3: =IFERROR(_xlfn.T.TEST(E3:N3,O3:T3,2,2),"") | X3: =IFERROR(AVERAGE(E3:N3),"") | Y3: =IFERROR(AVERAGE(O3:T3),"")
