Workbook

Sheet Activation map
E1: Group | F1: 0 | G1: 0 | H1: 0 | I1: 0 | J1: 0 | K1: 0 | L1: 0 | M1: 0 | N1: 0 | O1: 1 | P1: 1 | Q1: 1 | R1: 1 | S1: 1 | T1: 1 | U1: 1 | V1: 1
A2: region | B2: id | C2: name | D2: structure_order | E2: parent_id | F2: 124 | G2: 143 | H2: 146 | I2: 152 | J2: 170 | K2: 171 | L2: 175 | M2: 183 | N2: 200 | O2: 113 | P2: 172 | Q2: 177 | R2: 178 | S2: 179 | T2: 180 | U2: 184 | V2: 207 | X2: T-test | Y2: Gem 0 | Z2: Gem 1
A3: dCA1 | B3: 382 | C3: Field CA1 | D3: 37700 | E3: 375 | F3: =SUMIFS(#REF!,#REF!,'Activation map'!$B3) -> #VALUE! | G3: =SUMIFS(#REF!,#REF!,'Activation map'!$B3) -> #VALUE! | H3: =SUMIFS(#REF!,#REF!,'Activation map'!$B3) -> #VALUE! | I3: =SUMIFS(#REF!,#REF!,'Activation map'!$B3) -> #VALUE! | J3: =SUMIFS(#REF!,#REF!,'Activation map'!$B3) -> #VALUE! | K3: =SUMIFS(#REF!,#REF!,'Activation map'!$B3) -> #VALUE! | L3: =SUMIFS(#REF!,#REF!,'Activation map'!$B3) -> #VALUE! | M3: =SUMIFS(#REF!,#REF!,'Activation map'!$B3) -> #VALUE! | ... V3: =SUMIFS(#REF!,#REF!,'Activation map'!$B3) -> #VALUE! | X3: =_xlfn.T.TEST(F3:N3,O3:V3,2,2) -> #VALUE! | Y3: =AVERAGE(F3:N3) -> #VALUE! | Z3: =AVERAGE(O3:V3) -> #VALUE!
A4: dCA3 | B4: 463 | C4: Field CA3 | D4: 38700 | E4: 375 | F4: =SUMIFS(#REF!,#REF!,'Activation map'!$B4) -> #VALUE! | G4: =SUMIFS(#REF!,#REF!,'Activation map'!$B4) -> #VALUE! | H4: =SUMIFS(#REF!,#REF!,'Activation map'!$B4) -> #VALUE! | I4: =SUMIFS(#REF!,#REF!,'Activation map'!$B4) -> #VALUE! | J4: =SUMIFS(#REF!,#REF!,'Activation map'!$B4) -> #VALUE! | K4: =SUMIFS(#REF!,#REF!,'Activation map'!$B4) -> #VALUE! | L4: =SUMIFS(#REF!,#REF!,'Activation map'!$B4) -> #VALUE! | M4: =SUMIFS(#REF!,#REF!,'Activation map'!$B4) -> #VALUE! | ... V4: =SUMIFS(#REF!,#REF!,'Activation map'!$B4) -> #VALUE! | X4: =_xlfn.T.TEST(F4:N4,O4:V4,2,2) -> #VALUE! | Y4: =AVERAGE(F4:N4) -> #VALUE! | Z4: =AVERAGE(O4:V4) -> #VALUE!
A5: dDG | C5: Dentate gyrus | E5: 726 | F5: =SUMPRODUCT(SUMIFS(#REF!,#REF!,$B16:$B18)) -> #VALUE! | G5: =SUMPRODUCT(SUMIFS(#REF!,#REF!,$B16:$B18)) -> #VALUE! | H5: =SUMPRODUCT(SUMIFS(#REF!,#REF!,$B16:$B18)) -> #VALUE! | I5: =SUMPRODUCT(SUMIFS(#REF!,#REF!,$B16:$B18)) -> #VALUE! | J5: =SUMPRODUCT(SUMIFS(#REF!,#REF!,$B16:$B18)) -> #VALUE! | K5: =SUMPRODUCT(SUMIFS(#REF!,#REF!,$B16:$B18)) -> #VALUE! | L5: =SUMPRODUCT(SUMIFS(#REF!,#REF!,$B16:$B18)) -> #VALUE! | M5: =SUMPRODUCT(SUMIFS(#REF!,#REF!,$B16:$B18)) -> #VALUE! | ... V5: =SUMPRODUCT(SUMIFS(#REF!,#REF!,$B16:$B18)) -> #VALUE! | X5: =_xlfn.T.TEST(F5:N5,O5:V5,2,2) -> #VALUE! | Y5: =AVERAGE(F5:N5) -> #VALUE! | Z5: =AVERAGE(O5:V5) -> #VALUE!
A6: vCA1 | B6: 2382 | C6: Field CA1 ventral | D6: 37700 | E6: 2375 | F6: =SUMIFS(#REF!,#REF!,'Activation map'!$B6) -> #VALUE! | G6: =SUMIFS(#REF!,#REF!,'Activation map'!$B6) -> #VALUE! | H6: =SUMIFS(#REF!,#REF!,'Activation map'!$B6) -> #VALUE! | I6: =SUMIFS(#REF!,#REF!,'Activation map'!$B6) -> #VALUE! | J6: =SUMIFS(#REF!,#REF!,'Activation map'!$B6) -> #VALUE! | K6: =SUMIFS(#REF!,#REF!,'Activation map'!$B6) -> #VALUE! | L6: =SUMIFS(#REF!,#REF!,'Activation map'!$B6) -> #VALUE! | M6: =SUMIFS(#REF!,#REF!,'Activation map'!$B6) -> #VALUE! | ... V6: =SUMIFS(#REF!,#REF!,'Activation map'!$B6) -> #VALUE! | X6: =_xlfn.T.TEST(F6:N6,O6:V6,2,2) -> #VALUE! | Y6: =AVERAGE(F6:N6) -> #VALUE! | Z6: =AVERAGE(O6:V6) -> #VALUE!
A7: vCA3 | B7: 2463 | C7: Field CA3 ventral | D7: 38700 | E7: 2375 | F7: =SUMIFS(#REF!,#REF!,'Activation map'!$B7) -> #VALUE! | G7: =SUMIFS(#REF!,#REF!,'Activation map'!$B7) -> #VALUE! | H7: =SUMIFS(#REF!,#REF!,'Activation map'!$B7) -> #VALUE! | I7: =SUMIFS(#REF!,#REF!,'Activation map'!$B7) -> #VALUE! | J7: =SUMIFS(#REF!,#REF!,'Activation map'!$B7) -> #VALUE! | K7: =SUMIFS(#REF!,#REF!,'Activation map'!$B7) -> #VALUE! | L7: =SUMIFS(#REF!,#REF!,'Activation map'!$B7) -> #VALUE! | M7: =SUMIFS(#REF!,#REF!,'Activation map'!$B7) -> #VALUE! | ... V7: =SUMIFS(#REF!,#REF!,'Activation map'!$B7) -> #VALUE! | X7: =_xlfn.T.TEST(F7:N7,O7:V7,2,2) -> #VALUE! | Y7: =AVERAGE(F7:N7) -> #VALUE! | Z7: =AVERAGE(O7:V7) -> #VALUE!
A8: vDG | C8: Dentate gyrus ventral | E8: 2726 | F8: =SUMPRODUCT(SUMIFS(#REF!,#REF!,$B19:$B21)) -> #VALUE! | G8: =SUMPRODUCT(SUMIFS(#REF!,#REF!,$B19:$B21)) -> #VALUE! | H8: =SUMPRODUCT(SUMIFS(#REF!,#REF!,$B19:$B21)) -> #VALUE! | I8: =SUMPRODUCT(SUMIFS(#REF!,#REF!,$B19:$B21)) -> #VALUE! | J8: =SUMPRODUCT(SUMIFS(#REF!,#REF!,$B19:$B21)) -> #VALUE! | K8: =SUMPRODUCT(SUMIFS(#REF!,#REF!,$B19:$B21)) -> #VALUE! | L8: =SUMPRODUCT(SUMIFS(#REF!,#REF!,$B19:$B21)) -> #VALUE! | M8: =SUMPRODUCT(SUMIFS(#REF!,#REF!,$B19:$B21)) -> #VALUE! | ... V8: =SUMPRODUCT(SUMIFS(#REF!,#REF!,$B19:$B21)) -> #VALUE! | X8: =_xlfn.T.TEST(F8:N8,O8:V8,2,2) -> #VALUE! | Y8: =AVERAGE(F8:N8) -> #VALUE! | Z8: =AVERAGE(O8:V8) -> #VALUE!
A9: RSP | C9: Retrosplenial area | F9: =SUMPRODUCT(SUMIFS(#REF!,#REF!,$B22:$B38)) -> #VALUE! | G9: =SUMPRODUCT(SUMIFS(#REF!,#REF!,$B22:$B38)) -> #VALUE! | H9: =SUMPRODUCT(SUMIFS(#REF!,#REF!,$B22:$B38)) -> #VALUE! | I9: =SUMPRODUCT(SUMIFS(#REF!,#REF!,$B22:$B38)) -> #VALUE! | J9: =SUMPRODUCT(SUMIFS(#REF!,#REF!,$B22:$B38)) -> #VALUE! | K9: =SUMPRODUCT(SUMIFS(#REF!,#REF!,$B22:$B38)) -> #VALUE! | L9: =SUMPRODUCT(SUMIFS(#REF!,#REF!,$B22:$B38)) -> #VALUE! | M9: =SUMPRODUCT(SUMIFS(#REF!,#REF!,$B22:$B38)) -> #VALUE! | ... V9: =SUMPRODUCT(SUMIFS(#REF!,#REF!,$B22:$B38)) -> #VALUE! | X9: =_xlfn.T.TEST(F9:N9,O9:V9,2,2) -> #VALUE! | Y9: =AVERAGE(F9:N9) -> #VALUE! | Z9: =AVERAGE(O9:V9) -> #VALUE!
A10: ACC | C10: Anterior cingulate area | F10: =SUMPRODUCT(SUMIFS(#REF!,#REF!,$B39:$B48)) -> #VALUE! | G10: =SUMPRODUCT(SUMIFS(#REF!,#REF!,$B39:$B48)) -> #VALUE! | H10: =SUMPRODUCT(SUMIFS(#REF!,#REF!,$B39:$B48)) -> #VALUE! | I10: =SUMPRODUCT(SUMIFS(#REF!,#REF!,$B39:$B48)) -> #VALUE! | J10: =SUMPRODUCT(SUMIFS(#REF!,#REF!,$B39:$B48)) -> #VALUE! | K10: =SUMPRODUCT(SUMIFS(#REF!,#REF!,$B39:$B48)) -> #VALUE! | L10: =SUMPRODUCT(SUMIFS(#REF!,#REF!,$B39:$B48)) -> #VALUE! | M10: =SUMPRODUCT(SUMIFS(#REF!,#REF!,$B39:$B48)) -> #VALUE! | ... V10: =SUMPRODUCT(SUMIFS(#REF!,#REF!,$B39:$B48)) -> #VALUE! | X10: =_xlfn.T.TEST(F10:N10,O10:V10,2,2) -> #VALUE! | Y10: =AVERAGE(F10:N10) -> #VALUE! | Z10: =AVERAGE(O10:V10) -> #VALUE!
A11: PL | C11: Prelimbic area | E11: 972 | F11: =SUMPRODUCT(SUMIFS(#REF!,#REF!,$B49:$B53)) -> #VALUE! | G11: =SUMPRODUCT(SUMIFS(#REF!,#REF!,$B49:$B53)) -> #VALUE! | H11: =SUMPRODUCT(SUMIFS(#REF!,#REF!,$B49:$B53)) -> #VALUE! | I11: =SUMPRODUCT(SUMIFS(#REF!,#REF!,$B49:$B53)) -> #VALUE! | J11: =SUMPRODUCT(SUMIFS(#REF!,#REF!,$B49:$B53)) -> #VALUE! | K11: =SUMPRODUCT(SUMIFS(#REF!,#REF!,$B49:$B53)) -> #VALUE! | L11: =SUMPRODUCT(SUMIFS(#REF!,#REF!,$B49:$B53)) -> #VALUE! | M11: =SUMPRODUCT(SUMIFS(#REF!,#REF!,$B49:$B53)) -> #VALUE! | ... V11: =SUMPRODUCT(SUMIFS(#REF!,#REF!,$B49:$B53)) -> #VALUE! | X11: =_xlfn.T.TEST(F11:N11,O11:V11,2,2) -> #VALUE! | Y11: =AVERAGE(F11:N11) -> #VALUE! | Z11: =AVERAGE(O11:V11) -> #VALUE!
A12: IL | C12: Infralimbic area | E12: 44 | F12: =SUMPRODUCT(SUMIFS(#REF!,#REF!,$B54:$B58)) -> #VALUE! | G12: =SUMPRODUCT(SUMIFS(#REF!,#REF!,$B54:$B58)) -> #VALUE! | H12: =SUMPRODUCT(SUMIFS(#REF!,#REF!,$B54:$B58)) -> #VALUE! | I12: =SUMPRODUCT(SUMIFS(#REF!,#REF!,$B54:$B58)) -> #VALUE! | J12: =SUMPRODUCT(SUMIFS(#REF!,#REF!,$B54:$B58)) -> #VALUE! | K12: =SUMPRODUCT(SUMIFS(#REF!,#REF!,$B54:$B58)) -> #VALUE! | L12: =SUMPRODUCT(SUMIFS(#REF!,#REF!,$B54:$B58)) -> #VALUE! | M12: =SUMPRODUCT(SUMIFS(#REF!,#REF!,$B54:$B58)) -> #VALUE! | ... V12: =SUMPRODUCT(SUMIFS(#REF!,#REF!,$B54:$B58)) -> #VALUE! | X12: =_xlfn.T.TEST(F12:N12,O12:V12,2,2) -> #VALUE! | Y12: =AVERAGE(F12:N12) -> #VALUE! | Z12: =AVERAGE(O12:V12) -> #VALUE!
A13: CeA | B13: 536 | C13: Central amygdalar nucleus | D13: 50300 | E13: 278 | F13: =SUMIFS(#REF!,#REF!,'Activation map'!$B13) -> #VALUE! | G13: =SUMIFS(#REF!,#REF!,'Activation map'!$B13) -> #VALUE! | H13: =SUMIFS(#REF!,#REF!,'Activation map'!$B13) -> #VALUE! | I13: =SUMIFS(#REF!,#REF!,'Activation map'!$B13) -> #VALUE! | J13: =SUMIFS(#REF!,#REF!,'Activation map'!$B13) -> #VALUE! | K13: =SUMIFS(#REF!,#REF!,'Activation map'!$B13) -> #VALUE! | L13: =SUMIFS(#REF!,#REF!,'Activation map'!$B13) -> #VALUE! | M13: =SUMIFS(#REF!,#REF!,'Activation map'!$B13) -> #VALUE! | ... V13: =SUMIFS(#REF!,#REF!,'Activation map'!$B13) -> #VALUE! | X13: =_xlfn.T.TEST(F13:N13,O13:V13,2,2) -> #VALUE! | Y13: =AVERAGE(F13:N13) -> #VALUE! | Z13: =AVERAGE(O13:V13) -> #VALUE!
A14: BLA | C14: Basolateral amygdalar nucleus | E14: 295 | F14: =SUMPRODUCT(SUMIFS(#REF!,#REF!,$B59:$B61)) -> #VALUE! | G14: =SUMPRODUCT(SUMIFS(#REF!,#REF!,$B59:$B61)) -> #VALUE! | H14: =SUMPRODUCT(SUMIFS(#REF!,#REF!,$B59:$B61)) -> #VALUE! | I14: =SUMPRODUCT(SUMIFS(#REF!,#REF!,$B59:$B61)) -> #VALUE! | J14: =SUMPRODUCT(SUMIFS(#REF!,#REF!,$B59:$B61)) -> #VALUE! | K14: =SUMPRODUCT(SUMIFS(#REF!,#REF!,$B59:$B61)) -> #VALUE! | L14: =SUMPRODUCT(SUMIFS(#REF!,#REF!,$B59:$B61)) -> #VALUE! | M14: =SUMPRODUCT(SUMIFS(#REF!,#REF!,$B59:$B61)) -> #VALUE! | ... V14: =SUMPRODUCT(SUMIFS(#REF!,#REF!,$B59:$B61)) -> #VALUE! | X14: =_xlfn.T.TEST(F14:N14,O14:V14,2,2) -> #VALUE! | Y14: =AVERAGE(F14:N14) -> #VALUE! | Z14: =AVERAGE(O14:V14) -> #VALUE!
B16: 632 | C16: Dentate gyrus, granule cell layer | D16: 39600 | E16: 726
B17: 10703 | C17: Dentate gyrus, molecular layer | D17: 39400 | E17: 726
B18: 10704 | C18: Dentate gyrus, polymorph layer | D18: 39500 | E18: 726
B19: 2632 | C19: Dentate gyrus, granule cell layer ventral | D19: 39600 | E19: 2726
B20: 12703 | C20: Dentate gyrus, molecular layer | D20: 39400 | E20: 2726
B21: 12704 | C21: Dentate gyrus, subgranular zone ventral | D21: 39700 | E21: 2726
B22: 894 | C22: Retrosplenial area, lateral agranular part | D22: 25300 | E22: 254
B23: 274 | C23: Retrosplenial area, dorsal part, layer 6a | D23: 26400 | E23: 879
B24: 330 | C24: Retrosplenial area, dorsal part, layer 6b | D24: 26500 | E24: 879
B25: 434 | C25: Retrosplenial area, dorsal part, layer 2/3 | D25: 26100 | E25: 879
B26: 442 | C26: Retrosplenial area, dorsal part, layer 1 | D26: 26000 | E26: 879
B27: 545 | C27: Retrosplenial area, dorsal part, layer 4 | D27: 26200 | E27: 879
... B61: 451 | C61: Basolateral amygdalar nucleus, ventral part | D61: 47400 | E61: 295

Sheet Total-corrected counts Z<2
E1: 0 | F1: 0 | G1: 0 | H1: 0 | I1: 0 | J1: 0 | K1: 0 | L1: 0 | M1: 0 | N1: 1 | O1: 1 | P1: 1 | Q1: 1 | R1: 1 | S1: 1 | T1: 1 | U1: 1
A2: id | B2: name | C2: structure_order | D2: parent_id | E2: 124 | F2: 143 | G2: 146 | H2: 152 | I2: 170 | J2: 171 | K2: 175 | L2: 183 | M2: 200 | N2: 113 | O2: 172 | P2: 177 | Q2: 178 | R2: 179 | S2: 180 | T2: 184 | U2: 207 | V2: Filter | W2: T-test | X2: Gem 0 | Y2: Gem 1
A3: 0 | B3: background | C3: 0 | E3: =IFERROR(IF(OR(HLOOKUP($A3,#REF!,3,FALSE())>2,HLOOKUP(A3,#REF!,3,FALSE())<-2),"",#REF!),"") | F3: =IFERROR(IF(OR(HLOOKUP($A3,#REF!,4,FALSE())>2,HLOOKUP($A3,#REF!,4,FALSE())<-2),"",#REF!),"") | G3: =IFERROR(IF(OR(HLOOKUP($A3,#REF!,5,FALSE())>2,HLOOKUP($A3,#REF!,5,FALSE())<-2),"",#REF!),"") | H3: =IFERROR(IF(OR(HLOOKUP($A3,#REF!,6,FALSE())>2,HLOOKUP($A3,#REF!,6,FALSE())<-2),"",#REF!),"") | I3: =IFERROR(IF(OR(HLOOKUP($A3,#REF!,7,FALSE())>2,HLOOKUP($A3,#REF!,7,FALSE())<-2),"",#REF!),"") | J3: =IFERROR(IF(OR(HLOOKUP($A3,#REF!,8,FALSE())>2,HLOOKUP($A3,#REF!,8,FALSE())<-2),"",#REF!),"") | K3: =IFERROR(IF(OR(HLOOKUP($A3,#REF!,9,FALSE())>2,HLOOKUP($A3,#REF!,9,FALSE())<-2),"",#REF!),"") | L3: =IFERROR(IF(OR(HLOOKUP($A3,#REF!,10,FALSE())>2,HLOOKUP($A3,#REF!,10,FALSE())<-2),"",#REF!),"") | M3: =IFERROR(IF(OR(HLOOKUP($A3,#REF!,11,FALSE())>2,HLOOKUP($A3,#REF!,11,FALSE())<-2),"",#REF!),"") | N3: =IFERROR(IF(OR(HLOOKUP($A3,#REF!,12,FALSE())>2,HLOOKUP($A3,#REF!,12,FALSE())<-2),"",#REF!),"") | O3: =IFERROR(IF(OR(HLOOKUP($A3,#REF!,13,FALSE())>2,HLOOKUP($A3,#REF!,13,FALSE())<-2),"",#REF!),"") | P3: =IFERROR(IF(OR(HLOOKUP($A3,#REF!,14,FALSE())>2,HLOOKUP($A3,#REF!,14,FALSE())<-2),"",#REF!),"") | Q3: =IFERROR(IF(OR(HLOOKUP($A3,#REF!,15,FALSE())>2,HLOOKUP($A3,#REF!,15,FALSE())<-2),"",#REF!),"") | R3: =IFERROR(IF(OR(HLOOKUP($A3,#REF!,16,FALSE())>2,HLOOKUP($A3,#REF!,16,FALSE())<-2),"",#REF!),"") | S3: =IFERROR(IF(OR(HLOOKUP($A3,#REF!,17,FALSE())>2,HLOOKUP($A3,#REF!,17,FALSE())<-2),"",#REF!),"") | T3: =IFERROR(IF(OR(HLOOKUP($A3,#REF!,18,FALSE())>2,HLOOKUP($A3,#REF!,18,FALSE())<-2),"",#REF!),"") | U3: =IFERROR(IF(OR(HLOOKUP($A3,#REF!,19,FALSE())>2,HLOOKUP($A3,#REF!,19,FALSE())<-2),"",#REF!),"") | V3: =IFERROR(IF(AND(X3=0,Y3=0),0,1),0) -> 1 | W3: =IFERROR(_xlfn.T.TEST(E3:M3,N3:U3,2,2),"") | X3: =IFERROR(AVERAGE(E3:M3),"") | Y3: =IFERROR(AVERAGE(N3:U3),"")
A4: 1 | B4: Tuberomammillary nucleus, ventral part | C4: 75500 | D4: 557 | E4: =IFERROR(IF(OR(HLOOKUP($A4,#REF!,3,FALSE())>2,HLOOKUP(A4,#REF!,3,FALSE())<-2),"",#REF!),"") | F4: =IFERROR(IF(OR(HLOOKUP($A4,#REF!,4,FALSE())>2,HLOOKUP($A4,#REF!,4,FALSE())<-2),"",#REF!),"") | G4: =IFERROR(IF(OR(HLOOKUP($A4,#REF!,5,FALSE())>2,HLOOKUP($A4,#REF!,5,FALSE())<-2),"",#REF!),"") | H4: =IFERROR(IF(OR(HLOOKUP($A4,#REF!,6,FALSE())>2,HLOOKUP($A4,#REF!,6,FALSE())<-2),"",#REF!),"") | I4: =IFERROR(IF(OR(HLOOKUP($A4,#REF!,7,FALSE())>2,HLOOKUP($A4,#REF!,7,FALSE())<-2),"",#REF!),"") | J4: =IFERROR(IF(OR(HLOOKUP($A4,#REF!,8,FALSE())>2,HLOOKUP($A4,#REF!,8,FALSE())<-2),"",#REF!),"") | K4: =IFERROR(IF(OR(HLOOKUP($A4,#REF!,9,FALSE())>2,HLOOKUP($A4,#REF!,9,FALSE())<-2),"",#REF!),"") | L4: =IFERROR(IF(OR(HLOOKUP($A4,#REF!,10,FALSE())>2,HLOOKUP($A4,#REF!,10,FALSE())<-2),"",#REF!),"") | M4: =IFERROR(IF(OR(HLOOKUP($A4,#REF!,11,FALSE())>2,HLOOKUP($A4,#REF!,11,FALSE())<-2),"",#REF!),"") | N4: =IFERROR(IF(OR(HLOOKUP($A4,#REF!,12,FALSE())>2,HLOOKUP($A4,#REF!,12,FALSE())<-2),"",#REF!),"") | O4: =IFERROR(IF(OR(HLOOKUP($A4,#REF!,13,FALSE())>2,HLOOKUP($A4,#REF!,13,FALSE())<-2),"",#REF!),"") | P4: =IFERROR(IF(OR(HLOOKUP($A4,#REF!,14,FALSE())>2,HLOOKUP($A4,#REF!,14,FALSE())<-2),"",#REF!),"") | Q4: =IFERROR(IF(OR(HLOOKUP($A4,#REF!,15,FALSE())>2,HLOOKUP($A4,#REF!,15,FALSE())<-2),"",#REF!),"") | R4: =IFERROR(IF(OR(HLOOKUP($A4,#REF!,16,FALSE())>2,HLOOKUP($A4,#REF!,16,FALSE())<-2),"",#REF!),"") | S4: =IFERROR(IF(OR(HLOOKUP($A4,#REF!,17,FALSE())>2,HLOOKUP($A4,#REF!,17,FALSE())<-2),"",#REF!),"") | T4: =IFERROR(IF(OR(HLOOKUP($A4,#REF!,18,FALSE())>2,HLOOKUP($A4,#REF!,18,FALSE())<-2),"",#REF!),"") | U4: =IFERROR(IF(OR(HLOOKUP($A4,#REF!,19,FALSE())>2,HLOOKUP($A4,#REF!,19,FALSE())<-2),"",#REF!),"") | V4: =IFERROR(IF(AND(X4=0,Y4=0),0,1),0) -> 1 | W4: =IFERROR(_xlfn.T.TEST(E4:M4,N4:U4,2,2),"") | X4: =IFERROR(AVERAGE(E4:M4),"") | Y4: =IFERROR(AVERAGE(N4:U4),"")
A5: 2 | B5: Primary somatosensory area, mouth, layer 6b | C5: 6200 | D5: 345 | E5: =IFERROR(IF(OR(HLOOKUP($A5,#REF!,3,FALSE())>2,HLOOKUP(A5,#REF!,3,FALSE())<-2),"",#REF!),"") | F5: =IFERROR(IF(OR(HLOOKUP($A5,#REF!,4,FALSE())>2,HLOOKUP($A5,#REF!,4,FALSE())<-2),"",#REF!),"") | G5: =IFERROR(IF(OR(HLOOKUP($A5,#REF!,5,FALSE())>2,HLOOKUP($A5,#REF!,5,FALSE())<-2),"",#REF!),"") | H5: =IFERROR(IF(OR(HLOOKUP($A5,#REF!,6,FALSE())>2,HLOOKUP($A5,#REF!,6,FALSE())<-2),"",#REF!),"") | I5: =IFERROR(IF(OR(HLOOKUP($A5,#REF!,7,FALSE())>2,HLOOKUP($A5,#REF!,7,FALSE())<-2),"",#REF!),"") | J5: =IFERROR(IF(OR(HLOOKUP($A5,#REF!,8,FALSE())>2,HLOOKUP($A5,#REF!,8,FALSE())<-2),"",#REF!),"") | K5: =IFERROR(IF(OR(HLOOKUP($A5,#REF!,9,FALSE())>2,HLOOKUP($A5,#REF!,9,FALSE())<-2),"",#REF!),"") | L5: =IFERROR(IF(OR(HLOOKUP($A5,#REF!,10,FALSE())>2,HLOOKUP($A5,#REF!,10,FALSE())<-2),"",#REF!),"") | M5: =IFERROR(IF(OR(HLOOKUP($A5,#REF!,11,FALSE())>2,HLOOKUP($A5,#REF!,11,FALSE())<-2),"",#REF!),"") | N5: =IFERROR(IF(OR(HLOOKUP($A5,#REF!,12,FALSE())>2,HLOOKUP($A5,#REF!,12,FALSE())<-2),"",#REF!),"") | O5: =IFERROR(IF(OR(HLOOKUP($A5,#REF!,13,FALSE())>2,HLOOKUP($A5,#REF!,13,FALSE())<-2),"",#REF!),"") | P5: =IFERROR(IF(OR(HLOOKUP($A5,#REF!,14,FALSE())>2,HLOOKUP($A5,#REF!,14,FALSE())<-2),"",#REF!),"") | Q5: =IFERROR(IF(OR(HLOOKUP($A5,#REF!,15,FALSE())>2,HLOOKUP($A5,#REF!,15,FALSE())<-2),"",#REF!),"") | R5: =IFERROR(IF(OR(HLOOKUP($A5,#REF!,16,FALSE())>2,HLOOKUP($A5,#REF!,16,FALSE())<-2),"",#REF!),"") | S5: =IFERROR(IF(OR(HLOOKUP($A5,#REF!,17,FALSE())>2,HLOOKUP($A5,#REF!,17,FALSE())<-2),"",#REF!),"") | T5: =IFERROR(IF(OR(HLOOKUP($A5,#REF!,18,FALSE())>2,HLOOKUP($A5,#REF!,18,FALSE())<-2),"",#REF!),"") | U5: =IFERROR(IF(OR(HLOOKUP($A5,#REF!,19,FALSE())>2,HLOOKUP($A5,#REF!,19,FALSE())<-2),"",#REF!),"") | V5: =IFERROR(IF(AND(X5=0,Y5=0),0,1),0) -> 1 | W5: =IFERROR(_xlfn.T.TEST(E5:M5,N5:U5,2,2),"") | X5: =IFERROR(AVERAGE(E5:M5),"") | Y5: =IFERROR(AVERAGE(N5:U5),"")
A6: 3 | B6: secondary fissure | C6: 118200 | D6: 1040 | E6: =IFERROR(IF(OR(HLOOKUP($A6,#REF!,3,FALSE())>2,HLOOKUP(A6,#REF!,3,FALSE())<-2),"",#REF!),"") | F6: =IFERROR(IF(OR(HLOOKUP($A6,#REF!,4,FALSE())>2,HLOOKUP($A6,#REF!,4,FALSE())<-2),"",#REF!),"") | G6: =IFERROR(IF(OR(HLOOKUP($A6,#REF!,5,FALSE())>2,HLOOKUP($A6,#REF!,5,FALSE())<-2),"",#REF!),"") | H6: =IFERROR(IF(OR(HLOOKUP($A6,#REF!,6,FALSE())>2,HLOOKUP($A6,#REF!,6,FALSE())<-2),"",#REF!),"") | I6: =IFERROR(IF(OR(HLOOKUP($A6,#REF!,7,FALSE())>2,HLOOKUP($A6,#REF!,7,FALSE())<-2),"",#REF!),"") | J6: =IFERROR(IF(OR(HLOOKUP($A6,#REF!,8,FALSE())>2,HLOOKUP($A6,#REF!,8,FALSE())<-2),"",#REF!),"") | K6: =IFERROR(IF(OR(HLOOKUP($A6,#REF!,9,FALSE())>2,HLOOKUP($A6,#REF!,9,FALSE())<-2),"",#REF!),"") | L6: =IFERROR(IF(OR(HLOOKUP($A6,#REF!,10,FALSE())>2,HLOOKUP($A6,#REF!,10,FALSE())<-2),"",#REF!),"") | M6: =IFERROR(IF(OR(HLOOKUP($A6,#REF!,11,FALSE())>2,HLOOKUP($A6,#REF!,11,FALSE())<-2),"",#REF!),"") | N6: =IFERROR(IF(OR(HLOOKUP($A6,#REF!,12,FALSE())>2,HLOOKUP($A6,#REF!,12,FALSE())<-2),"",#REF!),"") | O6: =IFERROR(IF(OR(HLOOKUP($A6,#REF!,13,FALSE())>2,HLOOKUP($A6,#REF!,13,FALSE())<-2),"",#REF!),"") | P6: =IFERROR(IF(OR(HLOOKUP($A6,#REF!,14,FALSE())>2,HLOOKUP($A6,#REF!,14,FALSE())<-2),"",#REF!),"") | Q6: =IFERROR(IF(OR(HLOOKUP($A6,#REF!,15,FALSE())>2,HLOOKUP($A6,#REF!,15,FALSE())<-2),"",#REF!),"") | R6: =IFERROR(IF(OR(HLOOKUP($A6,#REF!,16,FALSE())>2,HLOOKUP($A6,#REF!,16,FALSE())<-2),"",#REF!),"") | S6: =IFERROR(IF(OR(HLOOKUP($A6,#REF!,17,FALSE())>2,HLOOKUP($A6,#REF!,17,FALSE())<-2),"",#REF!),"") | T6: =IFERROR(IF(OR(HLOOKUP($A6,#REF!,18,FALSE())>2,HLOOKUP($A6,#REF!,18,FALSE())<-2),"",#REF!),"") | U6: =IFERROR(IF(OR(HLOOKUP($A6,#REF!,19,FALSE())>2,HLOOKUP($A6,#REF!,19,FALSE())<-2),"",#REF!),"") | V6: =IFERROR(IF(AND(X6=0,Y6=0),0,1),0) -> 1 | W6: =IFERROR(_xlfn.T.TEST(E6:M6,N6:U6,2,2),"") | X6: =IFERROR(AVERAGE(E6:M6),"") | Y6: =IFERROR(AVERAGE(N6:U6),"")
A7: 4 | B7: Inferior colliculus | C7: 79100 | D7: 339 | E7: =IFERROR(IF(OR(HLOOKUP($A7,#REF!,3,FALSE())>2,HLOOKUP(A7,#REF!,3,FALSE())<-2),"",#REF!),"") | F7: =IFERROR(IF(OR(HLOOKUP($A7,#REF!,4,FALSE())>2,HLOOKUP($A7,#REF!,4,FALSE())<-2),"",#REF!),"") | G7: =IFERROR(IF(OR(HLOOKUP($A7,#REF!,5,FALSE())>2,HLOOKUP($A7,#REF!,5,FALSE())<-2),"",#REF!),"") | H7: =IFERROR(IF(OR(HLOOKUP($A7,#REF!,6,FALSE())>2,HLOOKUP($A7,#REF!,6,FALSE())<-2),"",#REF!),"") | I7: =IFERROR(IF(OR(HLOOKUP($A7,#REF!,7,FALSE())>2,HLOOKUP($A7,#REF!,7,FALSE())<-2),"",#REF!),"") | J7: =IFERROR(IF(OR(HLOOKUP($A7,#REF!,8,FALSE())>2,HLOOKUP($A7,#REF!,8,FALSE())<-2),"",#REF!),"") | K7: =IFERROR(IF(OR(HLOOKUP($A7,#REF!,9,FALSE())>2,HLOOKUP($A7,#REF!,9,FALSE())<-2),"",#REF!),"") | L7: =IFERROR(IF(OR(HLOOKUP($A7,#REF!,10,FALSE())>2,HLOOKUP($A7,#REF!,10,FALSE())<-2),"",#REF!),"") | M7: =IFERROR(IF(OR(HLOOKUP($A7,#REF!,11,FALSE())>2,HLOOKUP($A7,#REF!,11,FALSE())<-2),"",#REF!),"") | N7: =IFERROR(IF(OR(HLOOKUP($A7,#REF!,12,FALSE())>2,HLOOKUP($A7,#REF!,12,FALSE())<-2),"",#REF!),"") | O7: =IFERROR(IF(OR(HLOOKUP($A7,#REF!,13,FALSE())>2,HLOOKUP($A7,#REF!,13,FALSE())<-2),"",#REF!),"") | P7: =IFERROR(IF(OR(HLOOKUP($A7,#REF!,14,FALSE())>2,HLOOKUP($A7,#REF!,14,FALSE())<-2),"",#REF!),"") | Q7: =IFERROR(IF(OR(HLOOKUP($A7,#REF!,15,FALSE())>2,HLOOKUP($A7,#REF!,15,FALSE())<-2),"",#REF!),"") | R7: =IFERROR(IF(OR(HLOOKUP($A7,#REF!,16,FALSE())>2,HLOOKUP($A7,#REF!,16,FALSE())<-2),"",#REF!),"") | S7: =IFERROR(IF(OR(HLOOKUP($A7,#REF!,17,FALSE())>2,HLOOKUP($A7,#REF!,17,FALSE())<-2),"",#REF!),"") | T7: =IFERROR(IF(OR(HLOOKUP($A7,#REF!,18,FALSE())>2,HLOOKUP($A7,#REF!,18,FALSE())<-2),"",#REF!),"") | U7: =IFERROR(IF(OR(HLOOKUP($A7,#REF!,19,FALSE())>2,HLOOKUP($A7,#REF!,19,FALSE())<-2),"",#REF!),"") | V7: =IFERROR(IF(AND(X7=0,Y7=0),0,1),0) -> 1 | W7: =IFERROR(_xlfn.T.TEST(E7:M7,N7:U7,2,2),"") | X7: =IFERROR(AVERAGE(E7:M7),"") | Y7: =IFERROR(AVERAGE(N7:U7),"")
A8: 6 | B8: internal capsule | C8: 107000 | D8: 784 | E8: =IFERROR(IF(OR(HLOOKUP($A8,#REF!,3,FALSE())>2,HLOOKUP(A8,#REF!,3,FALSE())<-2),"",#REF!),"") | F8: =IFERROR(IF(OR(HLOOKUP($A8,#REF!,4,FALSE())>2,HLOOKUP($A8,#REF!,4,FALSE())<-2),"",#REF!),"") | G8: =IFERROR(IF(OR(HLOOKUP($A8,#REF!,5,FALSE())>2,HLOOKUP($A8,#REF!,5,FALSE())<-2),"",#REF!),"") | H8: =IFERROR(IF(OR(HLOOKUP($A8,#REF!,6,FALSE())>2,HLOOKUP($A8,#REF!,6,FALSE())<-2),"",#REF!),"") | I8: =IFERROR(IF(OR(HLOOKUP($A8,#REF!,7,FALSE())>2,HLOOKUP($A8,#REF!,7,FALSE())<-2),"",#REF!),"") | J8: =IFERROR(IF(OR(HLOOKUP($A8,#REF!,8,FALSE())>2,HLOOKUP($A8,#REF!,8,FALSE())<-2),"",#REF!),"") | K8: =IFERROR(IF(OR(HLOOKUP($A8,#REF!,9,FALSE())>2,HLOOKUP($A8,#REF!,9,FALSE())<-2),"",#REF!),"") | L8: =IFERROR(IF(OR(HLOOKUP($A8,#REF!,10,FALSE())>2,HLOOKUP($A8,#REF!,10,FALSE())<-2),"",#REF!),"") | M8: =IFERROR(IF(OR(HLOOKUP($A8,#REF!,11,FALSE())>2,HLOOKUP($A8,#REF!,11,FALSE())<-2),"",#REF!),"") | N8: =IFERROR(IF(OR(HLOOKUP($A8,#REF!,12,FALSE())>2,HLOOKUP($A8,#REF!,12,FALSE())<-2),"",#REF!),"") | O8: =IFERROR(IF(OR(HLOOKUP($A8,#REF!,13,FALSE())>2,HLOOKUP($A8,#REF!,13,FALSE())<-2),"",#REF!),"") | P8: =IFERROR(IF(OR(HLOOKUP($A8,#REF!,14,FALSE())>2,HLOOKUP($A8,#REF!,14,FALSE())<-2),"",#REF!),"") | Q8: =IFERROR(IF(OR(HLOOKUP($A8,#REF!,15,FALSE())>2,HLOOKUP($A8,#REF!,15,FALSE())<-2),"",#REF!),"") | R8: =IFERROR(IF(OR(HLOOKUP($A8,#REF!,16,FALSE())>2,HLOOKUP($A8,#REF!,16,FALSE())<-2),"",#REF!),"") | S8: =IFERROR(IF(OR(HLOOKUP($A8,#REF!,17,FALSE())>2,HLOOKUP($A8,#REF!,17,FALSE())<-2),"",#REF!),"") | T8: =IFERROR(IF(OR(HLOOKUP($A8,#REF!,18,FALSE())>2,HLOOKUP($A8,#REF!,18,FALSE())<-2),"",#REF!),"") | U8: =IFERROR(IF(OR(HLOOKUP($A8,#REF!,19,FALSE())>2,HLOOKUP($A8,#REF!,19,FALSE())<-2),"",#REF!),"") | V8: =IFERROR(IF(AND(X8=0,Y8=0),0,1),0) -> 1 | W8: =IFERROR(_xlfn.T.TEST(E8:M8,N8:U8,2,2),"") | X8: =IFERROR(AVERAGE(E8:M8),"") | Y8: =IFERROR(AVERAGE(N8:U8),"")
A9: 7 | B9: Principal sensory nucleus of the trigeminal | C9: 85300 | D9: 1132 | E9: =IFERROR(IF(OR(HLOOKUP($A9,#REF!,3,FALSE())>2,HLOOKUP(A9,#REF!,3,FALSE())<-2),"",#REF!),"") | F9: =IFERROR(IF(OR(HLOOKUP($A9,#REF!,4,FALSE())>2,HLOOKUP($A9,#REF!,4,FALSE())<-2),"",#REF!),"") | G9: =IFERROR(IF(OR(HLOOKUP($A9,#REF!,5,FALSE())>2,HLOOKUP($A9,#REF!,5,FALSE())<-2),"",#REF!),"") | H9: =IFERROR(IF(OR(HLOOKUP($A9,#REF!,6,FALSE())>2,HLOOKUP($A9,#REF!,6,FALSE())<-2),"",#REF!),"") | I9: =IFERROR(IF(OR(HLOOKUP($A9,#REF!,7,FALSE())>2,HLOOKUP($A9,#REF!,7,FALSE())<-2),"",#REF!),"") | J9: =IFERROR(IF(OR(HLOOKUP($A9,#REF!,8,FALSE())>2,HLOOKUP($A9,#REF!,8,FALSE())<-2),"",#REF!),"") | K9: =IFERROR(IF(OR(HLOOKUP($A9,#REF!,9,FALSE())>2,HLOOKUP($A9,#REF!,9,FALSE())<-2),"",#REF!),"") | L9: =IFERROR(IF(OR(HLOOKUP($A9,#REF!,10,FALSE())>2,HLOOKUP($A9,#REF!,10,FALSE())<-2),"",#REF!),"") | M9: =IFERROR(IF(OR(HLOOKUP($A9,#REF!,11,FALSE())>2,HLOOKUP($A9,#REF!,11,FALSE())<-2),"",#REF!),"") | N9: =IFERROR(IF(OR(HLOOKUP($A9,#REF!,12,FALSE())>2,HLOOKUP($A9,#REF!,12,FALSE())<-2),"",#REF!),"") | O9: =IFERROR(IF(OR(HLOOKUP($A9,#REF!,13,FALSE())>2,HLOOKUP($A9,#REF!,13,FALSE())<-2),"",#REF!),"") | P9: =IFERROR(IF(OR(HLOOKUP($A9,#REF!,14,FALSE())>2,HLOOKUP($A9,#REF!,14,FALSE())<-2),"",#REF!),"") | Q9: =IFERROR(IF(OR(HLOOKUP($A9,#REF!,15,FALSE())>2,HLOOKUP($A9,#REF!,15,FALSE())<-2),"",#REF!),"") | R9: =IFERROR(IF(OR(HLOOKUP($A9,#REF!,16,FALSE())>2,HLOOKUP($A9,#REF!,16,FALSE())<-2),"",#REF!),"") | S9: =IFERROR(IF(OR(HLOOKUP($A9,#REF!,17,FALSE())>2,HLOOKUP($A9,#REF!,17,FALSE())<-2),"",#REF!),"") | T9: =IFERROR(IF(OR(HLOOKUP($A9,#REF!,18,FALSE())>2,HLOOKUP($A9,#REF!,18,FALSE())<-2),"",#REF!),"") | U9: =IFERROR(IF(OR(HLOOKUP($A9,#REF!,19,FALSE())>2,HLOOKUP($A9,#REF!,19,FALSE())<-2),"",#REF!),"") | V9: =IFERROR(IF(AND(X9=0,Y9=0),0,1),0) -> 1 | W9: =IFERROR(_xlfn.T.TEST(E9:M9,N9:U9,2,2),"") | X9: =IFERROR(AVERAGE(E9:M9),"") | Y9: =IFERROR(AVERAGE(N9:U9),"")
A10: 8 | B10: Basic cell groups and regions | C10: 100 | D10: 997 | E10: =IFERROR(IF(OR(HLOOKUP($A10,#REF!,3,FALSE())>2,HLOOKUP(A10,#REF!,3,FALSE())<-2),"",#REF!),"") | F10: =IFERROR(IF(OR(HLOOKUP($A10,#REF!,4,FALSE())>2,HLOOKUP($A10,#REF!,4,FALSE())<-2),"",#REF!),"") | G10: =IFERROR(IF(OR(HLOOKUP($A10,#REF!,5,FALSE())>2,HLOOKUP($A10,#REF!,5,FALSE())<-2),"",#REF!),"") | H10: =IFERROR(IF(OR(HLOOKUP($A10,#REF!,6,FALSE())>2,HLOOKUP($A10,#REF!,6,FALSE())<-2),"",#REF!),"") | I10: =IFERROR(IF(OR(HLOOKUP($A10,#REF!,7,FALSE())>2,HLOOKUP($A10,#REF!,7,FALSE())<-2),"",#REF!),"") | J10: =IFERROR(IF(OR(HLOOKUP($A10,#REF!,8,FALSE())>2,HLOOKUP($A10,#REF!,8,FALSE())<-2),"",#REF!),"") | K10: =IFERROR(IF(OR(HLOOKUP($A10,#REF!,9,FALSE())>2,HLOOKUP($A10,#REF!,9,FALSE())<-2),"",#REF!),"") | L10: =IFERROR(IF(OR(HLOOKUP($A10,#REF!,10,FALSE())>2,HLOOKUP($A10,#REF!,10,FALSE())<-2),"",#REF!),"") | M10: =IFERROR(IF(OR(HLOOKUP($A10,#REF!,11,FALSE())>2,HLOOKUP($A10,#REF!,11,FALSE())<-2),"",#REF!),"") | N10: =IFERROR(IF(OR(HLOOKUP($A10,#REF!,12,FALSE())>2,HLOOKUP($A10,#REF!,12,FALSE())<-2),"",#REF!),"") | O10: =IFERROR(IF(OR(HLOOKUP($A10,#REF!,13,FALSE())>2,HLOOKUP($A10,#REF!,13,FALSE())<-2),"",#REF!),"") | P10: =IFERROR(IF(OR(HLOOKUP($A10,#REF!,14,FALSE())>2,HLOOKUP($A10,#REF!,14,FALSE())<-2),"",#REF!),"") | Q10: =IFERROR(IF(OR(HLOOKUP($A10,#REF!,15,FALSE())>2,HLOOKUP($A10,#REF!,15,FALSE())<-2),"",#REF!),"") | R10: =IFERROR(IF(OR(HLOOKUP($A10,#REF!,16,FALSE())>2,HLOOKUP($A10,#REF!,16,FALSE())<-2),"",#REF!),"") | S10: =IFERROR(IF(OR(HLOOKUP($A10,#REF!,17,FALSE())>2,HLOOKUP($A10,#REF!,17,FALSE())<-2),"",#REF!),"") | T10: =IFERROR(IF(OR(HLOOKUP($A10,#REF!,18,FALSE())>2,HLOOKUP($A10,#REF!,18,FALSE())<-2),"",#REF!),"") | U10: =IFERROR(IF(OR(HLOOKUP($A10,#REF!,19,FALSE())>2,HLOOKUP($A10,#REF!,19,FALSE())<-2),"",#REF!),"") | V10: =IFERROR(IF(AND(X10=0,Y10=0),0,1),0) -> 1 | W10: =IFERROR(_xlfn.T.TEST(E10:M10,N10:U10,2,2),"") | X10: =IFERROR(AVERAGE(E10:M10),"") | Y10: =IFERROR(AVERAGE(N10:U10),"")
A11: 9 | B11: Primary somatosensory area, trunk, layer 6a | C11: 7500 | D11: 361 | E11: =IFERROR(IF(OR(HLOOKUP($A11,#REF!,3,FALSE())>2,HLOOKUP(A11,#REF!,3,FALSE())<-2),"",#REF!),"") | F11: =IFERROR(IF(OR(HLOOKUP($A11,#REF!,4,FALSE())>2,HLOOKUP($A11,#REF!,4,FALSE())<-2),"",#REF!),"") | G11: =IFERROR(IF(OR(HLOOKUP($A11,#REF!,5,FALSE())>2,HLOOKUP($A11,#REF!,5,FALSE())<-2),"",#REF!),"") | H11: =IFERROR(IF(OR(HLOOKUP($A11,#REF!,6,FALSE())>2,HLOOKUP($A11,#REF!,6,FALSE())<-2),"",#REF!),"") | I11: =IFERROR(IF(OR(HLOOKUP($A11,#REF!,7,FALSE())>2,HLOOKUP($A11,#REF!,7,FALSE())<-2),"",#REF!),"") | J11: =IFERROR(IF(OR(HLOOKUP($A11,#REF!,8,FALSE())>2,HLOOKUP($A11,#REF!,8,FALSE())<-2),"",#REF!),"") | K11: =IFERROR(IF(OR(HLOOKUP($A11,#REF!,9,FALSE())>2,HLOOKUP($A11,#REF!,9,FALSE())<-2),"",#REF!),"") | L11: =IFERROR(IF(OR(HLOOKUP($A11,#REF!,10,FALSE())>2,HLOOKUP($A11,#REF!,10,FALSE())<-2),"",#REF!),"") | M11: =IFERROR(IF(OR(HLOOKUP($A11,#REF!,11,FALSE())>2,HLOOKUP($A11,#REF!,11,FALSE())<-2),"",#REF!),"") | N11: =IFERROR(IF(OR(HLOOKUP($A11,#REF!,12,FALSE())>2,HLOOKUP($A11,#REF!,12,FALSE())<-2),"",#REF!),"") | O11: =IFERROR(IF(OR(HLOOKUP($A11,#REF!,13,FALSE())>2,HLOOKUP($A11,#REF!,13,FALSE())<-2),"",#REF!),"") | P11: =IFERROR(IF(OR(HLOOKUP($A11,#REF!,14,FALSE())>2,HLOOKUP($A11,#REF!,14,FALSE())<-2),"",#REF!),"") | Q11: =IFERROR(IF(OR(HLOOKUP($A11,#REF!,15,FALSE())>2,HLOOKUP($A11,#REF!,15,FALSE())<-2),"",#REF!),"") | R11: =IFERROR(IF(OR(HLOOKUP($A11,#REF!,16,FALSE())>2,HLOOKUP($A11,#REF!,16,FALSE())<-2),"",#REF!),"") | S11: =IFERROR(IF(OR(HLOOKUP($A11,#REF!,17,FALSE())>2,HLOOKUP($A11,#REF!,17,FALSE())<-2),"",#REF!),"") | T11: =IFERROR(IF(OR(HLOOKUP($A11,#REF!,18,FALSE())>2,HLOOKUP($A11,#REF!,18,FALSE())<-2),"",#REF!),"") | U11: =IFERROR(IF(OR(HLOOKUP($A11,#REF!,19,FALSE())>2,HLOOKUP($A11,#REF!,19,FALSE())<-2),"",#REF!),"") | V11: =IFERROR(IF(AND(X11=0,Y11=0),0,1),0) -> 1 | W11: =IFERROR(_xlfn.T.TEST(E11:M11,N11:U11,2,2),"") | X11: =IFERROR(AVERAGE(E11:M11),"") | Y11: =IFERROR(AVERAGE(N11:U11),"")
A12: 10 | B12: Superior colliculus, motor related, intermediate gray layer | C12: 81100 | D12: 294 | E12: =IFERROR(IF(OR(HLOOKUP($A12,#REF!,3,FALSE())>2,HLOOKUP(A12,#REF!,3,FALSE())<-2),"",#REF!),"") | F12: =IFERROR(IF(OR(HLOOKUP($A12,#REF!,4,FALSE())>2,HLOOKUP($A12,#REF!,4,FALSE())<-2),"",#REF!),"") | G12: =IFERROR(IF(OR(HLOOKUP($A12,#REF!,5,FALSE())>2,HLOOKUP($A12,#REF!,5,FALSE())<-2),"",#REF!),"") | H12: =IFERROR(IF(OR(HLOOKUP($A12,#REF!,6,FALSE())>2,HLOOKUP($A12,#REF!,6,FALSE())<-2),"",#REF!),"") | I12: =IFERROR(IF(OR(HLOOKUP($A12,#REF!,7,FALSE())>2,HLOOKUP($A12,#REF!,7,FALSE())<-2),"",#REF!),"") | J12: =IFERROR(IF(OR(HLOOKUP($A12,#REF!,8,FALSE())>2,HLOOKUP($A12,#REF!,8,FALSE())<-2),"",#REF!),"") | K12: =IFERROR(IF(OR(HLOOKUP($A12,#REF!,9,FALSE())>2,HLOOKUP($A12,#REF!,9,FALSE())<-2),"",#REF!),"") | L12: =IFERROR(IF(OR(HLOOKUP($A12,#REF!,10,FALSE())>2,HLOOKUP($A12,#REF!,10,FALSE())<-2),"",#REF!),"") | M12: =IFERROR(IF(OR(HLOOKUP($A12,#REF!,11,FALSE())>2,HLOOKUP($A12,#REF!,11,FALSE())<-2),"",#REF!),"") | N12: =IFERROR(IF(OR(HLOOKUP($A12,#REF!,12,FALSE())>2,HLOOKUP($A12,#REF!,12,FALSE())<-2),"",#REF!),"") | O12: =IFERROR(IF(OR(HLOOKUP($A12,#REF!,13,FALSE())>2,HLOOKUP($A12,#REF!,13,FALSE())<-2),"",#REF!),"") | P12: =IFERROR(IF(OR(HLOOKUP($A12,#REF!,14,FALSE())>2,HLOOKUP($A12,#REF!,14,FALSE())<-2),"",#REF!),"") | Q12: =IFERROR(IF(OR(HLOOKUP($A12,#REF!,15,FALSE())>2,HLOOKUP($A12,#REF!,15,FALSE())<-2),"",#REF!),"") | R12: =IFERROR(IF(OR(HLOOKUP($A12,#REF!,16,FALSE())>2,HLOOKUP($A12,#REF!,16,FALSE())<-2),"",#REF!),"") | S12: =IFERROR(IF(OR(HLOOKUP($A12,#REF!,17,FALSE())>2,HLOOKUP($A12,#REF!,17,FALSE())<-2),"",#REF!),"") | T12: =IFERROR(IF(OR(HLOOKUP($A12,#REF!,18,FALSE())>2,HLOOKUP($A12,#REF!,18,FALSE())<-2),"",#REF!),"") | U12: =IFERROR(IF(OR(HLOOKUP($A12,#REF!,19,FALSE())>2,HLOOKUP($A12,#REF!,19,FALSE())<-2),"",#REF!),"") | V12: =IFERROR(IF(AND(X12=0,Y12=0),0,1),0) -> 1 | W12: =IFERROR(_xlfn.T.TEST(E12:M12,N12:U12,2,2),"") | X12: =IFERROR(AVERAGE(E12:M12),"") | Y12: =IFERROR(AVERAGE(N12:U12),"")
A13: 11 | B13: posterolateral fissure | C13: 118300 | D13: 1040 | E13: =IFERROR(IF(OR(HLOOKUP($A13,#REF!,3,FALSE())>2,HLOOKUP(A13,#REF!,3,FALSE())<-2),"",#REF!),"") | F13: =IFERROR(IF(OR(HLOOKUP($A13,#REF!,4,FALSE())>2,HLOOKUP($A13,#REF!,4,FALSE())<-2),"",#REF!),"") | G13: =IFERROR(IF(OR(HLOOKUP($A13,#REF!,5,FALSE())>2,HLOOKUP($A13,#REF!,5,FALSE())<-2),"",#REF!),"") | H13: =IFERROR(IF(OR(HLOOKUP($A13,#REF!,6,FALSE())>2,HLOOKUP($A13,#REF!,6,FALSE())<-2),"",#REF!),"") | I13: =IFERROR(IF(OR(HLOOKUP($A13,#REF!,7,FALSE())>2,HLOOKUP($A13,#REF!,7,FALSE())<-2),"",#REF!),"") | J13: =IFERROR(IF(OR(HLOOKUP($A13,#REF!,8,FALSE())>2,HLOOKUP($A13,#REF!,8,FALSE())<-2),"",#REF!),"") | K13: =IFERROR(IF(OR(HLOOKUP($A13,#REF!,9,FALSE())>2,HLOOKUP($A13,#REF!,9,FALSE())<-2),"",#REF!),"") | L13: =IFERROR(IF(OR(HLOOKUP($A13,#REF!,10,FALSE())>2,HLOOKUP($A13,#REF!,10,FALSE())<-2),"",#REF!),"") | M13: =IFERROR(IF(OR(HLOOKUP($A13,#REF!,11,FALSE())>2,HLOOKUP($A13,#REF!,11,FALSE())<-2),"",#REF!),"") | N13: =IFERROR(IF(OR(HLOOKUP($A13,#REF!,12,FALSE())>2,HLOOKUP($A13,#REF!,12,FALSE())<-2),"",#REF!),"") | O13: =IFERROR(IF(OR(HLOOKUP($A13,#REF!,13,FALSE())>2,HLOOKUP($A13,#REF!,13,FALSE())<-2),"",#REF!),"") | P13: =IFERROR(IF(OR(HLOOKUP($A13,#REF!,14,FALSE())>2,HLOOKUP($A13,#REF!,14,FALSE())<-2),"",#REF!),"") | Q13: =IFERROR(IF(OR(HLOOKUP($A13,#REF!,15,FALSE())>2,HLOOKUP($A13,#REF!,15,FALSE())<-2),"",#REF!),"") | R13: =IFERROR(IF(OR(HLOOKUP($A13,#REF!,16,FALSE())>2,HLOOKUP($A13,#REF!,16,FALSE())<-2),"",#REF!),"") | S13: =IFERROR(IF(OR(HLOOKUP($A13,#REF!,17,FALSE())>2,HLOOKUP($A13,#REF!,17,FALSE())<-2),"",#REF!),"") | T13: =IFERROR(IF(OR(HLOOKUP($A13,#REF!,18,FALSE())>2,HLOOKUP($A13,#REF!,18,FALSE())<-2),"",#REF!),"") | U13: =IFERROR(IF(OR(HLOOKUP($A13,#REF!,19,FALSE())>2,HLOOKUP($A13,#REF!,19,FALSE())<-2),"",#REF!),"") | V13: =IFERROR(IF(AND(X13=0,Y13=0),0,1),0) -> 1 | W13: =IFERROR(_xlfn.T.TEST(E13:M13,N13:U13,2,2),"") | X13: =IFERROR(AVERAGE(E13:M13),"") | Y13: =IFERROR(AVERAGE(N13:U13),"")
A14: 12 | B14: Interfascicular nucleus raphÈ | C14: 84100 | D14: 165 | E14: =IFERROR(IF(OR(HLOOKUP($A14,#REF!,3,FALSE())>2,HLOOKUP(A14,#REF!,3,FALSE())<-2),"",#REF!),"") | F14: =IFERROR(IF(OR(HLOOKUP($A14,#REF!,4,FALSE())>2,HLOOKUP($A14,#REF!,4,FALSE())<-2),"",#REF!),"") | G14: =IFERROR(IF(OR(HLOOKUP($A14,#REF!,5,FALSE())>2,HLOOKUP($A14,#REF!,5,FALSE())<-2),"",#REF!),"") | H14: =IFERROR(IF(OR(HLOOKUP($A14,#REF!,6,FALSE())>2,HLOOKUP($A14,#REF!,6,FALSE())<-2),"",#REF!),"") | I14: =IFERROR(IF(OR(HLOOKUP($A14,#REF!,7,FALSE())>2,HLOOKUP($A14,#REF!,7,FALSE())<-2),"",#REF!),"") | J14: =IFERROR(IF(OR(HLOOKUP($A14,#REF!,8,FALSE())>2,HLOOKUP($A14,#REF!,8,FALSE())<-2),"",#REF!),"") | K14: =IFERROR(IF(OR(HLOOKUP($A14,#REF!,9,FALSE())>2,HLOOKUP($A14,#REF!,9,FALSE())<-2),"",#REF!),"") | L14: =IFERROR(IF(OR(HLOOKUP($A14,#REF!,10,FALSE())>2,HLOOKUP($A14,#REF!,10,FALSE())<-2),"",#REF!),"") | M14: =IFERROR(IF(OR(HLOOKUP($A14,#REF!,11,FALSE())>2,HLOOKUP($A14,#REF!,11,FALSE())<-2),"",#REF!),"") | N14: =IFERROR(IF(OR(HLOOKUP($A14,#REF!,12,FALSE())>2,HLOOKUP($A14,#REF!,12,FALSE())<-2),"",#REF!),"") | O14: =IFERROR(IF(OR(HLOOKUP($A14,#REF!,13,FALSE())>2,HLOOKUP($A14,#REF!,13,FALSE())<-2),"",#REF!),"") | P14: =IFERROR(IF(OR(HLOOKUP($A14,#REF!,14,FALSE())>2,HLOOKUP($A14,#REF!,14,FALSE())<-2),"",#REF!),"") | Q14: =IFERROR(IF(OR(HLOOKUP($A14,#REF!,15,FALSE())>2,HLOOKUP($A14,#REF!,15,FALSE())<-2),"",#REF!),"") | R14: =IFERROR(IF(OR(HLOOKUP($A14,#REF!,16,FALSE())>2,HLOOKUP($A14,#REF!,16,FALSE())<-2),"",#REF!),"") | S14: =IFERROR(IF(OR(HLOOKUP($A14,#REF!,17,FALSE())>2,HLOOKUP($A14,#REF!,17,FALSE())<-2),"",#REF!),"") | T14: =IFERROR(IF(OR(HLOOKUP($A14,#REF!,18,FALSE())>2,HLOOKUP($A14,#REF!,18,FALSE())<-2),"",#REF!),"") | U14: =IFERROR(IF(OR(HLOOKUP($A14,#REF!,19,FALSE())>2,HLOOKUP($A14,#REF!,19,FALSE())<-2),"",#REF!),"") | V14: =IFERROR(IF(AND(X14=0,Y14=0),0,1),0) -> 1 | W14: =IFERROR(_xlfn.T.TEST(E14:M14,N14:U14,2,2),"") | X14: =IFERROR(AVERAGE(E14:M14),"") | Y14: =IFERROR(AVERAGE(N14:U14),"")
A15: 14 | B15: internal medullary lamina of the thalamus | C15: 108200 | D15: 896 | E15: =IFERROR(IF(OR(HLOOKUP($A15,#REF!,3,FALSE())>2,HLOOKUP(A15,#REF!,3,FALSE())<-2),"",#REF!),"") | F15: =IFERROR(IF(OR(HLOOKUP($A15,#REF!,4,FALSE())>2,HLOOKUP($A15,#REF!,4,FALSE())<-2),"",#REF!),"") | G15: =IFERROR(IF(OR(HLOOKUP($A15,#REF!,5,FALSE())>2,HLOOKUP($A15,#REF!,5,FALSE())<-2),"",#REF!),"") | H15: =IFERROR(IF(OR(HLOOKUP($A15,#REF!,6,FALSE())>2,HLOOKUP($A15,#REF!,6,FALSE())<-2),"",#REF!),"") | I15: =IFERROR(IF(OR(HLOOKUP($A15,#REF!,7,FALSE())>2,HLOOKUP($A15,#REF!,7,FALSE())<-2),"",#REF!),"") | J15: =IFERROR(IF(OR(HLOOKUP($A15,#REF!,8,FALSE())>2,HLOOKUP($A15,#REF!,8,FALSE())<-2),"",#REF!),"") | K15: =IFERROR(IF(OR(HLOOKUP($A15,#REF!,9,FALSE())>2,HLOOKUP($A15,#REF!,9,FALSE())<-2),"",#REF!),"") | L15: =IFERROR(IF(OR(HLOOKUP($A15,#REF!,10,FALSE())>2,HLOOKUP($A15,#REF!,10,FALSE())<-2),"",#REF!),"") | M15: =IFERROR(IF(OR(HLOOKUP($A15,#REF!,11,FALSE())>2,HLOOKUP($A15,#REF!,11,FALSE())<-2),"",#REF!),"") | N15: =IFERROR(IF(OR(HLOOKUP($A15,#REF!,12,FALSE())>2,HLOOKUP($A15,#REF!,12,FALSE())<-2),"",#REF!),"") | O15: =IFERROR(IF(OR(HLOOKUP($A15,#REF!,13,FALSE())>2,HLOOKUP($A15,#REF!,13,FALSE())<-2),"",#REF!),"") | P15: =IFERROR(IF(OR(HLOOKUP($A15,#REF!,14,FALSE())>2,HLOOKUP($A15,#REF!,14,FALSE())<-2),"",#REF!),"") | Q15: =IFERROR(IF(OR(HLOOKUP($A15,#REF!,15,FALSE())>2,HLOOKUP($A15,#REF!,15,FALSE())<-2),"",#REF!),"") | R15: =IFERROR(IF(OR(HLOOKUP($A15,#REF!,16,FALSE())>2,HLOOKUP($A15,#REF!,16,FALSE())<-2),"",#REF!),"") | S15: =IFERROR(IF(OR(HLOOKUP($A15,#REF!,17,FALSE())>2,HLOOKUP($A15,#REF!,17,FALSE())<-2),"",#REF!),"") | T15: =IFERROR(IF(OR(HLOOKUP($A15,#REF!,18,FALSE())>2,HLOOKUP($A15,#REF!,18,FALSE())<-2),"",#REF!),"") | U15: =IFERROR(IF(OR(HLOOKUP($A15,#REF!,19,FALSE())>2,HLOOKUP($A15,#REF!,19,FALSE())<-2),"",#REF!),"") | V15: =IFERROR(IF(AND(X15=0,Y15=0),0,1),0) -> 1 | W15: =IFERROR(_xlfn.T.TEST(E15:M15,N15:U15,2,2),"") | X15: =IFERROR(AVERAGE(E15:M15),"") | Y15: =IFERROR(AVERAGE(N15:U15),"")
... A988: 996 | B988: Agranular insular area, dorsal part, layer 1 | C988: 23500 | D988: 104 | E988: =IFERROR(IF(OR(HLOOKUP($A988,#REF!,3,FALSE())>2,HLOOKUP(A988,#REF!,3,FALSE())<-2),"",#REF!),"") | F988: =IFERROR(IF(OR(HLOOKUP($A988,#REF!,4,FALSE())>2,HLOOKUP($A988,#REF!,4,FALSE())<-2),"",#REF!),"") | G988: =IFERROR(IF(OR(HLOOKUP($A988,#REF!,5,FALSE())>2,HLOOKUP($A988,#REF!,5,FALSE())<-2),"",#REF!),"") | H988: =IFERROR(IF(OR(HLOOKUP($A988,#REF!,6,FALSE())>2,HLOOKUP($A988,#REF!,6,FALSE())<-2),"",#REF!),"") | I988: =IFERROR(IF(OR(HLOOKUP($A988,#REF!,7,FALSE())>2,HLOOKUP($A988,#REF!,7,FALSE())<-2),"",#REF!),"") | J988: =IFERROR(IF(OR(HLOOKUP($A988,#REF!,8,FALSE())>2,HLOOKUP($A988,#REF!,8,FALSE())<-2),"",#REF!),"") | K988: =IFERROR(IF(OR(HLOOKUP($A988,#REF!,9,FALSE())>2,HLOOKUP($A988,#REF!,9,FALSE())<-2),"",#REF!),"") | L988: =IFERROR(IF(OR(HLOOKUP($A988,#REF!,10,FALSE())>2,HLOOKUP($A988,#REF!,10,FALSE())<-2),"",#REF!),"") | M988: =IFERROR(IF(OR(HLOOKUP($A988,#REF!,11,FALSE())>2,HLOOKUP($A988,#REF!,11,FALSE())<-2),"",#REF!),"") | N988: =IFERROR(IF(OR(HLOOKUP($A988,#REF!,12,FALSE())>2,HLOOKUP($A988,#REF!,12,FALSE())<-2),"",#REF!),"") | O988: =IFERROR(IF(OR(HLOOKUP($A988,#REF!,13,FALSE())>2,HLOOKUP($A988,#REF!,13,FALSE())<-2),"",#REF!),"") | P988: =IFERROR(IF(OR(HLOOKUP($A988,#REF!,14,FALSE())>2,HLOOKUP($A988,#REF!,14,FALSE())<-2),"",#REF!),"") | Q988: =IFERROR(IF(OR(HLOOKUP($A988,#REF!,15,FALSE())>2,HLOOKUP($A988,#REF!,15,FALSE())<-2),"",#REF!),"") | R988: =IFERROR(IF(OR(HLOOKUP($A988,#REF!,16,FALSE())>2,HLOOKUP($A988,#REF!,16,FALSE())<-2),"",#REF!),"") | S988: =IFERROR(IF(OR(HLOOKUP($A988,#REF!,17,FALSE())>2,HLOOKUP($A988,#REF!,17,FALSE())<-2),"",#REF!),"") | T988: =IFERROR(IF(OR(HLOOKUP($A988,#REF!,18,FALSE())>2,HLOOKUP($A988,#REF!,18,FALSE())<-2),"",#REF!),"") | U988: =IFERROR(IF(OR(HLOOKUP($A988,#REF!,19,FALSE())>2,HLOOKUP($A988,#REF!,19,FALSE())<-2),"",#REF!),"") | V988: =IFERROR(IF(AND(X988=0,Y988=0),0,1),0) -> 1 | W988: =IFERROR(_xlfn.T.TEST(E988:M988,N988:U988,2,2),"") | X988: =IFERROR(AVERAGE(E988:M988),"") | Y988: =IFERROR(AVERAGE(N988:U988),"")
A989: 997 | B989: root | C989: 0 | E989: =IFERROR(IF(OR(HLOOKUP($A989,#REF!,3,FALSE())>2,HLOOKUP(A989,#REF!,3,FALSE())<-2),"",#REF!),"") | F989: =IFERROR(IF(OR(HLOOKUP($A989,#REF!,4,FALSE())>2,HLOOKUP($A989,#REF!,4,FALSE())<-2),"",#REF!),"") | G989: =IFERROR(IF(OR(HLOOKUP($A989,#REF!,5,FALSE())>2,HLOOKUP($A989,#REF!,5,FALSE())<-2),"",#REF!),"") | H989: =IFERROR(IF(OR(HLOOKUP($A989,#REF!,6,FALSE())>2,HLOOKUP($A989,#REF!,6,FALSE())<-2),"",#REF!),"") | I989: =IFERROR(IF(OR(HLOOKUP($A989,#REF!,7,FALSE())>2,HLOOKUP($A989,#REF!,7,FALSE())<-2),"",#REF!),"") | J989: =IFERROR(IF(OR(HLOOKUP($A989,#REF!,8,FALSE())>2,HLOOKUP($A989,#REF!,8,FALSE())<-2),"",#REF!),"") | K989: =IFERROR(IF(OR(HLOOKUP($A989,#REF!,9,FALSE())>2,HLOOKUP($A989,#REF!,9,FALSE())<-2),"",#REF!),"") | L989: =IFERROR(IF(OR(HLOOKUP($A989,#REF!,10,FALSE())>2,HLOOKUP($A989,#REF!,10,FALSE())<-2),"",#REF!),"") | M989: =IFERROR(IF(OR(HLOOKUP($A989,#REF!,11,FALSE())>2,HLOOKUP($A989,#REF!,11,FALSE())<-2),"",#REF!),"") | N989: =IFERROR(IF(OR(HLOOKUP($A989,#REF!,12,FALSE())>2,HLOOKUP($A989,#REF!,12,FALSE())<-2),"",#REF!),"") | O989: =IFERROR(IF(OR(HLOOKUP($A989,#REF!,13,FALSE())>2,HLOOKUP($A989,#REF!,13,FALSE())<-2),"",#REF!),"") | P989: =IFERROR(IF(OR(HLOOKUP($A989,#REF!,14,FALSE())>2,HLOOKUP($A989,#REF!,14,FALSE())<-2),"",#REF!),"") | Q989: =IFERROR(IF(OR(HLOOKUP($A989,#REF!,15,FALSE())>2,HLOOKUP($A989,#REF!,15,FALSE())<-2),"",#REF!),"") | R989: =IFERROR(IF(OR(HLOOKUP($A989,#REF!,16,FALSE())>2,HLOOKUP($A989,#REF!,16,FALSE())<-2),"",#REF!),"") | S989: =IFERROR(IF(OR(HLOOKUP($A989,#REF!,17,FALSE())>2,HLOOKUP($A989,#REF!,17,FALSE())<-2),"",#REF!),"") | T989: =IFERROR(IF(OR(HLOOKUP($A989,#REF!,18,FALSE())>2,HLOOKUP($A989,#REF!,18,FALSE())<-2),"",#REF!),"") | U989: =IFERROR(IF(OR(HLOOKUP($A989,#REF!,19,FALSE())>2,HLOOKUP($A989,#REF!,19,FALSE())<-2),"",#REF!),"") | V989: =IFERROR(IF(AND(X989=0,Y989=0),0,1),0) -> 1 | W989: =IFERROR(_xlfn.T.TEST(E989:M989,N989:U989,2,2),"") | X989: =IFERROR(AVERAGE(E989:M989),"") | Y989: =IFERROR(AVERAGE(N989:U989),"")
A990: 998 | B990: Fundus of striatum | C990: 48500 | D990: 493 | E990: =IFERROR(IF(OR(HLOOKUP($A990,#REF!,3,FALSE())>2,HLOOKUP(A990,#REF!,3,FALSE())<-2),"",#REF!),"") | F990: =IFERROR(IF(OR(HLOOKUP($A990,#REF!,4,FALSE())>2,HLOOKUP($A990,#REF!,4,FALSE())<-2),"",#REF!),"") | G990: =IFERROR(IF(OR(HLOOKUP($A990,#REF!,5,FALSE())>2,HLOOKUP($A990,#REF!,5,FALSE())<-2),"",#REF!),"") | H990: =IFERROR(IF(OR(HLOOKUP($A990,#REF!,6,FALSE())>2,HLOOKUP($A990,#REF!,6,FALSE())<-2),"",#REF!),"") | I990: =IFERROR(IF(OR(HLOOKUP($A990,#REF!,7,FALSE())>2,HLOOKUP($A990,#REF!,7,FALSE())<-2),"",#REF!),"") | J990: =IFERROR(IF(OR(HLOOKUP($A990,#REF!,8,FALSE())>2,HLOOKUP($A990,#REF!,8,FALSE())<-2),"",#REF!),"") | K990: =IFERROR(IF(OR(HLOOKUP($A990,#REF!,9,FALSE())>2,HLOOKUP($A990,#REF!,9,FALSE())<-2),"",#REF!),"") | L990: =IFERROR(IF(OR(HLOOKUP($A990,#REF!,10,FALSE())>2,HLOOKUP($A990,#REF!,10,FALSE())<-2),"",#REF!),"") | M990: =IFERROR(IF(OR(HLOOKUP($A990,#REF!,11,FALSE())>2,HLOOKUP($A990,#REF!,11,FALSE())<-2),"",#REF!),"") | N990: =IFERROR(IF(OR(HLOOKUP($A990,#REF!,12,FALSE())>2,HLOOKUP($A990,#REF!,12,FALSE())<-2),"",#REF!),"") | O990: =IFERROR(IF(OR(HLOOKUP($A990,#REF!,13,FALSE())>2,HLOOKUP($A990,#REF!,13,FALSE())<-2),"",#REF!),"") | P990: =IFERROR(IF(OR(HLOOKUP($A990,#REF!,14,FALSE())>2,HLOOKUP($A990,#REF!,14,FALSE())<-2),"",#REF!),"") | Q990: =IFERROR(IF(OR(HLOOKUP($A990,#REF!,15,FALSE())>2,HLOOKUP($A990,#REF!,15,FALSE())<-2),"",#REF!),"") | R990: =IFERROR(IF(OR(HLOOKUP($A990,#REF!,16,FALSE())>2,HLOOKUP($A990,#REF!,16,FALSE())<-2),"",#REF!),"") | S990: =IFERROR(IF(OR(HLOOKUP($A990,#REF!,17,FALSE())>2,HLOOKUP($A990,#REF!,17,FALSE())<-2),"",#REF!),"") | T990: =IFERROR(IF(OR(HLOOKUP($A990,#REF!,18,FALSE())>2,HLOOKUP($A990,#REF!,18,FALSE())<-2),"",#REF!),"") | U990: =IFERROR(IF(OR(HLOOKUP($A990,#REF!,19,FALSE())>2,HLOOKUP($A990,#REF!,19,FALSE())<-2),"",#REF!),"") | V990: =IFERROR(IF(AND(X990=0,Y990=0),0,1),0) -> 1 | W990: =IFERROR(_xlfn.T.TEST(E990:M990,N990:U990,2,2),"") | X990: =IFERROR(AVERAGE(E990:M990),"") | Y990: =IFERROR(AVERAGE(N990:U990),"")
A991: 999 | B991: Entorhinal area, lateral part, layer 2/3 | C991: 41600 | D991: 918 | E991: =IFERROR(IF(OR(HLOOKUP($A991,#REF!,3,FALSE())>2,HLOOKUP(A991,#REF!,3,FALSE())<-2),"",#REF!),"") | F991: =IFERROR(IF(OR(HLOOKUP($A991,#REF!,4,FALSE())>2,HLOOKUP($A991,#REF!,4,FALSE())<-2),"",#REF!),"") | G991: =IFERROR(IF(OR(HLOOKUP($A991,#REF!,5,FALSE())>2,HLOOKUP($A991,#REF!,5,FALSE())<-2),"",#REF!),"") | H991: =IFERROR(IF(OR(HLOOKUP($A991,#REF!,6,FALSE())>2,HLOOKUP($A991,#REF!,6,FALSE())<-2),"",#REF!),"") | I991: =IFERROR(IF(OR(HLOOKUP($A991,#REF!,7,FALSE())>2,HLOOKUP($A991,#REF!,7,FALSE())<-2),"",#REF!),"") | J991: =IFERROR(IF(OR(HLOOKUP($A991,#REF!,8,FALSE())>2,HLOOKUP($A991,#REF!,8,FALSE())<-2),"",#REF!),"") | K991: =IFERROR(IF(OR(HLOOKUP($A991,#REF!,9,FALSE())>2,HLOOKUP($A991,#REF!,9,FALSE())<-2),"",#REF!),"") | L991: =IFERROR(IF(OR(HLOOKUP($A991,#REF!,10,FALSE())>2,HLOOKUP($A991,#REF!,10,FALSE())<-2),"",#REF!),"") | M991: =IFERROR(IF(OR(HLOOKUP($A991,#REF!,11,FALSE())>2,HLOOKUP($A991,#REF!,11,FALSE())<-2),"",#REF!),"") | N991: =IFERROR(IF(OR(HLOOKUP($A991,#REF!,12,FALSE())>2,HLOOKUP($A991,#REF!,12,FALSE())<-2),"",#REF!),"") | O991: =IFERROR(IF(OR(HLOOKUP($A991,#REF!,13,FALSE())>2,HLOOKUP($A991,#REF!,13,FALSE())<-2),"",#REF!),"") | P991: =IFERROR(IF(OR(HLOOKUP($A991,#REF!,14,FALSE())>2,HLOOKUP($A991,#REF!,14,FALSE())<-2),"",#REF!),"") | Q991: =IFERROR(IF(OR(HLOOKUP($A991,#REF!,15,FALSE())>2,HLOOKUP($A991,#REF!,15,FALSE())<-2),"",#REF!),"") | R991: =IFERROR(IF(OR(HLOOKUP($A991,#REF!,16,FALSE())>2,HLOOKUP($A991,#REF!,16,FALSE())<-2),"",#REF!),"") | S991: =IFERROR(IF(OR(HLOOKUP($A991,#REF!,17,FALSE())>2,HLOOKUP($A991,#REF!,17,FALSE())<-2),"",#REF!),"") | T991: =IFERROR(IF(OR(HLOOKUP($A991,#REF!,18,FALSE())>2,HLOOKUP($A991,#REF!,18,FALSE())<-2),"",#REF!),"") | U991: =IFERROR(IF(OR(HLOOKUP($A991,#REF!,19,FALSE())>2,HLOOKUP($A991,#REF!,19,FALSE())<-2),"",#REF!),"") | V991: =IFERROR(IF(AND(X991=0,Y991=0),0,1),0) -> 1 | W991: =IFERROR(_xlfn.T.TEST(E991:M991,N991:U991,2,2),"") | X991: =IFERROR(AVERAGE(E991:M991),"") | Y991: =IFERROR(AVERAGE(N991:U991),"")
A992: 1000 | B992: extrapyramidal fiber systems | C992: 108500 | D992: 1009 | E992: =IFERROR(IF(OR(HLOOKUP($A992,#REF!,3,FALSE())>2,HLOOKUP(A992,#REF!,3,FALSE())<-2),"",#REF!),"") | F992: =IFERROR(IF(OR(HLOOKUP($A992,#REF!,4,FALSE())>2,HLOOKUP($A992,#REF!,4,FALSE())<-2),"",#REF!),"") | G992: =IFERROR(IF(OR(HLOOKUP($A992,#REF!,5,FALSE())>2,HLOOKUP($A992,#REF!,5,FALSE())<-2),"",#REF!),"") | H992: =IFERROR(IF(OR(HLOOKUP($A992,#REF!,6,FALSE())>2,HLOOKUP($A992,#REF!,6,FALSE())<-2),"",#REF!),"") | I992: =IFERROR(IF(OR(HLOOKUP($A992,#REF!,7,FALSE())>2,HLOOKUP($A992,#REF!,7,FALSE())<-2),"",#REF!),"") | J992: =IFERROR(IF(OR(HLOOKUP($A992,#REF!,8,FALSE())>2,HLOOKUP($A992,#REF!,8,FALSE())<-2),"",#REF!),"") | K992: =IFERROR(IF(OR(HLOOKUP($A992,#REF!,9,FALSE())>2,HLOOKUP($A992,#REF!,9,FALSE())<-2),"",#REF!),"") | L992: =IFERROR(IF(OR(HLOOKUP($A992,#REF!,10,FALSE())>2,HLOOKUP($A992,#REF!,10,FALSE())<-2),"",#REF!),"") | M992: =IFERROR(IF(OR(HLOOKUP($A992,#REF!,11,FALSE())>2,HLOOKUP($A992,#REF!,11,FALSE())<-2),"",#REF!),"") | N992: =IFERROR(IF(OR(HLOOKUP($A992,#REF!,12,FALSE())>2,HLOOKUP($A992,#REF!,12,FALSE())<-2),"",#REF!),"") | O992: =IFERROR(IF(OR(HLOOKUP($A992,#REF!,13,FALSE())>2,HLOOKUP($A992,#REF!,13,FALSE())<-2),"",#REF!),"") | P992: =IFERROR(IF(OR(HLOOKUP($A992,#REF!,14,FALSE())>2,HLOOKUP($A992,#REF!,14,FALSE())<-2),"",#REF!),"") | Q992: =IFERROR(IF(OR(HLOOKUP($A992,#REF!,15,FALSE())>2,HLOOKUP($A992,#REF!,15,FALSE())<-2),"",#REF!),"") | R992: =IFERROR(IF(OR(HLOOKUP($A992,#REF!,16,FALSE())>2,HLOOKUP($A992,#REF!,16,FALSE())<-2),"",#REF!),"") | S992: =IFERROR(IF(OR(HLOOKUP($A992,#REF!,17,FALSE())>2,HLOOKUP($A992,#REF!,17,FALSE())<-2),"",#REF!),"") | T992: =IFERROR(IF(OR(HLOOKUP($A992,#REF!,18,FALSE())>2,HLOOKUP($A992,#REF!,18,FALSE())<-2),"",#REF!),"") | U992: =IFERROR(IF(OR(HLOOKUP($A992,#REF!,19,FALSE())>2,HLOOKUP($A992,#REF!,19,FALSE())<-2),"",#REF!),"") | V992: =IFERROR(IF(AND(X992=0,Y992=0),0,1),0) -> 1 | W992: =IFERROR(_xlfn.T.TEST(E992:M992,N992:U992,2,2),"") | X992: =IFERROR(AVERAGE(E992:M992),"") | Y992: =IFERROR(AVERAGE(N992:U992),"")
A993: 1001 | B993: Lobule V | C993: 56800 | D993: 928 | E993: =IFERROR(IF(OR(HLOOKUP($A993,#REF!,3,FALSE())>2,HLOOKUP(A993,#REF!,3,FALSE())<-2),"",#REF!),"") | F993: =IFERROR(IF(OR(HLOOKUP($A993,#REF!,4,FALSE())>2,HLOOKUP($A993,#REF!,4,FALSE())<-2),"",#REF!),"") | G993: =IFERROR(IF(OR(HLOOKUP($A993,#REF!,5,FALSE())>2,HLOOKUP($A993,#REF!,5,FALSE())<-2),"",#REF!),"") | H993: =IFERROR(IF(OR(HLOOKUP($A993,#REF!,6,FALSE())>2,HLOOKUP($A993,#REF!,6,FALSE())<-2),"",#REF!),"") | I993: =IFERROR(IF(OR(HLOOKUP($A993,#REF!,7,FALSE())>2,HLOOKUP($A993,#REF!,7,FALSE())<-2),"",#REF!),"") | J993: =IFERROR(IF(OR(HLOOKUP($A993,#REF!,8,FALSE())>2,HLOOKUP($A993,#REF!,8,FALSE())<-2),"",#REF!),"") | K993: =IFERROR(IF(OR(HLOOKUP($A993,#REF!,9,FALSE())>2,HLOOKUP($A993,#REF!,9,FALSE())<-2),"",#REF!),"") | L993: =IFERROR(IF(OR(HLOOKUP($A993,#REF!,10,FALSE())>2,HLOOKUP($A993,#REF!,10,FALSE())<-2),"",#REF!),"") | M993: =IFERROR(IF(OR(HLOOKUP($A993,#REF!,11,FALSE())>2,HLOOKUP($A993,#REF!,11,FALSE())<-2),"",#REF!),"") | N993: =IFERROR(IF(OR(HLOOKUP($A993,#REF!,12,FALSE())>2,HLOOKUP($A993,#REF!,12,FALSE())<-2),"",#REF!),"") | O993: =IFERROR(IF(OR(HLOOKUP($A993,#REF!,13,FALSE())>2,HLOOKUP($A993,#REF!,13,FALSE())<-2),"",#REF!),"") | P993: =IFERROR(IF(OR(HLOOKUP($A993,#REF!,14,FALSE())>2,HLOOKUP($A993,#REF!,14,FALSE())<-2),"",#REF!),"") | Q993: =IFERROR(IF(OR(HLOOKUP($A993,#REF!,15,FALSE())>2,HLOOKUP($A993,#REF!,15,FALSE())<-2),"",#REF!),"") | R993: =IFERROR(IF(OR(HLOOKUP($A993,#REF!,16,FALSE())>2,HLOOKUP($A993,#REF!,16,FALSE())<-2),"",#REF!),"") | S993: =IFERROR(IF(OR(HLOOKUP($A993,#REF!,17,FALSE())>2,HLOOKUP($A993,#REF!,17,FALSE())<-2),"",#REF!),"") | T993: =IFERROR(IF(OR(HLOOKUP($A993,#REF!,18,FALSE())>2,HLOOKUP($A993,#REF!,18,FALSE())<-2),"",#REF!),"") | U993: =IFERROR(IF(OR(HLOOKUP($A993,#REF!,19,FALSE())>2,HLOOKUP($A993,#REF!,19,FALSE())<-2),"",#REF!),"") | V993: =IFERROR(IF(AND(X993=0,Y993=0),0,1),0) -> 1 | W993: =IFERROR(_xlfn.T.TEST(E993:M993,N993:U993,2,2),"") | X993: =IFERROR(AVERAGE(E993:M993),"") | Y993: =IFERROR(AVERAGE(N993:U993),"")
A994: 1002 | B994: Primary auditory area | C994: 11300 | D994: 247 | E994: =IFERROR(IF(OR(HLOOKUP($A994,#REF!,3,FALSE())>2,HLOOKUP(A994,#REF!,3,FALSE())<-2),"",#REF!),"") | F994: =IFERROR(IF(OR(HLOOKUP($A994,#REF!,4,FALSE())>2,HLOOKUP($A994,#REF!,4,FALSE())<-2),"",#REF!),"") | G994: =IFERROR(IF(OR(HLOOKUP($A994,#REF!,5,FALSE())>2,HLOOKUP($A994,#REF!,5,FALSE())<-2),"",#REF!),"") | H994: =IFERROR(IF(OR(HLOOKUP($A994,#REF!,6,FALSE())>2,HLOOKUP($A994,#REF!,6,FALSE())<-2),"",#REF!),"") | I994: =IFERROR(IF(OR(HLOOKUP($A994,#REF!,7,FALSE())>2,HLOOKUP($A994,#REF!,7,FALSE())<-2),"",#REF!),"") | J994: =IFERROR(IF(OR(HLOOKUP($A994,#REF!,8,FALSE())>2,HLOOKUP($A994,#REF!,8,FALSE())<-2),"",#REF!),"") | K994: =IFERROR(IF(OR(HLOOKUP($A994,#REF!,9,FALSE())>2,HLOOKUP($A994,#REF!,9,FALSE())<-2),"",#REF!),"") | L994: =IFERROR(IF(OR(HLOOKUP($A994,#REF!,10,FALSE())>2,HLOOKUP($A994,#REF!,10,FALSE())<-2),"",#REF!),"") | M994: =IFERROR(IF(OR(HLOOKUP($A994,#REF!,11,FALSE())>2,HLOOKUP($A994,#REF!,11,FALSE())<-2),"",#REF!),"") | N994: =IFERROR(IF(OR(HLOOKUP($A994,#REF!,12,FALSE())>2,HLOOKUP($A994,#REF!,12,FALSE())<-2),"",#REF!),"") | O994: =IFERROR(IF(OR(HLOOKUP($A994,#REF!,13,FALSE())>2,HLOOKUP($A994,#REF!,13,FALSE())<-2),"",#REF!),"") | P994: =IFERROR(IF(OR(HLOOKUP($A994,#REF!,14,FALSE())>2,HLOOKUP($A994,#REF!,14,FALSE())<-2),"",#REF!),"") | Q994: =IFERROR(IF(OR(HLOOKUP($A994,#REF!,15,FALSE())>2,HLOOKUP($A994,#REF!,15,FALSE())<-2),"",#REF!),"") | R994: =IFERROR(IF(OR(HLOOKUP($A994,#REF!,16,FALSE())>2,HLOOKUP($A994,#REF!,16,FALSE())<-2),"",#REF!),"") | S994: =IFERROR(IF(OR(HLOOKUP($A994,#REF!,17,FALSE())>2,HLOOKUP($A994,#REF!,17,FALSE())<-2),"",#REF!),"") | T994: =IFERROR(IF(OR(HLOOKUP($A994,#REF!,18,FALSE())>2,HLOOKUP($A994,#REF!,18,FALSE())<-2),"",#REF!),"") | U994: =IFERROR(IF(OR(HLOOKUP($A994,#REF!,19,FALSE())>2,HLOOKUP($A994,#REF!,19,FALSE())<-2),"",#REF!),"") | V994: =IFERROR(IF(AND(X994=0,Y994=0),0,1),0) -> 1 | W994: =IFERROR(_xlfn.T.TEST(E994:M994,N994:U994,2,2),"") | X994: =IFERROR(AVERAGE(E994:M994),"") | Y994: =IFERROR(AVERAGE(N994:U994),"")
A995: 1003 | B995: corticopontine tract | C995: 107400 | D995: 784 | E995: =IFERROR(IF(OR(HLOOKUP($A995,#REF!,3,FALSE())>2,HLOOKUP(A995,#REF!,3,FALSE())<-2),"",#REF!),"") | F995: =IFERROR(IF(OR(HLOOKUP($A995,#REF!,4,FALSE())>2,HLOOKUP($A995,#REF!,4,FALSE())<-2),"",#REF!),"") | G995: =IFERROR(IF(OR(HLOOKUP($A995,#REF!,5,FALSE())>2,HLOOKUP($A995,#REF!,5,FALSE())<-2),"",#REF!),"") | H995: =IFERROR(IF(OR(HLOOKUP($A995,#REF!,6,FALSE())>2,HLOOKUP($A995,#REF!,6,FALSE())<-2),"",#REF!),"") | I995: =IFERROR(IF(OR(HLOOKUP($A995,#REF!,7,FALSE())>2,HLOOKUP($A995,#REF!,7,FALSE())<-2),"",#REF!),"") | J995: =IFERROR(IF(OR(HLOOKUP($A995,#REF!,8,FALSE())>2,HLOOKUP($A995,#REF!,8,FALSE())<-2),"",#REF!),"") | K995: =IFERROR(IF(OR(HLOOKUP($A995,#REF!,9,FALSE())>2,HLOOKUP($A995,#REF!,9,FALSE())<-2),"",#REF!),"") | L995: =IFERROR(IF(OR(HLOOKUP($A995,#REF!,10,FALSE())>2,HLOOKUP($A995,#REF!,10,FALSE())<-2),"",#REF!),"") | M995: =IFERROR(IF(OR(HLOOKUP($A995,#REF!,11,FALSE())>2,HLOOKUP($A995,#REF!,11,FALSE())<-2),"",#REF!),"") | N995: =IFERROR(IF(OR(HLOOKUP($A995,#REF!,12,FALSE())>2,HLOOKUP($A995,#REF!,12,FALSE())<-2),"",#REF!),"") | O995: =IFERROR(IF(OR(HLOOKUP($A995,#REF!,13,FALSE())>2,HLOOKUP($A995,#REF!,13,FALSE())<-2),"",#REF!),"") | P995: =IFERROR(IF(OR(HLOOKUP($A995,#REF!,14,FALSE())>2,HLOOKUP($A995,#REF!,14,FALSE())<-2),"",#REF!),"") | Q995: =IFERROR(IF(OR(HLOOKUP($A995,#REF!,15,FALSE())>2,HLOOKUP($A995,#REF!,15,FALSE())<-2),"",#REF!),"") | R995: =IFERROR(IF(OR(HLOOKUP($A995,#REF!,16,FALSE())>2,HLOOKUP($A995,#REF!,16,FALSE())<-2),"",#REF!),"") | S995: =IFERROR(IF(OR(HLOOKUP($A995,#REF!,17,FALSE())>2,HLOOKUP($A995,#REF!,17,FALSE())<-2),"",#REF!),"") | T995: =IFERROR(IF(OR(HLOOKUP($A995,#REF!,18,FALSE())>2,HLOOKUP($A995,#REF!,18,FALSE())<-2),"",#REF!),"") | U995: =IFERROR(IF(OR(HLOOKUP($A995,#REF!,19,FALSE())>2,HLOOKUP($A995,#REF!,19,FALSE())<-2),"",#REF!),"") | V995: =IFERROR(IF(AND(X995=0,Y995=0),0,1),0) -> 1 | W995: =IFERROR(_xlfn.T.TEST(E995:M995,N995:U995,2,2),"") | X995: =IFERROR(AVERAGE(E995:M995),"") | Y995: =IFERROR(AVERAGE(N995:U995),"")
A996: 1004 | B996: Ventral premammillary nucleus | C996: 76100 | D996: 467 | E996: =IFERROR(IF(OR(HLOOKUP($A996,#REF!,3,FALSE())>2,HLOOKUP(A996,#REF!,3,FALSE())<-2),"",#REF!),"") | F996: =IFERROR(IF(OR(HLOOKUP($A996,#REF!,4,FALSE())>2,HLOOKUP($A996,#REF!,4,FALSE())<-2),"",#REF!),"") | G996: =IFERROR(IF(OR(HLOOKUP($A996,#REF!,5,FALSE())>2,HLOOKUP($A996,#REF!,5,FALSE())<-2),"",#REF!),"") | H996: =IFERROR(IF(OR(HLOOKUP($A996,#REF!,6,FALSE())>2,HLOOKUP($A996,#REF!,6,FALSE())<-2),"",#REF!),"") | I996: =IFERROR(IF(OR(HLOOKUP($A996,#REF!,7,FALSE())>2,HLOOKUP($A996,#REF!,7,FALSE())<-2),"",#REF!),"") | J996: =IFERROR(IF(OR(HLOOKUP($A996,#REF!,8,FALSE())>2,HLOOKUP($A996,#REF!,8,FALSE())<-2),"",#REF!),"") | K996: =IFERROR(IF(OR(HLOOKUP($A996,#REF!,9,FALSE())>2,HLOOKUP($A996,#REF!,9,FALSE())<-2),"",#REF!),"") | L996: =IFERROR(IF(OR(HLOOKUP($A996,#REF!,10,FALSE())>2,HLOOKUP($A996,#REF!,10,FALSE())<-2),"",#REF!),"") | M996: =IFERROR(IF(OR(HLOOKUP($A996,#REF!,11,FALSE())>2,HLOOKUP($A996,#REF!,11,FALSE())<-2),"",#REF!),"") | N996: =IFERROR(IF(OR(HLOOKUP($A996,#REF!,12,FALSE())>2,HLOOKUP($A996,#REF!,12,FALSE())<-2),"",#REF!),"") | O996: =IFERROR(IF(OR(HLOOKUP($A996,#REF!,13,FALSE())>2,HLOOKUP($A996,#REF!,13,FALSE())<-2),"",#REF!),"") | P996: =IFERROR(IF(OR(HLOOKUP($A996,#REF!,14,FALSE())>2,HLOOKUP($A996,#REF!,14,FALSE())<-2),"",#REF!),"") | Q996: =IFERROR(IF(OR(HLOOKUP($A996,#REF!,15,FALSE())>2,HLOOKUP($A996,#REF!,15,FALSE())<-2),"",#REF!),"") | R996: =IFERROR(IF(OR(HLOOKUP($A996,#REF!,16,FALSE())>2,HLOOKUP($A996,#REF!,16,FALSE())<-2),"",#REF!),"") | S996: =IFERROR(IF(OR(HLOOKUP($A996,#REF!,17,FALSE())>2,HLOOKUP($A996,#REF!,17,FALSE())<-2),"",#REF!),"") | T996: =IFERROR(IF(OR(HLOOKUP($A996,#REF!,18,FALSE())>2,HLOOKUP($A996,#REF!,18,FALSE())<-2),"",#REF!),"") | U996: =IFERROR(IF(OR(HLOOKUP($A996,#REF!,19,FALSE())>2,HLOOKUP($A996,#REF!,19,FALSE())<-2),"",#REF!),"") | V996: =IFERROR(IF(AND(X996=0,Y996=0),0,1),0) -> 1 | W996: =IFERROR(_xlfn.T.TEST(E996:M996,N996:U996,2,2),"") | X996: =IFERROR(AVERAGE(E996:M996),"") | Y996: =IFERROR(AVERAGE(N996:U996),"")
A997: 1005 | B997: Primary auditory area, layer 6b | C997: 11900 | D997: 1002 | E997: =IFERROR(IF(OR(HLOOKUP($A997,#REF!,3,FALSE())>2,HLOOKUP(A997,#REF!,3,FALSE())<-2),"",#REF!),"") | F997: =IFERROR(IF(OR(HLOOKUP($A997,#REF!,4,FALSE())>2,HLOOKUP($A997,#REF!,4,FALSE())<-2),"",#REF!),"") | G997: =IFERROR(IF(OR(HLOOKUP($A997,#REF!,5,FALSE())>2,HLOOKUP($A997,#REF!,5,FALSE())<-2),"",#REF!),"") | H997: =IFERROR(IF(OR(HLOOKUP($A997,#REF!,6,FALSE())>2,HLOOKUP($A997,#REF!,6,FALSE())<-2),"",#REF!),"") | I997: =IFERROR(IF(OR(HLOOKUP($A997,#REF!,7,FALSE())>2,HLOOKUP($A997,#REF!,7,FALSE())<-2),"",#REF!),"") | J997: =IFERROR(IF(OR(HLOOKUP($A997,#REF!,8,FALSE())>2,HLOOKUP($A997,#REF!,8,FALSE())<-2),"",#REF!),"") | K997: =IFERROR(IF(OR(HLOOKUP($A997,#REF!,9,FALSE())>2,HLOOKUP($A997,#REF!,9,FALSE())<-2),"",#REF!),"") | L997: =IFERROR(IF(OR(HLOOKUP($A997,#REF!,10,FALSE())>2,HLOOKUP($A997,#REF!,10,FALSE())<-2),"",#REF!),"") | M997: =IFERROR(IF(OR(HLOOKUP($A997,#REF!,11,FALSE())>2,HLOOKUP($A997,#REF!,11,FALSE())<-2),"",#REF!),"") | N997: =IFERROR(IF(OR(HLOOKUP($A997,#REF!,12,FALSE())>2,HLOOKUP($A997,#REF!,12,FALSE())<-2),"",#REF!),"") | O997: =IFERROR(IF(OR(HLOOKUP($A997,#REF!,13,FALSE())>2,HLOOKUP($A997,#REF!,13,FALSE())<-2),"",#REF!),"") | P997: =IFERROR(IF(OR(HLOOKUP($A997,#REF!,14,FALSE())>2,HLOOKUP($A997,#REF!,14,FALSE())<-2),"",#REF!),"") | Q997: =IFERROR(IF(OR(HLOOKUP($A997,#REF!,15,FALSE())>2,HLOOKUP($A997,#REF!,15,FALSE())<-2),"",#REF!),"") | R997: =IFERROR(IF(OR(HLOOKUP($A997,#REF!,16,FALSE())>2,HLOOKUP($A997,#REF!,16,FALSE())<-2),"",#REF!),"") | S997: =IFERROR(IF(OR(HLOOKUP($A997,#REF!,17,FALSE())>2,HLOOKUP($A997,#REF!,17,FALSE())<-2),"",#REF!),"") | T997: =IFERROR(IF(OR(HLOOKUP($A997,#REF!,18,FALSE())>2,HLOOKUP($A997,#REF!,18,FALSE())<-2),"",#REF!),"") | U997: =IFERROR(IF(OR(HLOOKUP($A997,#REF!,19,FALSE())>2,HLOOKUP($A997,#REF!,19,FALSE())<-2),"",#REF!),"") | V997: =IFERROR(IF(AND(X997=0,Y997=0),0,1),0) -> 1 | W997: =IFERROR(_xlfn.T.TEST(E997:M997,N997:U997,2,2),"") | X997: =IFERROR(AVERAGE(E997:M997),"") | Y997: =IFERROR(AVERAGE(N997:U997),"")
A998: 1006 | B998: Primary somatosensory area, trunk, layer 1 | C998: 7100 | D998: 361 | E998: =IFERROR(IF(OR(HLOOKUP($A998,#REF!,3,FALSE())>2,HLOOKUP(A998,#REF!,3,FALSE())<-2),"",#REF!),"") | F998: =IFERROR(IF(OR(HLOOKUP($A998,#REF!,4,FALSE())>2,HLOOKUP($A998,#REF!,4,FALSE())<-2),"",#REF!),"") | G998: =IFERROR(IF(OR(HLOOKUP($A998,#REF!,5,FALSE())>2,HLOOKUP($A998,#REF!,5,FALSE())<-2),"",#REF!),"") | H998: =IFERROR(IF(OR(HLOOKUP($A998,#REF!,6,FALSE())>2,HLOOKUP($A998,#REF!,6,FALSE())<-2),"",#REF!),"") | I998: =IFERROR(IF(OR(HLOOKUP($A998,#REF!,7,FALSE())>2,HLOOKUP($A998,#REF!,7,FALSE())<-2),"",#REF!),"") | J998: =IFERROR(IF(OR(HLOOKUP($A998,#REF!,8,FALSE())>2,HLOOKUP($A998,#REF!,8,FALSE())<-2),"",#REF!),"") | K998: =IFERROR(IF(OR(HLOOKUP($A998,#REF!,9,FALSE())>2,HLOOKUP($A998,#REF!,9,FALSE())<-2),"",#REF!),"") | L998: =IFERROR(IF(OR(HLOOKUP($A998,#REF!,10,FALSE())>2,HLOOKUP($A998,#REF!,10,FALSE())<-2),"",#REF!),"") | M998: =IFERROR(IF(OR(HLOOKUP($A998,#REF!,11,FALSE())>2,HLOOKUP($A998,#REF!,11,FALSE())<-2),"",#REF!),"") | N998: =IFERROR(IF(OR(HLOOKUP($A998,#REF!,12,FALSE())>2,HLOOKUP($A998,#REF!,12,FALSE())<-2),"",#REF!),"") | O998: =IFERROR(IF(OR(HLOOKUP($A998,#REF!,13,FALSE())>2,HLOOKUP($A998,#REF!,13,FALSE())<-2),"",#REF!),"") | P998: =IFERROR(IF(OR(HLOOKUP($A998,#REF!,14,FALSE())>2,HLOOKUP($A998,#REF!,14,FALSE())<-2),"",#REF!),"") | Q998: =IFERROR(IF(OR(HLOOKUP($A998,#REF!,15,FALSE())>2,HLOOKUP($A998,#REF!,15,FALSE())<-2),"",#REF!),"") | R998: =IFERROR(IF(OR(HLOOKUP($A998,#REF!,16,FALSE())>2,HLOOKUP($A998,#REF!,16,FALSE())<-2),"",#REF!),"") | S998: =IFERROR(IF(OR(HLOOKUP($A998,#REF!,17,FALSE())>2,HLOOKUP($A998,#REF!,17,FALSE())<-2),"",#REF!),"") | T998: =IFERROR(IF(OR(HLOOKUP($A998,#REF!,18,FALSE())>2,HLOOKUP($A998,#REF!,18,FALSE())<-2),"",#REF!),"") | U998: =IFERROR(IF(OR(HLOOKUP($A998,#REF!,19,FALSE())>2,HLOOKUP($A998,#REF!,19,FALSE())<-2),"",#REF!),"") | V998: =IFERROR(IF(AND(X998=0,Y998=0),0,1),0) -> 1 | W998: =IFERROR(_xlfn.T.TEST(E998:M998,N998:U998,2,2),"") | X998: =IFERROR(AVERAGE(E998:M998),"") | Y998: =IFERROR(AVERAGE(N998:U998),"")
